Workbook

Sheet Guideline
A1: Guideline to make and understand Unit Test Case
A3: 1. Overview
A4: - In the template, Unit test cases are based on functions. Each sheet presents test cases for one function.
A5: - Cover: General information of the project and Unit Test cases
A6: - FunctionList: The list of Classes and Functions in the document. + To control that the number of Unit TC meets customer's requirement or the norm, user should fill value for 'Normal number of Test cases/KLOC'.
A7: + Click on Function link to open the related Test cases of the function. Note: You should create new Function sheet before creating the link
A8: - Test Report: provive the overview results of Functions Unit test: Test coverage, Test successful coverage (Summary, for normal/abnormal/boundary cases)
A9: Note: Should check the formula of "Sub Total" if you add more functions
A11: 2. Content in Test function sheet
A12: 2.1 Combination of test cases.
A13: - To verify that number of Unit TC meets customer's requirement or not. User has to fill number LOC of tested function and fill value of 'Normal number test cases/KLOC' item in FunctionList sheet, which is required by customer or normal value. The number of lacked TC is shown in 'Lack of test cases' item.
A14: - If the number of Unit TC does not meet the requirement, creator should explain the reasons.
... A47: - Test requirement: Brief description about requirements which are tested in this function, it is not mandatory.

Sheet Cover
B2: UNIT TEST DOCUMENT
A4: Project Name | B4: IQGS – AI-Powered Interview Question Generation System Using RAG and LLM – A Dual-Sided Platform for HR and Job Seekers | E4: Creator | F4: NamNM
A5: Project Code | B5: SU26SE102 | E5: Issue Date | F5: 15/09/2026
A6: Document Code | B6: =B5&"_"&"Unit Test Report"&"_"&"v0.3.0" -> SU26SE102_Unit Test Report_v0.3.0 | E6: Version | F6: 0.3.0
A9: Record of change
A10: Effective Date | B10: Version | C10: Change Item | D10: *A,D,M | E10: Change description | F10: Reference
A11: 02/06/2026 | B11: 0.0.1 | D11: A | E11: Add project information and record of change table
A12: 16/08/2026 | B12: 0.2.0 | C12: Cover title | D12: M | E12: Retitled from "UNIT TEST DOCUMENT" to "UNIT & API TEST DOCUMENT", the workbook documents both FE Vitest scenarios and 18 real BE (RAG_IQGS) API test scenarios, not FE unit tests alone.
A13: 10/09/2026 | B13: 0.2.1 | C13: Scenario notes | D13: M | E13: Annotated 3 scenarios whose automated Vitest coverage was removed 2026-09-10 (ApplyPlanSettingsTimeout/UTCID02, SampleJdModalCopyUse/UTCID02, StudioChatRefineMultiTurn — see each sheet's own Note row) after cross-referencing actual UTCID conditions, not just ID-number similarity — this workbook's FE_RAG_0XX scenario IDs do not correspond 1:1 to the Vitest RAG0XX IDs in tests/unit/. Two other removed automated tests were checked and deliberately NOT annotated: RAG029-2 (studio-flow.test.tsx) was an ad-hoc code-review regression test with no corresponding scenario sheet in this workbook to begin with; RAG030-1 (studio-flow.test.tsx, settings-toggle persistence) does not match StudioGenerationSettingsToggles, whose UTCIDs verify generated-question content reflects the toggles, a different mechanism than the removed test's settings-PUT-call assertion. Historical Passed/Failed data on all sheets is left untouched. | F13: TestExecutionGuide.docx; Report5_Test_Report.xlsx
A14: 12/09/2026 | B14: 0.2.2 | C14: Timeout5xxFriendlyMessage; FE_ACT_001 | D14: M | E14: Updated FE_RAGAUTH_011 after the 10/09/2026 merge: timeouts and 5xx now surface friendly localized copy (NETWORK/SERVER_ERROR_MESSAGES in error.interceptor.ts), so the scenario was renamed Timeout5xxFriendlyMessage and UTCID01-03 expectations rewritten; 429 still has no dedicated handling. Flagged FE_ACT_001 as covering the /admin/content page deleted in 0ff281f. | F14: error.interceptor.ts; Report5_Test_Report.xlsx
A15: 13/09/2026 | B15: 0.2.3 | C15: Unit test reduction | D15: M, D | E15: Synced with the reduced Vitest suite (529 -> 470 test cases): removed 7 scenarios for code the app no longer uses (NormalizePathname, GetLoginWelcomeRoleFromRedirect, SaveAndGetLocalSession, PatchAndUpdateLocalSession, ToGenerationSessionAndMalformed, ValidateAvatarFile, ContentTableRowAndDeadDeleteBut); trimmed UTCIDs to one per branch in 10 scenarios; renamed SortAndInjectJdCitation to InjectJdCitationForDisplay and BadgeClassAndCategoryLabelHelpers to FormatCategoryLabel; corrected the GetRoleRedirect default route to /candidate. | F15: tests/unit; Report5_Test_Report.xlsx
A16: 15/09/2026 | B16: 0.3.0 | C16: Unit test workbook | D16: A, M, D | E16: Rebuilt from executed tests only: 19 frontend functions (161 test cases, Vitest run 15/09/2026) and 38 backend application-layer functions (232 test cases, xUnit run 15/09/2026); every UTCID is a real test with its result and executed date. Restored the template header rows (Function Code/Name, Created By, Executed By, Lines of code, Lack of test cases, COUNTIF counters). The previous scenario sheets were replaced: UI scenarios are now functional test cases in Report5_Test_Report.xlsx, scenarios without a current automated test were removed, and the 18 RAG Service API scenarios moved to Report5_Test_Report.xlsx (Pending). | F16: Report5_Test_Report.xlsx; tests/unit; ApplicationLayer.UnitTests

Sheet Functions
E2: Function List
A4: Project Name | E4: =Cover!B4 -> IQGS – AI-Powered Interview Question Generation System Using RAG and LLM – A Dual-Sided Platform for HR and Job Seekers
A5: Project Code | E5: =Cover!B5 -> SU26SE102
A6: Normal number of Test cases/KLOC | E6: 100
A7: Test Environment Setup Description | E7: 1. Server: not required - all tests run locally (Windows 11 developer machine). 2. Frontend unit tests: Node.js 24, Vitest 4.1 with jsdom 29 - command: npx vitest run (logic-only test files). 3. Backend unit tests: .NET SDK 10.0.303, test project ApplicationLayer.UnitTests (net8.0, xUnit 2.9.2) - command: dotnet test ApplicationLayer.UnitTests. 4. Database: not required - repositories and usage metering are replaced by in-memory fakes. 5. Web browser: not required.
A10: No | B10: Requirement Name | C10: Class Name | D10: Function Name | E10: Function Code(Optional) | F10: Sheet Name | G10: Description | H10: Pre-Condition
A11: 1 | B11: REQ-FE-AUTH Session & Access Handling | C11: auth.interceptor.ts | D11: attachAuthInterceptor | E11: FE-AUTH-01 | F11: FE-AuthInterceptor | G11: Axios interceptor: on 401 refreshes the access token once, retries the request, shares one refresh between concurrent 401s, and clears auth + redirects to /login when the session cannot be refreshed. | H11: Axios client created with attachAuthInterceptor(); Access token "expired.jwt.token" and a refresh token are stored; current page /hr/generate-question/manual
A12: 2 | B12: REQ-FE-AUTH Session & Access Handling | C12: error.interceptor.ts | D12: extractErrorMessage | E12: FE-AUTH-02 | F12: FE-ExtractErrorMessage | G12: Turn an API error into the message shown to the user: canned text for known error codes, the server message when present, friendly text for bare 5xx and a generic fallback. | H12: Pure function, no mocks
A13: 3 | B13: REQ-FE-AUTH Session & Access Handling | C13: permissions.ts | D13: setAuth / isAuthenticated / clearAuth / setUserRole / getUserRole | E13: FE-AUTH-03 | F13: FE-AuthState | G13: Keep the login state and role in localStorage and clear role, tokens and cached profile together on logout. | H13: localStorage is empty before each test
A14: 4 | B14: REQ-FE-AUTH Session & Access Handling | C14: permissions.ts | D14: getRoleRedirect / extractRole | E14: FE-AUTH-04 | F14: FE-RoleRedirectExtractRole | G14: Pick the landing page for a role and read the role from a login response (direct field, nested data, or JWT payload). | H14: Pure functions, no mocks
A15: 5 | B15: REQ-FE-STU Studio Question Display | C15: citation-display.ts | D15: isJdCitation / citationsForDisplay / formatCitationExcerpt / citationDisplayName | E15: FE-STU-01 | F15: FE-CitationDisplay | G15: Prepare question citations for display: detect the JD source, add a JD row when missing, shorten excerpts and show readable source names. | H15: Pure functions, no mocks
A16: 6 | B16: REQ-FE-STU Studio Question Display | C16: question-template-infer.ts | D16: inferStudioTemplate (template detection) | E16: FE-STU-02 | F16: FE-InferTemplate-Detect | G16: Detect the code template of a Studio question from its explicit template, content keywords, scoring rubric, type or snippet. | H16: Base question: Technical, Medium, no expected answer or rubric unless stated
A17: 7 | B17: REQ-FE-STU Studio Question Display | C17: question-template-infer.ts | D17: inferStudioTemplate (snippet & meta) | E17: FE-STU-03 | F17: FE-InferTemplate-Snippet | G17: Extract the code snippet (codeSnippet or fenced block, never expectedAnswer) and read language, image hint, diagram hint and attached image meta. | H17: Base question: Technical, Medium; neutral content unless stated
A18: 8 | B18: REQ-FE-STU Studio Question Display | C18: question-template-infer.ts | D18: inferGeneratedQuestionTemplate | E18: FE-STU-04 | F18: FE-InferGeneratedTemplate | G18: Map a saved (History/Review) question to the Studio template view model using its type, difficulty and rationale/rubric meta. | H18: Pure function, no mocks
A19: 9 | B19: REQ-FE-GAM Gamification Display | C19: gamification-formatters.ts | D19: formatXp / getLevelLabel / getLevelColorClass / getLevelBarColor / streakIntensity / xpRewardTypeLabel | E19: FE-GAM-01 | F19: FE-GamificationFormatters | G19: Format XP numbers and map levels, streaks and XP reward types to labels and colours. | H19: Pure functions, no mocks
A20: 10 | B20: REQ-FE-GAM Gamification Display | C20: gamification-formatters.ts | D20: timeAgo | E20: FE-GAM-02 | F20: FE-TimeAgo | G20: Show how long ago an XP event happened, in English and Vietnamese. | H20: System time fixed at 15/06/2026 12:00 UTC
A21: 11 | B21: REQ-FE-CAN Candidate Practice Display | C21: practice-streak.ts | D21: computeStreakDays | E21: FE-CAN-01 | F21: FE-ComputeStreakDays | G21: Count the consecutive practice days (ending today or yesterday) shown on the candidate dashboard. | H21: Session timestamps built relative to the real current date
A22: 12 | B22: REQ-FE-CAN Candidate Practice Display | C22: skill-labels.ts / company-visual.ts / pill.tsx | D22: translateDimensionKey / translateQuestionCategory / getCompanyInitials / getCompanyColor / formatCategoryLabel / getScoreBadgeClass / getScoreLevel | E22: FE-CAN-02 | F22: FE-LabelsCompanyScore | G22: Translate skill/category labels, build company initials and colours, and pick the score label and badge colour. | H22: Pure functions, no mocks
... A67: 57 | B67: REQ-BE-SUB Subscription Gates | C67: SubscriptionGateService | D67: CheckCoachGenerationAsync / CheckGeneratePersonalSetAsync | E67: BE-SUB-03 | F67: BE-GateCandidateCoach | G67: Allow the candidate AI Coach and personal question sets only on the Premium plan, trusting the plan code over a stale limits snapshot. | H67: Usage metering is an in-memory fake; limits snapshot = Candidate Free

Sheet Statistics
A2: UNIT TEST REPORT
A4: Project Name | B4: =Cover!B4 -> IQGS – AI-Powered Interview Question Generation System Using RAG and LLM – A Dual-Sided Platform for HR and Job Seekers | D4: Creator | F4: NamNM
A5: Project Code | B5: =Cover!B5 -> SU26SE102 | D5: Reviewer/Approver
A6: Document Code | B6: =B5&"_"&"Unit Test Report"&"_"&"v0.3.0" -> SU26SE102_Unit Test Report_v0.3.0 | D6: Issue Date | F6: 15/09/2026
A7: Notes | B7: This release covers 2 modules: Frontend logic (19 functions, 161 test cases, Vitest) and Backend application layer (38 functions, 232 test cases, xUnit). All test cases were executed on 15/09/2026 by Hoàng Đăng Khoa. UI component behaviour is reported as functional test cases in Report5_Test_Report.xlsx.
A11: No | B11: Function code | C11: Passed | D11: Failed | E11: Untested | F11: N | G11: A | H11: B | I11: Total Test Cases
A12: 1 | B12: FE-AUTH-01 | C12: ='FE-AuthInterceptor'!A7 -> 11 | D12: ='FE-AuthInterceptor'!C7 -> 0 | E12: ='FE-AuthInterceptor'!F7 -> 0 | F12: ='FE-AuthInterceptor'!L7 -> 3 | G12: ='FE-AuthInterceptor'!M7 -> 6 | H12: ='FE-AuthInterceptor'!N7 -> 2 | I12: ='FE-AuthInterceptor'!O7 -> 11
A13: 2 | B13: FE-AUTH-02 | C13: ='FE-ExtractErrorMessage'!A7 -> 4 | D13: ='FE-ExtractErrorMessage'!C7 -> 0 | E13: ='FE-ExtractErrorMessage'!F7 -> 0 | F13: ='FE-ExtractErrorMessage'!L7 -> 2 | G13: ='FE-ExtractErrorMessage'!M7 -> 1 | H13: ='FE-ExtractErrorMessage'!N7 -> 1 | I13: ='FE-ExtractErrorMessage'!O7 -> 4
A14: 3 | B14: FE-AUTH-03 | C14: ='FE-AuthState'!A7 -> 4 | D14: ='FE-AuthState'!C7 -> 0 | E14: ='FE-AuthState'!F7 -> 0 | F14: ='FE-AuthState'!L7 -> 4 | G14: ='FE-AuthState'!M7 -> 0 | H14: ='FE-AuthState'!N7 -> 0 | I14: ='FE-AuthState'!O7 -> 4
A15: 4 | B15: FE-AUTH-04 | C15: ='FE-RoleRedirectExtractRole'!A7 -> 11 | D15: ='FE-RoleRedirectExtractRole'!C7 -> 0 | E15: ='FE-RoleRedirectExtractRole'!F7 -> 0 | F15: ='FE-RoleRedirectExtractRole'!L7 -> 7 | G15: ='FE-RoleRedirectExtractRole'!M7 -> 2 | H15: ='FE-RoleRedirectExtractRole'!N7 -> 2 | I15: ='FE-RoleRedirectExtractRole'!O7 -> 11
A16: 5 | B16: FE-STU-01 | C16: ='FE-CitationDisplay'!A7 -> 7 | D16: ='FE-CitationDisplay'!C7 -> 0 | E16: ='FE-CitationDisplay'!F7 -> 0 | F16: ='FE-CitationDisplay'!L7 -> 5 | G16: ='FE-CitationDisplay'!M7 -> 0 | H16: ='FE-CitationDisplay'!N7 -> 2 | I16: ='FE-CitationDisplay'!O7 -> 7
A17: 6 | B17: FE-STU-02 | C17: ='FE-InferTemplate-Detect'!A7 -> 13 | D17: ='FE-InferTemplate-Detect'!C7 -> 0 | E17: ='FE-InferTemplate-Detect'!F7 -> 0 | F17: ='FE-InferTemplate-Detect'!L7 -> 10 | G17: ='FE-InferTemplate-Detect'!M7 -> 1 | H17: ='FE-InferTemplate-Detect'!N7 -> 2 | I17: ='FE-InferTemplate-Detect'!O7 -> 13
A18: 7 | B18: FE-STU-03 | C18: ='FE-InferTemplate-Snippet'!A7 -> 12 | D18: ='FE-InferTemplate-Snippet'!C7 -> 0 | E18: ='FE-InferTemplate-Snippet'!F7 -> 0 | F18: ='FE-InferTemplate-Snippet'!L7 -> 6 | G18: ='FE-InferTemplate-Snippet'!M7 -> 3 | H18: ='FE-InferTemplate-Snippet'!N7 -> 3 | I18: ='FE-InferTemplate-Snippet'!O7 -> 12
A19: 8 | B19: FE-STU-04 | C19: ='FE-InferGeneratedTemplate'!A7 -> 3 | D19: ='FE-InferGeneratedTemplate'!C7 -> 0 | E19: ='FE-InferGeneratedTemplate'!F7 -> 0 | F19: ='FE-InferGeneratedTemplate'!L7 -> 2 | G19: ='FE-InferGeneratedTemplate'!M7 -> 0 | H19: ='FE-InferGeneratedTemplate'!N7 -> 1 | I19: ='FE-InferGeneratedTemplate'!O7 -> 3
A20: 9 | B20: FE-GAM-01 | C20: ='FE-GamificationFormatters'!A7 -> 14 | D20: ='FE-GamificationFormatters'!C7 -> 0 | E20: ='FE-GamificationFormatters'!F7 -> 0 | F20: ='FE-GamificationFormatters'!L7 -> 2 | G20: ='FE-GamificationFormatters'!M7 -> 0 | H20: ='FE-GamificationFormatters'!N7 -> 12 | I20: ='FE-GamificationFormatters'!O7 -> 14
A21: 10 | B21: FE-GAM-02 | C21: ='FE-TimeAgo'!A7 -> 10 | D21: ='FE-TimeAgo'!C7 -> 0 | E21: ='FE-TimeAgo'!F7 -> 0 | F21: ='FE-TimeAgo'!L7 -> 8 | G21: ='FE-TimeAgo'!M7 -> 0 | H21: ='FE-TimeAgo'!N7 -> 2 | I21: ='FE-TimeAgo'!O7 -> 10
A22: 11 | B22: FE-CAN-01 | C22: ='FE-ComputeStreakDays'!A7 -> 8 | D22: ='FE-ComputeStreakDays'!C7 -> 0 | E22: ='FE-ComputeStreakDays'!F7 -> 0 | F22: ='FE-ComputeStreakDays'!L7 -> 2 | G22: ='FE-ComputeStreakDays'!M7 -> 3 | H22: ='FE-ComputeStreakDays'!N7 -> 3 | I22: ='FE-ComputeStreakDays'!O7 -> 8
A23: 12 | B23: FE-CAN-02 | C23: ='FE-LabelsCompanyScore'!A7 -> 9 | D23: ='FE-LabelsCompanyScore'!C7 -> 0 | E23: ='FE-LabelsCompanyScore'!F7 -> 0 | F23: ='FE-LabelsCompanyScore'!L7 -> 5 | G23: ='FE-LabelsCompanyScore'!M7 -> 1 | H23: ='FE-LabelsCompanyScore'!N7 -> 3 | I23: ='FE-LabelsCompanyScore'!O7 -> 9
A24: 13 | B24: FE-ADM-01 | C24: ='FE-AdminUserDisplay'!A7 -> 13 | D24: ='FE-AdminUserDisplay'!C7 -> 0 | E24: ='FE-AdminUserDisplay'!F7 -> 0 | F24: ='FE-AdminUserDisplay'!L7 -> 8 | G24: ='FE-AdminUserDisplay'!M7 -> 2 | H24: ='FE-AdminUserDisplay'!N7 -> 3 | I24: ='FE-AdminUserDisplay'!O7 -> 13
A25: 14 | B25: FE-SHR-01 | C25: ='FE-GreetingLoginWelcome'!A7 -> 8 | D25: ='FE-GreetingLoginWelcome'!C7 -> 0 | E25: ='FE-GreetingLoginWelcome'!F7 -> 0 | F25: ='FE-GreetingLoginWelcome'!L7 -> 2 | G25: ='FE-GreetingLoginWelcome'!M7 -> 1 | H25: ='FE-GreetingLoginWelcome'!N7 -> 5 | I25: ='FE-GreetingLoginWelcome'!O7 -> 8
A26: 15 | B26: FE-SHR-02 | C26: ='FE-FormatRelativeTime'!A7 -> 9 | D26: ='FE-FormatRelativeTime'!C7 -> 0 | E26: ='FE-FormatRelativeTime'!F7 -> 0 | F26: ='FE-FormatRelativeTime'!L7 -> 6 | G26: ='FE-FormatRelativeTime'!M7 -> 1 | H26: ='FE-FormatRelativeTime'!N7 -> 2 | I26: ='FE-FormatRelativeTime'!O7 -> 9
A27: 16 | B27: FE-SHR-03 | C27: ='FE-NavUserDisplay'!A7 -> 8 | D27: ='FE-NavUserDisplay'!C7 -> 0 | E27: ='FE-NavUserDisplay'!F7 -> 0 | F27: ='FE-NavUserDisplay'!L7 -> 4 | G27: ='FE-NavUserDisplay'!M7 -> 2 | H27: ='FE-NavUserDisplay'!N7 -> 2 | I27: ='FE-NavUserDisplay'!O7 -> 8
A28: 17 | B28: FE-SHR-04 | C28: ='FE-UrlAvatarMessages'!A7 -> 7 | D28: ='FE-UrlAvatarMessages'!C7 -> 0 | E28: ='FE-UrlAvatarMessages'!F7 -> 0 | F28: ='FE-UrlAvatarMessages'!L7 -> 3 | G28: ='FE-UrlAvatarMessages'!M7 -> 3 | H28: ='FE-UrlAvatarMessages'!N7 -> 1 | I28: ='FE-UrlAvatarMessages'!O7 -> 7
A29: 18 | B29: FE-SUB-01 | C29: ='FE-SubscriptionRealtime'!A7 -> 6 | D29: ='FE-SubscriptionRealtime'!C7 -> 0 | E29: ='FE-SubscriptionRealtime'!F7 -> 0 | F29: ='FE-SubscriptionRealtime'!L7 -> 3 | G29: ='FE-SubscriptionRealtime'!M7 -> 2 | H29: ='FE-SubscriptionRealtime'!N7 -> 1 | I29: ='FE-SubscriptionRealtime'!O7 -> 6
A30: 19 | B30: FE-SUB-02 | C30: ='FE-CandidatePlanCache'!A7 -> 4 | D30: ='FE-CandidatePlanCache'!C7 -> 0 | E30: ='FE-CandidatePlanCache'!F7 -> 0 | F30: ='FE-CandidatePlanCache'!L7 -> 2 | G30: ='FE-CandidatePlanCache'!M7 -> 1 | H30: ='FE-CandidatePlanCache'!N7 -> 1 | I30: ='FE-CandidatePlanCache'!O7 -> 4
A31: 20 | B31: BE-CAN-01 | C31: ='BE-CvCoachPromptBuilder'!A7 -> 3 | D31: ='BE-CvCoachPromptBuilder'!C7 -> 0 | E31: ='BE-CvCoachPromptBuilder'!F7 -> 0 | F31: ='BE-CvCoachPromptBuilder'!L7 -> 3 | G31: ='BE-CvCoachPromptBuilder'!M7 -> 0 | H31: ='BE-CvCoachPromptBuilder'!N7 -> 0 | I31: ='BE-CvCoachPromptBuilder'!O7 -> 3
A32: 21 | B32: BE-CAN-02 | C32: ='BE-SkillPlanResolveStatus'!A7 -> 1 | D32: ='BE-SkillPlanResolveStatus'!C7 -> 0 | E32: ='BE-SkillPlanResolveStatus'!F7 -> 0 | F32: ='BE-SkillPlanResolveStatus'!L7 -> 0 | G32: ='BE-SkillPlanResolveStatus'!M7 -> 0 | H32: ='BE-SkillPlanResolveStatus'!N7 -> 1 | I32: ='BE-SkillPlanResolveStatus'!O7 -> 1
A33: 22 | B33: BE-CAN-03 | C33: ='BE-SkillMatchHelper'!A7 -> 3 | D33: ='BE-SkillMatchHelper'!C7 -> 0 | E33: ='BE-SkillMatchHelper'!F7 -> 0 | F33: ='BE-SkillMatchHelper'!L7 -> 2 | G33: ='BE-SkillMatchHelper'!M7 -> 0 | H33: ='BE-SkillMatchHelper'!N7 -> 1 | I33: ='BE-SkillMatchHelper'!O7 -> 3
A34: 23 | B34: BE-GAM-01 | C34: ='BE-AchievementRules'!A7 -> 9 | D34: ='BE-AchievementRules'!C7 -> 0 | E34: ='BE-AchievementRules'!F7 -> 0 | F34: ='BE-AchievementRules'!L7 -> 1 | G34: ='BE-AchievementRules'!M7 -> 0 | H34: ='BE-AchievementRules'!N7 -> 8 | I34: ='BE-AchievementRules'!O7 -> 9
A35: 24 | B35: BE-GAM-02 | C35: ='BE-LevelCalculator-Level'!A7 -> 15 | D35: ='BE-LevelCalculator-Level'!C7 -> 0 | E35: ='BE-LevelCalculator-Level'!F7 -> 0 | F35: ='BE-LevelCalculator-Level'!L7 -> 0 | G35: ='BE-LevelCalculator-Level'!M7 -> 0 | H35: ='BE-LevelCalculator-Level'!N7 -> 15 | I35: ='BE-LevelCalculator-Level'!O7 -> 15
A36: 25 | B36: BE-GAM-03 | C36: ='BE-LevelCalculator-Xp'!A7 -> 15 | D36: ='BE-LevelCalculator-Xp'!C7 -> 0 | E36: ='BE-LevelCalculator-Xp'!F7 -> 0 | F36: ='BE-LevelCalculator-Xp'!L7 -> 13 | G36: ='BE-LevelCalculator-Xp'!M7 -> 0 | H36: ='BE-LevelCalculator-Xp'!N7 -> 2 | I36: ='BE-LevelCalculator-Xp'!O7 -> 15
A37: 26 | B37: BE-GAM-04 | C37: ='BE-StreakCalculator'!A7 -> 6 | D37: ='BE-StreakCalculator'!C7 -> 0 | E37: ='BE-StreakCalculator'!F7 -> 0 | F37: ='BE-StreakCalculator'!L7 -> 3 | G37: ='BE-StreakCalculator'!M7 -> 1 | H37: ='BE-StreakCalculator'!N7 -> 2 | I37: ='BE-StreakCalculator'!O7 -> 6
A38: 27 | B38: BE-GAM-05 | C38: ='BE-UserLocalDateProvider'!A7 -> 4 | D38: ='BE-UserLocalDateProvider'!C7 -> 0 | E38: ='BE-UserLocalDateProvider'!F7 -> 0 | F38: ='BE-UserLocalDateProvider'!L7 -> 1 | G38: ='BE-UserLocalDateProvider'!M7 -> 3 | H38: ='BE-UserLocalDateProvider'!N7 -> 0 | I38: ='BE-UserLocalDateProvider'!O7 -> 4
A39: 28 | B39: BE-GAM-06 | C39: ='BE-XpRewardPolicy-Score'!A7 -> 10 | D39: ='BE-XpRewardPolicy-Score'!C7 -> 0 | E39: ='BE-XpRewardPolicy-Score'!F7 -> 0 | F39: ='BE-XpRewardPolicy-Score'!L7 -> 0 | G39: ='BE-XpRewardPolicy-Score'!M7 -> 2 | H39: ='BE-XpRewardPolicy-Score'!N7 -> 8 | I39: ='BE-XpRewardPolicy-Score'!O7 -> 10
A40: 29 | B40: BE-GAM-07 | C40: ='BE-XpRewardPolicy-Bonus'!A7 -> 11 | D40: ='BE-XpRewardPolicy-Bonus'!C7 -> 0 | E40: ='BE-XpRewardPolicy-Bonus'!F7 -> 0 | F40: ='BE-XpRewardPolicy-Bonus'!L7 -> 8 | G40: ='BE-XpRewardPolicy-Bonus'!M7 -> 0 | H40: ='BE-XpRewardPolicy-Bonus'!N7 -> 3 | I40: ='BE-XpRewardPolicy-Bonus'!O7 -> 11
A41: 30 | B41: BE-QS-01 | C41: ='BE-PublishQuestionSelection'!A7 -> 4 | D41: ='BE-PublishQuestionSelection'!C7 -> 0 | E41: ='BE-PublishQuestionSelection'!F7 -> 0 | F41: ='BE-PublishQuestionSelection'!L7 -> 2 | G41: ='BE-PublishQuestionSelection'!M7 -> 1 | H41: ='BE-PublishQuestionSelection'!N7 -> 1 | I41: ='BE-PublishQuestionSelection'!O7 -> 4
A42: 31 | B42: BE-QS-02 | C42: ='BE-RubricNormalizer'!A7 -> 4 | D42: ='BE-RubricNormalizer'!C7 -> 0 | E42: ='BE-RubricNormalizer'!F7 -> 0 | F42: ='BE-RubricNormalizer'!L7 -> 4 | G42: ='BE-RubricNormalizer'!M7 -> 0 | H42: ='BE-RubricNormalizer'!N7 -> 0 | I42: ='BE-RubricNormalizer'!O7 -> 4
A43: 32 | B43: BE-QS-03 | C43: ='BE-CitationSourceScope'!A7 -> 3 | D43: ='BE-CitationSourceScope'!C7 -> 0 | E43: ='BE-CitationSourceScope'!F7 -> 0 | F43: ='BE-CitationSourceScope'!L7 -> 3 | G43: ='BE-CitationSourceScope'!M7 -> 0 | H43: ='BE-CitationSourceScope'!N7 -> 0 | I43: ='BE-CitationSourceScope'!O7 -> 3
A44: 33 | B44: BE-HR-01 | C44: ='BE-JdFitReviewMapper'!A7 -> 8 | D44: ='BE-JdFitReviewMapper'!C7 -> 0 | E44: ='BE-JdFitReviewMapper'!F7 -> 0 | F44: ='BE-JdFitReviewMapper'!L7 -> 6 | G44: ='BE-JdFitReviewMapper'!M7 -> 2 | H44: ='BE-JdFitReviewMapper'!N7 -> 0 | I44: ='BE-JdFitReviewMapper'!O7 -> 8
A45: 34 | B45: BE-HR-02 | C45: ='BE-JdFitContentHash'!A7 -> 1 | D45: ='BE-JdFitContentHash'!C7 -> 0 | E45: ='BE-JdFitContentHash'!F7 -> 0 | F45: ='BE-JdFitContentHash'!L7 -> 1 | G45: ='BE-JdFitContentHash'!M7 -> 0 | H45: ='BE-JdFitContentHash'!N7 -> 0 | I45: ='BE-JdFitContentHash'!O7 -> 1
...

Sheet FE-AuthInterceptor
A2: Function Code | C2: =Functions!E11 -> FE-AUTH-01 | F2: Function Name | L2: =Functions!D11 -> attachAuthInterceptor
A3: Created By | C3: Hoàng Đăng Khoa | F3: Executed By | L3: Hoàng Đăng Khoa
A4: Lines of code | C4: 44 | F4: Lack of test cases | L4: =IF(Functions!E6<>"N/A",SUM(C4*Functions!E6/1000,-O7),"N/A") -> -6.6
A5: Test requirement | C5: Axios interceptor: on 401 refreshes the access token once, retries the request, shares one refresh between concurrent 401s, and clears auth + redirects to /login when the session cannot be refreshed.
A6: Passed | C6: Failed | F6: Untested | L6: N/A/B | O6: Total Test Cases
A7: =COUNTIF(F37:T37,"P") -> 11 | C7: =COUNTIF(F37:T37,"F") -> 0 | F7: =SUM(O7,-A7,-C7) -> 0 | L7: =COUNTIF(F36:T36,"N") -> 3 | M7: =COUNTIF(F36:T36,"A") -> 6 | N7: =COUNTIF(F36:T36,"B") -> 2 | O7: =COUNTA(F9:T9) -> 11
F9: UTCID01 | G9: UTCID02 | H9: UTCID03 | I9: UTCID04 | J9: UTCID05 | K9: UTCID06 | L9: UTCID07 | M9: UTCID08 | N9: UTCID09 | O9: UTCID10 | P9: UTCID11
A10: Condition | B10: Precondition
B11: Axios client created with attachAuthInterceptor() | F11: O | G11: O | H11: O | I11: O | J11: O | K11: O | L11: O | M11: O | N11: O | O11: O | P11: O
B12: Access token "expired.jwt.token" and a refresh token are stored; current page /hr/generate-question/manual | F12: O | G12: O | H12: O | I12: O | J12: O | K12: O | L12: O | M12: O | N12: O | O12: O | P12: O
B13: Input
B14: GET /api/users/me returns 401 once, then 200; refresh returns new tokens | F14: O
B15: GET returns 401; refresh endpoint returns 401 | G15: O | N15: O
B16: No refresh token stored; GET returns 401 | H16: O
B17: POST /api/auth/refresh-token itself returns 401 | I17: O
B18: POST /api/auth/login (public endpoint) returns 401 | J18: O
B19: GET returns 403 | K19: O
B20: GET returns 401 on the original call and on the retry; refresh succeeds | L20: O
B21: Any request (GET /api/whatever returns 200) | M21: O
B22: GET returns 401 once, then 200; refresh returns rotated tokens | O22: O
B23: Two concurrent requests both return 401 once; refresh takes 50 ms | P23: O
A24: Confirm | B24: Return
B25: Request resolves 200 after one retry; setAuthTokens(new tokens); no clearAuth, no redirect | F25: O
B26: Request rejects with 401; clearAuth() called once; redirect to /login | G26: O
B27: Refresh endpoint never called; clearAuth() called once | H27: O
B28: Request rejects; refresh called only once (no loop); clearAuth() called once | I28: O
B29: Request rejects with 401; no refresh attempt; clearAuth() not called | J29: O
B30: Request rejects with 403; no refresh attempt; clearAuth() not called | K30: O
B31: Refresh called once, request retried once, then rejects; clearAuth() called once | L31: O
B32: Authorization header "Bearer expired.jwt.token" comes from getAccessToken(), not from a cookie | M32: O
B33: clearAuth() called once (also clears the cached profile) | N33: O
B34: setAuthTokens("rotated-access-token", "rotated-refresh-token") | O34: O
B35: Both requests resolve 200; refresh endpoint called exactly once; no clearAuth | P35: O
A36: Result | B36: Type(N : Normal, A : Abnormal, B : Boundary) | F36: N | G36: A | H36: A | I36: A | J36: A | K36: A | L36: B | M36: N | N36: A | O36: N | P36: B
B37: Passed/Failed | F37: P | G37: P | H37: P | I37: P | J37: P | K37: P | L37: P | M37: P | N37: P | O37: P | P37: P
B38: Executed Date | F38: 15/09/2026 | G38: 15/09/2026 | H38: 15/09/2026 | I38: 15/09/2026 | J38: 15/09/2026 | K38: 15/09/2026 | L38: 15/09/2026 | M38: 15/09/2026 | N38: 15/09/2026 | O38: 15/09/2026 | P38: 15/09/2026
B39: Defect ID

Sheet FE-ExtractErrorMessage
A2: Function Code | C2: =Functions!E12 -> FE-AUTH-02 | F2: Function Name | L2: =Functions!D12 -> extractErrorMessage
A3: Created By | C3: Hoàng Đăng Khoa | F3: Executed By | L3: Hoàng Đăng Khoa
A4: Lines of code | C4: 28 | F4: Lack of test cases | L4: =IF(Functions!E6<>"N/A",SUM(C4*Functions!E6/1000,-O7),"N/A") -> -1.2
A5: Test requirement | C5: Turn an API error into the message shown to the user: canned text for known error codes, the server message when present, friendly text for bare 5xx and a generic fallback.
A6: Passed | C6: Failed | F6: Untested | L6: N/A/B | O6: Total Test Cases
A7: =COUNTIF(F23:T23,"P") -> 4 | C7: =COUNTIF(F23:T23,"F") -> 0 | F7: =SUM(O7,-A7,-C7) -> 0 | L7: =COUNTIF(F22:T22,"N") -> 2 | M7: =COUNTIF(F22:T22,"A") -> 1 | N7: =COUNTIF(F22:T22,"B") -> 1 | O7: =COUNTA(F9:T9) -> 4
F9: UTCID01 | G9: UTCID02 | H9: UTCID03 | I9: UTCID04
A10: Condition | B10: Precondition
B11: Pure function, no mocks | F11: O | G11: O | H11: O | I11: O
B12: Input
B13: error.response = { status: 500, data: {} } | F13: O
B14: response 400 with data.message "Job description is required." | G14: O
B15: response 403 with data.errorCode QUOTA_EXCEEDED | H15: O
B16: error = undefined | I16: O
A17: Confirm | B17: Return
B18: "The server is temporarily unavailable, so the job description could not be analyzed. Please try again later." | F18: O
B19: "Job description is required." | G19: O
B20: "You've used up your quota for this period. Upgrade to Premium or buy an extra Ask-AI pack." | H20: O
B21: "Something went wrong. Please try again." | I21: O
A22: Result | B22: Type(N : Normal, A : Abnormal, B : Boundary) | F22: A | G22: N | H22: N | I22: B
B23: Passed/Failed | F23: P | G23: P | H23: P | I23: P
B24: Executed Date | F24: 15/09/2026 | G24: 15/09/2026 | H24: 15/09/2026 | I24: 15/09/2026
B25: Defect ID

Sheet FE-AuthState
A2: Function Code | C2: =Functions!E13 -> FE-AUTH-03 | F2: Function Name | L2: =Functions!D13 -> setAuth / isAuthenticated / clearAuth / setUserRole / getUserRole
A3: Created By | C3: Hoàng Đăng Khoa | F3: Executed By | L3: Hoàng Đăng Khoa
A4: Lines of code | C4: 23 | F4: Lack of test cases | L4: =IF(Functions!E6<>"N/A",SUM(C4*Functions!E6/1000,-O7),"N/A") -> -1.7
A5: Test requirement | C5: Keep the login state and role in localStorage and clear role, tokens and cached profile together on logout.
A6: Passed | C6: Failed | F6: Untested | L6: N/A/B | O6: Total Test Cases
A7: =COUNTIF(F23:T23,"P") -> 4 | C7: =COUNTIF(F23:T23,"F") -> 0 | F7: =SUM(O7,-A7,-C7) -> 0 | L7: =COUNTIF(F22:T22,"N") -> 4 | M7: =COUNTIF(F22:T22,"A") -> 0 | N7: =COUNTIF(F22:T22,"B") -> 0 | O7: =COUNTA(F9:T9) -> 4
F9: UTCID01 | G9: UTCID02 | H9: UTCID03 | I9: UTCID04
A10: Condition | B10: Precondition
B11: localStorage is empty before each test | F11: O | G11: O | H11: O | I11: O
B12: Input
B13: setAuth() then clearAuth() | F13: O
B14: Only setAuthTokens("real.jwt.token") called | G14: O
B15: setUserRole("HR_MANAGER") | H15: O
B16: Flag, role ADMIN, tokens and cached profile set; clearAuth() called | I16: O
A17: Confirm | B17: Return
B18: isAuthenticated(): false, then true after setAuth, then false after clearAuth | F18: O
B19: isAuthenticated() = true | G19: O
B20: getUserRole(): null before, "HR_MANAGER" after | H20: O
B21: getUserRole(), getAccessToken() and getCachedUserProfile() all return null | I21: O
A22: Result | B22: Type(N : Normal, A : Abnormal, B : Boundary) | F22: N | G22: N | H22: N | I22: N
B23: Passed/Failed | F23: P | G23: P | H23: P | I23: P
B24: Executed Date | F24: 15/09/2026 | G24: 15/09/2026 | H24: 15/09/2026 | I24: 15/09/2026
B25: Defect ID

Sheet FE-RoleRedirectExtractRole
A2: Function Code | C2: =Functions!E14 -> FE-AUTH-04 | F2: Function Name | L2: =Functions!D14 -> getRoleRedirect / extractRole
A3: Created By | C3: Hoàng Đăng Khoa | F3: Executed By | L3: Hoàng Đăng Khoa
A4: Lines of code | C4: 27 | F4: Lack of test cases | L4: =IF(Functions!E6<>"N/A",SUM(C4*Functions!E6/1000,-O7),"N/A") -> -8.3
A5: Test requirement | C5: Pick the landing page for a role and read the role from a login response (direct field, nested data, or JWT payload).
A6: Passed | C6: Failed | F6: Untested | L6: N/A/B | O6: Total Test Cases
A7: =COUNTIF(F34:T34,"P") -> 11 | C7: =COUNTIF(F34:T34,"F") -> 0 | F7: =SUM(O7,-A7,-C7) -> 0 | L7: =COUNTIF(F33:T33,"N") -> 7 | M7: =COUNTIF(F33:T33,"A") -> 2 | N7: =COUNTIF(F33:T33,"B") -> 2 | O7: =COUNTA(F9:T9) -> 11
F9: UTCID01 | G9: UTCID02 | H9: UTCID03 | I9: UTCID04 | J9: UTCID05 | K9: UTCID06 | L9: UTCID07 | M9: UTCID08 | N9: UTCID09 | O9: UTCID10 | P9: UTCID11
A10: Condition | B10: Precondition
B11: Pure functions, no mocks | F11: O | G11: O | H11: O | I11: O | J11: O | K11: O | L11: O | M11: O | N11: O | O11: O | P11: O
B12: Input
B13: getRoleRedirect("SUPER_ADMIN") | F13: O
B14: getRoleRedirect("HR_MANAGER") | G14: O
B15: getRoleRedirect(null) | H15: O
B16: extractRole({ role: "HR_MANAGER" }) | I16: O
B17: extractRole({ data: { role: "ADMIN" } }) | J17: O
B18: JWT with role JOB_SEEKER under accessToken | K18: O
B19: JWT with role JOB_SEEKER under access_token | L19: O
B20: JWT with role JOB_SEEKER under token | M20: O
B21: JWT with claim Role = HR_MANAGER | N21: O
B22: { accessToken: "not-a-jwt" } | O22: O
B23: null, "a string" or {} | P23: O
A24: Confirm | B24: Return
B25: "/admin/dashboard" | F25: O
B26: "/hr/dashboard" | G26: O
B27: "/candidate" | H27: O
B28: "HR_MANAGER" | I28: O | N28: O
B29: "ADMIN" | J29: O
B30: "JOB_SEEKER" | K30: O | L30: O | M30: O
B31: null (no exception) | O31: O
B32: null | P32: O
A33: Result | B33: Type(N : Normal, A : Abnormal, B : Boundary) | F33: N | G33: N | H33: B | I33: N | J33: N | K33: N | L33: N | M33: N | N33: B | O33: A | P33: A
B34: Passed/Failed | F34: P | G34: P | H34: P | I34: P | J34: P | K34: P | L34: P | M34: P | N34: P | O34: P | P34: P
B35: Executed Date | F35: 15/09/2026 | G35: 15/09/2026 | H35: 15/09/2026 | I35: 15/09/2026 | J35: 15/09/2026 | K35: 15/09/2026 | L35: 15/09/2026 | M35: 15/09/2026 | N35: 15/09/2026 | O35: 15/09/2026 | P35: 15/09/2026
B36: Defect ID

Sheet FE-CitationDisplay
A2: Function Code | C2: =Functions!E15 -> FE-STU-01 | F2: Function Name | L2: =Functions!D15 -> isJdCitation / citationsForDisplay / formatCitationExcerpt / citationDisplayName
A3: Created By | C3: Hoàng Đăng Khoa | F3: Executed By | L3: Hoàng Đăng Khoa
A4: Lines of code | C4: 25 | F4: Lack of test cases | L4: =IF(Functions!E6<>"N/A",SUM(C4*Functions!E6/1000,-O7),"N/A") -> -4.5
A5: Test requirement | C5: Prepare question citations for display: detect the JD source, add a JD row when missing, shorten excerpts and show readable source names.
A6: Passed | C6: Failed | F6: Untested | L6: N/A/B | O6: Total Test Cases
A7: =COUNTIF(F28:T28,"P") -> 7 | C7: =COUNTIF(F28:T28,"F") -> 0 | F7: =SUM(O7,-A7,-C7) -> 0 | L7: =COUNTIF(F27:T27,"N") -> 5 | M7: =COUNTIF(F27:T27,"A") -> 0 | N7: =COUNTIF(F27:T27,"B") -> 2 | O7: =COUNTA(F9:T9) -> 7
F9: UTCID01 | G9: UTCID02 | H9: UTCID03 | I9: UTCID04 | J9: UTCID05 | K9: UTCID06 | L9: UTCID07
A10: Condition | B10: Precondition
B11: Pure functions, no mocks | F11: O | G11: O | H11: O | I11: O | J11: O | K11: O | L11: O
B12: Input
B13: isJdCitation("Job Description") | F13: O
B14: isJdCitation("handbook.pdf") | G14: O
B15: isJdCitation(null) | H15: O
B16: citations = [handbook.pdf] | I16: O
B17: citations = [job-description with excerpt] | J17: O
B18: " short text ", null, " ", 200 characters with max 140 | K18: O
B19: "job-description" / "handbook.pdf" | L19: O
A20: Confirm | B20: Return
B21: true | F21: O
B22: false | G22: O | H22: O
B23: 2 rows; first = { sourceFile: job-description, excerpt: null, origin: HR } | I23: O
B24: 1 row with the original excerpt | J24: O
B25: "short text"; null; null; 140 characters + "…" | K25: O
B26: "Job Description" / "handbook.pdf" | L26: O
A27: Result | B27: Type(N : Normal, A : Abnormal, B : Boundary) | F27: N | G27: N | H27: B | I27: N | J27: N | K27: B | L27: N
B28: Passed/Failed | F28: P | G28: P | H28: P | I28: P | J28: P | K28: P | L28: P
B29: Executed Date | F29: 15/09/2026 | G29: 15/09/2026 | H29: 15/09/2026 | I29: 15/09/2026 | J29: 15/09/2026 | K29: 15/09/2026 | L29: 15/09/2026
B30: Defect ID

Sheet FE-InferTemplate-Detect
A2: Function Code | C2: =Functions!E16 -> FE-STU-02 | F2: Function Name | L2: =Functions!D16 -> inferStudioTemplate (template detection)
A3: Created By | C3: Hoàng Đăng Khoa | F3: Executed By | L3: Hoàng Đăng Khoa
A4: Lines of code | C4: 62 | F4: Lack of test cases | L4: =IF(Functions!E6<>"N/A",SUM(C4*Functions!E6/1000,-O7),"N/A") -> -6.8
A5: Test requirement | C5: Detect the code template of a Studio question from its explicit template, content keywords, scoring rubric, type or snippet.
A6: Passed | C6: Failed | F6: Untested | L6: N/A/B | O6: Total Test Cases
A7: =COUNTIF(F35:T35,"P") -> 13 | C7: =COUNTIF(F35:T35,"F") -> 0 | F7: =SUM(O7,-A7,-C7) -> 0 | L7: =COUNTIF(F34:T34,"N") -> 10 | M7: =COUNTIF(F34:T34,"A") -> 1 | N7: =COUNTIF(F34:T34,"B") -> 2 | O7: =COUNTA(F9:T9) -> 13
F9: UTCID01 | G9: UTCID02 | H9: UTCID03 | I9: UTCID04 | J9: UTCID05 | K9: UTCID06 | L9: UTCID07 | M9: UTCID08 | N9: UTCID09 | O9: UTCID10 | P9: UTCID11 | Q9: UTCID12 | R9: UTCID13
A10: Condition | B10: Precondition
B11: Base question: Technical, Medium, no expected answer or rubric unless stated | F11: O | G11: O | H11: O | I11: O | J11: O | K11: O | L11: O | M11: O | N11: O | O11: O | P11: O | Q11: O | R11: O
B12: Input
B13: codeTemplateType "bug_detection", content "Find the bug" | F13: O
B14: codeTemplateType " refactoring " | G14: O
B15: codeTemplateType NOT_A_REAL_TEMPLATE, content mentions system design | H15: O
B16: content "Design a system architecture (system design) for a URL shortener." | I16: O
B17: content "Complete the TODO in this function (code completion)." | J17: O
B18: content "Find the bug in this loop." | K18: O
B19: content "Refactor this class to remove duplication." | L19: O
B20: content "Write a unit test case for this function." | M20: O
B21: content "Analyze the time complexity O(n^2) of this algorithm." | N21: O
B22: Neutral content, scoringRubric "Look for bug handling" | O22: O
B23: type SystemDesign, neutral content | P23: O
B24: Neutral content with a codeSnippet | Q24: O
B25: "Explain the difference between REST and GraphQL." only | R25: O
A26: Confirm | B26: Return
B27: templateId BUG_DETECTION | F27: O | K27: O | O27: O
B28: templateId REFACTORING | G28: O | L28: O
B29: templateId SYSTEM_DESIGN | H29: O | I29: O | P29: O
B30: templateId CODE_COMPLETION | J30: O | Q30: O
B31: templateId TEST_CASE_DESIGN | M31: O
B32: templateId PERFORMANCE_ANALYSIS | N32: O
B33: templateId null; imageHint not empty | R33: O
A34: Result | B34: Type(N : Normal, A : Abnormal, B : Boundary) | F34: N | G34: B | H34: A | I34: N | J34: N | K34: N | L34: N | M34: N | N34: N | O34: N | P34: N | Q34: N | R34: B
B35: Passed/Failed | F35: P | G35: P | H35: P | I35: P | J35: P | K35: P | L35: P | M35: P | N35: P | O35: P | P35: P | Q35: P | R35: P
B36: Executed Date | F36: 15/09/2026 | G36: 15/09/2026 | H36: 15/09/2026 | I36: 15/09/2026 | J36: 15/09/2026 | K36: 15/09/2026 | L36: 15/09/2026 | M36: 15/09/2026 | N36: 15/09/2026 | O36: 15/09/2026 | P36: 15/09/2026 | Q36: 15/09/2026 | R36: 15/09/2026
B37: Defect ID

Sheet FE-InferTemplate-Snippet
A2: Function Code | C2: =Functions!E17 -> FE-STU-03 | F2: Function Name | L2: =Functions!D17 -> inferStudioTemplate (snippet & meta)
A3: Created By | C3: Hoàng Đăng Khoa | F3: Executed By | L3: Hoàng Đăng Khoa
A4: Lines of code | C4: 62 | F4: Lack of test cases | L4: =IF(Functions!E6<>"N/A",SUM(C4*Functions!E6/1000,-O7),"N/A") -> -5.8
A5: Test requirement | C5: Extract the code snippet (codeSnippet or fenced block, never expectedAnswer) and read language, image hint, diagram hint and attached image meta.
A6: Passed | C6: Failed | F6: Untested | L6: N/A/B | O6: Total Test Cases
A7: =COUNTIF(F36:T36,"P") -> 12 | C7: =COUNTIF(F36:T36,"F") -> 0 | F7: =SUM(O7,-A7,-C7) -> 0 | L7: =COUNTIF(F35:T35,"N") -> 6 | M7: =COUNTIF(F35:T35,"A") -> 3 | N7: =COUNTIF(F35:T35,"B") -> 3 | O7: =COUNTA(F9:T9) -> 12
F9: UTCID01 | G9: UTCID02 | H9: UTCID03 | I9: UTCID04 | J9: UTCID05 | K9: UTCID06 | L9: UTCID07 | M9: UTCID08 | N9: UTCID09 | O9: UTCID10 | P9: UTCID11 | Q9: UTCID12
A10: Condition | B10: Precondition
B11: Base question: Technical, Medium; neutral content unless stated | F11: O | G11: O | H11: O | I11: O | J11: O | K11: O | L11: O | M11: O | N11: O | O11: O | P11: O | Q11: O
B12: Input
B13: codeSnippet "const x = 1;" | F13: O
B14: expectedAnswer contains a "Code snippet:" marker | G14: O
B15: content with a ```js fenced block | H15: O
B16: expectedAnswer is raw class code | I16: O
B17: expectedAnswer is plain prose | J17: O
B18: codeSnippet with literal \n escape sequences | K18: O
B19: scoringRubric "lang=TypeScript;template=CODE_COMPLETION" | L19: O
B20: scoringRubric "lang=auto" | M20: O
B21: imageHint "Custom hint" with template BUG_DETECTION | N21: O
B22: "Find the bug in this loop." without imageHint | O22: O
B23: System design content with / without diagramHint meta | P23: O
B24: attachedImageUrl " https://x/img.png " / " " | Q24: O
A25: Confirm | B25: Return
B26: snippet "const x = 1;" | F26: O | H26: O
B27: snippet undefined | G27: O | I27: O | J27: O
B28: snippet contains real line breaks | K28: O
B29: snippetLanguage "typescript" | L29: O
B30: snippetLanguage undefined | M30: O
B31: imageHint "Custom hint" | N31: O
B32: Default image hint of the template (contains "lỗi") | O32: O
B33: diagramDescription from meta / default (contains "sơ đồ kiến trúc") | P33: O
B34: "https://x/img.png" / undefined | Q34: O
A35: Result | B35: Type(N : Normal, A : Abnormal, B : Boundary) | F35: N | G35: A | H35: N | I35: A | J35: A | K35: B | L35: N | M35: B | N35: N | O35: N | P35: N | Q35: B
B36: Passed/Failed | F36: P | G36: P | H36: P | I36: P | J36: P | K36: P | L36: P | M36: P | N36: P | O36: P | P36: P | Q36: P
B37: Executed Date | F37: 15/09/2026 | G37: 15/09/2026 | H37: 15/09/2026 | I37: 15/09/2026 | J37: 15/09/2026 | K37: 15/09/2026 | L37: 15/09/2026 | M37: 15/09/2026 | N37: 15/09/2026 | O37: 15/09/2026 | P37: 15/09/2026 | Q37: 15/09/2026
B38: Defect ID

Sheet FE-InferGeneratedTemplate
A2: Function Code | C2: =Functions!E18 -> FE-STU-04 | F2: Function Name | L2: =Functions!D18 -> inferGeneratedQuestionTemplate
A3: Created By | C3: Hoàng Đăng Khoa | F3: Executed By | L3: Hoàng Đăng Khoa
A4: Lines of code | C4: 55 | F4: Lack of test cases | L4: =IF(Functions!E6<>"N/A",SUM(C4*Functions!E6/1000,-O7),"N/A") -> 2.5
A5: Test requirement | C5: Map a saved (History/Review) question to the Studio template view model using its type, difficulty and rationale/rubric meta.
A6: Passed | C6: Failed | F6: Untested | L6: N/A/B | O6: Total Test Cases
A7: =COUNTIF(F21:T21,"P") -> 3 | C7: =COUNTIF(F21:T21,"F") -> 0 | F7: =SUM(O7,-A7,-C7) -> 0 | L7: =COUNTIF(F20:T20,"N") -> 2 | M7: =COUNTIF(F20:T20,"A") -> 0 | N7: =COUNTIF(F20:T20,"B") -> 1 | O7: =COUNTA(F9:T9) -> 3
F9: UTCID01 | G9: UTCID02 | H9: UTCID03
A10: Condition | B10: Precondition
B11: Pure function, no mocks | F11: O | G11: O | H11: O
B12: Input
B13: questionType "System Design" | F13: O
B14: rationale "template=BUG_DETECTION;lang=Python" and a snippet meta | G14: O
B15: difficulty "very easy", "HARD", "unrecognized" | H15: O
A16: Confirm | B16: Return
B17: templateId SYSTEM_DESIGN | F17: O
B18: BUG_DETECTION, language python, snippet with a real line break | G18: O
B19: No exception; templateId null for a plain question | H19: O
A20: Result | B20: Type(N : Normal, A : Abnormal, B : Boundary) | F20: N | G20: N | H20: B
B21: Passed/Failed | F21: P | G21: P | H21: P
B22: Executed Date | F22: 15/09/2026 | G22: 15/09/2026 | H22: 15/09/2026
B23: Defect ID

Sheet FE-GamificationFormatters
A2: Function Code | C2: =Functions!E19 -> FE-GAM-01 | F2: Function Name | L2: =Functions!D19 -> formatXp / getLevelLabel / getLevelColorClass / getLevelBarColor / streakIntensity / xpRewardTypeLabel
A3: Created By | C3: Hoàng Đăng Khoa | F3: Executed By | L3: Hoàng Đăng Khoa
A4: Lines of code | C4: 47 | F4: Lack of test cases | L4: =IF(Functions!E6<>"N/A",SUM(C4*Functions!E6/1000,-O7),"N/A") -> -9.3
A5: Test requirement | C5: Format XP numbers and map levels, streaks and XP reward types to labels and colours.
A6: Passed | C6: Failed | F6: Untested | L6: N/A/B | O6: Total Test Cases
A7: =COUNTIF(F43:T43,"P") -> 14 | C7: =COUNTIF(F43:T43,"F") -> 0 | F7: =SUM(O7,-A7,-C7) -> 0 | L7: =COUNTIF(F42:T42,"N") -> 2 | M7: =COUNTIF(F42:T42,"A") -> 0 | N7: =COUNTIF(F42:T42,"B") -> 12 | O7: =COUNTA(F9:T9) -> 14
F9: UTCID01 | G9: UTCID02 | H9: UTCID03 | I9: UTCID04 | J9: UTCID05 | K9: UTCID06 | L9: UTCID07 | M9: UTCID08 | N9: UTCID09 | O9: UTCID10 | P9: UTCID11 | Q9: UTCID12 | R9: UTCID13 | S9: UTCID14
A10: Condition | B10: Precondition
B11: Pure functions, no mocks | F11: O | G11: O | H11: O | I11: O | J11: O | K11: O | L11: O | M11: O | N11: O | O11: O | P11: O | Q11: O | R11: O | S11: O
B12: Input
B13: formatXp(1200) / formatXp(0) | F13: O
B14: getLevelLabel(2) | G14: O
B15: getLevelLabel(5) | H15: O
B16: getLevelLabel(9) | I16: O
B17: getLevelLabel(14) | J17: O
B18: getLevelLabel(19) | K18: O
B19: getLevelLabel(29) | L19: O
B20: getLevelLabel(30) | M20: O
B21: Level 1 and level 30 | N21: O
B22: streakIntensity(0) | O22: O
B23: streakIntensity(2) | P23: O
B24: streakIntensity(6) | Q24: O
B25: streakIntensity(7) | R25: O
B26: StreakMilestone in en / vi; unknown type "SomethingNew" | S26: O
A27: Confirm | B27: Return
B28: "1,200" / "0" | F28: O
B29: "Newcomer" | G29: O
B30: "Practitioner" | H30: O
B31: "Achiever" | I31: O
B32: "Trailblazer" | J32: O
B33: "Specialist" | K33: O
B34: "Mentor" | L34: O
B35: "Legend" | M35: O
B36: Gray class + #6b7280 at level 1; yellow class + #eab308 at level 30 | N36: O
B37: Intensity 0 | O37: O
B38: Intensity 1 | P38: O
B39: Intensity 2 | Q39: O
B40: Intensity 3 | R40: O
B41: "Streak milestone" / "Mốc luyện tập liên tiếp" / "SomethingNew" | S41: O
A42: Result | B42: Type(N : Normal, A : Abnormal, B : Boundary) | F42: N | G42: B | H42: B | I42: B | J42: B | K42: B | L42: B | M42: B | N42: B | O42: B | P42: B | Q42: B | R42: B | S42: N
...

Sheet FE-TimeAgo
A2: Function Code | C2: =Functions!E20 -> FE-GAM-02 | F2: Function Name | L2: =Functions!D20 -> timeAgo
A3: Created By | C3: Hoàng Đăng Khoa | F3: Executed By | L3: Hoàng Đăng Khoa
A4: Lines of code | C4: 18 | F4: Lack of test cases | L4: =IF(Functions!E6<>"N/A",SUM(C4*Functions!E6/1000,-O7),"N/A") -> -8.2
A5: Test requirement | C5: Show how long ago an XP event happened, in English and Vietnamese.
A6: Passed | C6: Failed | F6: Untested | L6: N/A/B | O6: Total Test Cases
A7: =COUNTIF(F35:T35,"P") -> 10 | C7: =COUNTIF(F35:T35,"F") -> 0 | F7: =SUM(O7,-A7,-C7) -> 0 | L7: =COUNTIF(F34:T34,"N") -> 8 | M7: =COUNTIF(F34:T34,"A") -> 0 | N7: =COUNTIF(F34:T34,"B") -> 2 | O7: =COUNTA(F9:T9) -> 10
F9: UTCID01 | G9: UTCID02 | H9: UTCID03 | I9: UTCID04 | J9: UTCID05 | K9: UTCID06 | L9: UTCID07 | M9: UTCID08 | N9: UTCID09 | O9: UTCID10
A10: Condition | B10: Precondition
B11: System time fixed at 15/06/2026 12:00 UTC | F11: O | G11: O | H11: O | I11: O | J11: O | K11: O | L11: O | M11: O | N11: O | O11: O
B12: Input
B13: Age 0 ms, locale en | F13: O
B14: Age 0 ms, locale vi | G14: O
B15: Age 10 minutes, locale en | H15: O
B16: Age 10 minutes, locale vi | I16: O
B17: Age 5 hours, locale en | J17: O
B18: Age 5 hours, locale vi | K18: O
B19: Age 10 days, locale en | L19: O
B20: Age 10 days, locale vi | M20: O
B21: Age 60 days, locale en | N21: O
B22: Age 60 days, locale vi | O22: O
A23: Confirm | B23: Return
B24: "just now" | F24: O
B25: "vừa xong" | G25: O
B26: "10m ago" | H26: O
B27: "10 phút trước" | I27: O
B28: "5h ago" | J28: O
B29: "5 giờ trước" | K29: O
B30: "10d ago" | L30: O
B31: "10 ngày trước" | M31: O
B32: "2mo ago" | N32: O
B33: "2 tháng trước" | O33: O
A34: Result | B34: Type(N : Normal, A : Abnormal, B : Boundary) | F34: B | G34: B | H34: N | I34: N | J34: N | K34: N | L34: N | M34: N | N34: N | O34: N
B35: Passed/Failed | F35: P | G35: P | H35: P | I35: P | J35: P | K35: P | L35: P | M35: P | N35: P | O35: P
B36: Executed Date | F36: 15/09/2026 | G36: 15/09/2026 | H36: 15/09/2026 | I36: 15/09/2026 | J36: 15/09/2026 | K36: 15/09/2026 | L36: 15/09/2026 | M36: 15/09/2026 | N36: 15/09/2026 | O36: 15/09/2026
B37: Defect ID

Sheet FE-ComputeStreakDays
A2: Function Code | C2: =Functions!E21 -> FE-CAN-01 | F2: Function Name | L2: =Functions!D21 -> computeStreakDays
A3: Created By | C3: Hoàng Đăng Khoa | F3: Executed By | L3: Hoàng Đăng Khoa
A4: Lines of code | C4: 21 | F4: Lack of test cases | L4: =IF(Functions!E6<>"N/A",SUM(C4*Functions!E6/1000,-O7),"N/A") -> -5.9
A5: Test requirement | C5: Count the consecutive practice days (ending today or yesterday) shown on the candidate dashboard.
A6: Passed | C6: Failed | F6: Untested | L6: N/A/B | O6: Total Test Cases
A7: =COUNTIF(F31:T31,"P") -> 8 | C7: =COUNTIF(F31:T31,"F") -> 0 | F7: =SUM(O7,-A7,-C7) -> 0 | L7: =COUNTIF(F30:T30,"N") -> 2 | M7: =COUNTIF(F30:T30,"A") -> 3 | N7: =COUNTIF(F30:T30,"B") -> 3 | O7: =COUNTA(F9:T9) -> 8
F9: UTCID01 | G9: UTCID02 | H9: UTCID03 | I9: UTCID04 | J9: UTCID05 | K9: UTCID06 | L9: UTCID07 | M9: UTCID08
A10: Condition | B10: Precondition
B11: Session timestamps built relative to the real current date | F11: O | G11: O | H11: O | I11: O | J11: O | K11: O | L11: O | M11: O
B12: Input
B13: No sessions | F13: O
B14: One session today | G14: O
B15: Sessions today, yesterday and 2 days ago | H15: O
B16: Sessions today and 2 days ago | I16: O
B17: Sessions yesterday and 2 days ago | J17: O
B18: Only a session 3 days ago | K18: O
B19: [undefined, "not-a-date", today] | L19: O
B20: Two sessions today | M20: O
A21: Confirm | B21: Return
B22: 0 | F22: O
B23: 1 | G23: O
B24: 3 | H24: O
B25: 1 (streak broken) | I25: O
B26: 2 | J26: O
B27: 0 (streak broken) | K27: O
B28: 1 (bad entries ignored) | L28: O
B29: 1 (same day counted once) | M29: O
A30: Result | B30: Type(N : Normal, A : Abnormal, B : Boundary) | F30: B | G30: N | H30: N | I30: A | J30: B | K30: A | L30: A | M30: B
B31: Passed/Failed | F31: P | G31: P | H31: P | I31: P | J31: P | K31: P | L31: P | M31: P
B32: Executed Date | F32: 15/09/2026 | G32: 15/09/2026 | H32: 15/09/2026 | I32: 15/09/2026 | J32: 15/09/2026 | K32: 15/09/2026 | L32: 15/09/2026 | M32: 15/09/2026
B33: Defect ID

Sheet FE-LabelsCompanyScore
A2: Function Code | C2: =Functions!E22 -> FE-CAN-02 | F2: Function Name | L2: =Functions!D22 -> translateDimensionKey / translateQuestionCategory / getCompanyInitials / getCompanyColor / formatCategoryLabel / getScoreBadgeClass / getScoreLevel
A3: Created By | C3: Hoàng Đăng Khoa | F3: Executed By | L3: Hoàng Đăng Khoa
A4: Lines of code | C4: 49 | F4: Lack of test cases | L4: =IF(Functions!E6<>"N/A",SUM(C4*Functions!E6/1000,-O7),"N/A") -> -4.1
A5: Test requirement | C5: Translate skill/category labels, build company initials and colours, and pick the score label and badge colour.
A6: Passed | C6: Failed | F6: Untested | L6: N/A/B | O6: Total Test Cases
A7: =COUNTIF(F33:T33,"P") -> 9 | C7: =COUNTIF(F33:T33,"F") -> 0 | F7: =SUM(O7,-A7,-C7) -> 0 | L7: =COUNTIF(F32:T32,"N") -> 5 | M7: =COUNTIF(F32:T32,"A") -> 1 | N7: =COUNTIF(F32:T32,"B") -> 3 | O7: =COUNTA(F9:T9) -> 9
F9: UTCID01 | G9: UTCID02 | H9: UTCID03 | I9: UTCID04 | J9: UTCID05 | K9: UTCID06 | L9: UTCID07 | M9: UTCID08 | N9: UTCID09
A10: Condition | B10: Precondition
B11: Pure functions, no mocks | F11: O | G11: O | H11: O | I11: O | J11: O | K11: O | L11: O | M11: O | N11: O
B12: Input
B13: "technical_accuracy" / "Technical-Accuracy" in vi | F13: O
B14: "some_new_dimension" in vi / "clarity" in en | G14: O
B15: "problem-solving" vi / "unknown-cat" vi / "technical" en | H15: O
B16: "", " ", "Acme", "Acme Corp International" | I16: O
B17: Same seed "Acme Corp" twice | J17: O
B18: Seeds "Acme" and "Zephyr Industries" | K18: O
B19: "problem-solving", "system_design", "technical" | L19: O
B20: Scores 85, 80, 70, 65, 40 | M20: O
B21: Scores 90, 70, 55, 30 | N21: O
A22: Confirm | B22: Return
B23: "Độ chính xác kỹ thuật" | F23: O
B24: "Some New Dimension" / "Clarity" | G24: O
B25: "Giải quyết vấn đề" / "Unknown Cat" / "Technical" | H25: O
B26: "?", "?", "AC", "AC" | I26: O
B27: Same colour class bg-*-500 both times | J27: O
B28: Different colour classes | K28: O
B29: "Problem Solving", "System Design", "Technical" | L29: O
B30: emerald, emerald, violet, violet, amber | M30: O
B31: Excellent/emerald, Good/violet, Fair/amber, Needs work/red | N31: O
A32: Result | B32: Type(N : Normal, A : Abnormal, B : Boundary) | F32: N | G32: A | H32: N | I32: B | J32: N | K32: N | L32: N | M32: B | N32: B
B33: Passed/Failed | F33: P | G33: P | H33: P | I33: P | J33: P | K33: P | L33: P | M33: P | N33: P
B34: Executed Date | F34: 15/09/2026 | G34: 15/09/2026 | H34: 15/09/2026 | I34: 15/09/2026 | J34: 15/09/2026 | K34: 15/09/2026 | L34: 15/09/2026 | M34: 15/09/2026 | N34: 15/09/2026
B35: Defect ID

Sheet FE-AdminUserDisplay
A2: Function Code | C2: =Functions!E23 -> FE-ADM-01 | F2: Function Name | L2: =Functions!D23 -> toBackendRoleFilter / normalizeAdminRoleKey / getAdminUserStatus / isAdminRole
A3: Created By | C3: Hoàng Đăng Khoa | F3: Executed By | L3: Hoàng Đăng Khoa
A4: Lines of code | C4: 27 | F4: Lack of test cases | L4: =IF(Functions!E6<>"N/A",SUM(C4*Functions!E6/1000,-O7),"N/A") -> -10.3
A5: Test requirement | C5: Map roles between the admin UI and the backend filter, and derive the account status shown in User Management.
A6: Passed | C6: Failed | F6: Untested | L6: N/A/B | O6: Total Test Cases
A7: =COUNTIF(F40:T40,"P") -> 13 | C7: =COUNTIF(F40:T40,"F") -> 0 | F7: =SUM(O7,-A7,-C7) -> 0 | L7: =COUNTIF(F39:T39,"N") -> 8 | M7: =COUNTIF(F39:T39,"A") -> 2 | N7: =COUNTIF(F39:T39,"B") -> 3 | O7: =COUNTA(F9:T9) -> 13
F9: UTCID01 | G9: UTCID02 | H9: UTCID03 | I9: UTCID04 | J9: UTCID05 | K9: UTCID06 | L9: UTCID07 | M9: UTCID08 | N9: UTCID09 | O9: UTCID10 | P9: UTCID11 | Q9: UTCID12 | R9: UTCID13
A10: Condition | B10: Precondition
B11: Pure functions, no mocks | F11: O | G11: O | H11: O | I11: O | J11: O | K11: O | L11: O | M11: O | N11: O | O11: O | P11: O | Q11: O | R11: O
B12: Input
B13: toBackendRoleFilter("ADMIN") | F13: O
B14: toBackendRoleFilter("HR_MANAGER") | G14: O
B15: toBackendRoleFilter("JOB_SEEKER") | H15: O
B16: toBackendRoleFilter("UNKNOWN") | I16: O
B17: normalizeAdminRoleKey("SysAdmin") | J17: O
B18: normalizeAdminRoleKey("HR_MANAGER") | K18: O
B19: normalizeAdminRoleKey("Candidate") | L19: O
B20: normalizeAdminRoleKey("something-else") | M20: O
B21: normalizeAdminRoleKey(undefined) | N21: O
B22: isActive true, emailVerified false | O22: O
B23: isActive true, emailVerified true | P23: O
B24: isActive false, emailVerified false | Q24: O
B25: "ADMIN", "SuperAdmin", "HR_MANAGER", null, undefined | R25: O
A26: Confirm | B26: Return
B27: "Admin" | F27: O
B28: "HR" | G28: O
B29: "Candidate" | H29: O
B30: undefined | I30: O
B31: "ADMIN" | J31: O
B32: "HR_MANAGER" | K32: O
B33: "JOB_SEEKER" | L33: O
B34: "UNKNOWN" | M34: O | N34: O
B35: "Pending" | O35: O
B36: "Active" | P36: O
B37: "Suspended" (inactive wins) | Q37: O
B38: true, true, false, false, false | R38: O
A39: Result | B39: Type(N : Normal, A : Abnormal, B : Boundary) | F39: N | G39: N | H39: N | I39: A | J39: N | K39: N | L39: N | M39: A | N39: B | O39: N | P39: N | Q39: B | R39: B
B40: Passed/Failed | F40: P | G40: P | H40: P | I40: P | J40: P | K40: P | L40: P | M40: P | N40: P | O40: P | P40: P | Q40: P | R40: P
B41: Executed Date | F41: 15/09/2026 | G41: 15/09/2026 | H41: 15/09/2026 | I41: 15/09/2026 | J41: 15/09/2026 | K41: 15/09/2026 | L41: 15/09/2026 | M41: 15/09/2026 | N41: 15/09/2026 | O41: 15/09/2026 | P41: 15/09/2026 | Q41: 15/09/2026 | R41: 15/09/2026
B42: Defect ID

Sheet FE-GreetingLoginWelcome
A2: Function Code | C2: =Functions!E24 -> FE-SHR-01 | F2: Function Name | L2: =Functions!D24 -> getTimeOfDayGreeting / buildWelcomeMessage / mark-has-clearLoginWelcomePending
A3: Created By | C3: Hoàng Đăng Khoa | F3: Executed By | L3: Hoàng Đăng Khoa
A4: Lines of code | C4: 29 | F4: Lack of test cases | L4: =IF(Functions!E6<>"N/A",SUM(C4*Functions!E6/1000,-O7),"N/A") -> -5.1
A5: Test requirement | C5: Choose the greeting for the time of day, fill the welcome message, and remember per role that the login welcome is pending.
A6: Passed | C6: Failed | F6: Untested | L6: N/A/B | O6: Total Test Cases
A7: =COUNTIF(F31:T31,"P") -> 8 | C7: =COUNTIF(F31:T31,"F") -> 0 | F7: =SUM(O7,-A7,-C7) -> 0 | L7: =COUNTIF(F30:T30,"N") -> 2 | M7: =COUNTIF(F30:T30,"A") -> 1 | N7: =COUNTIF(F30:T30,"B") -> 5 | O7: =COUNTA(F9:T9) -> 8
F9: UTCID01 | G9: UTCID02 | H9: UTCID03 | I9: UTCID04 | J9: UTCID05 | K9: UTCID06 | L9: UTCID07 | M9: UTCID08
A10: Condition | B10: Precondition
B11: Labels Morning / Afternoon / Evening / Night | F11: O | G11: O | H11: O | I11: O | J11: O | K11: O | L11: O | M11: O
B12: Input
B13: Local time 05:00 | F13: O
B14: Local time 12:00 | G14: O
B15: Local time 18:00 | H15: O
B16: Local time 22:00 | I16: O
B17: Local time 04:00 | J17: O
B18: Template "{{greeting}}, {{name}}!" | K18: O
B19: Template "Hello there" | L19: O
B20: markLoginWelcomePending("hr"), then clearLoginWelcomePending() | M20: O
A21: Confirm | B21: Return
B22: "Morning" | F22: O
B23: "Afternoon" | G23: O
B24: "Evening" | H24: O
B25: "Night" | I25: O
B26: "Night" (wraps past midnight) | J26: O
B27: "Good morning, An!" | K27: O
B28: "Hello there" | L28: O
B29: Pending for hr only (not admin); cleared afterwards | M29: O
A30: Result | B30: Type(N : Normal, A : Abnormal, B : Boundary) | F30: B | G30: B | H30: B | I30: B | J30: B | K30: N | L30: A | M30: N
B31: Passed/Failed | F31: P | G31: P | H31: P | I31: P | J31: P | K31: P | L31: P | M31: P
B32: Executed Date | F32: 15/09/2026 | G32: 15/09/2026 | H32: 15/09/2026 | I32: 15/09/2026 | J32: 15/09/2026 | K32: 15/09/2026 | L32: 15/09/2026 | M32: 15/09/2026
B33: Defect ID

Sheet FE-FormatRelativeTime
A2: Function Code | C2: =Functions!E25 -> FE-SHR-02 | F2: Function Name | L2: =Functions!D25 -> formatRelativeTime
A3: Created By | C3: Hoàng Đăng Khoa | F3: Executed By | L3: Hoàng Đăng Khoa
A4: Lines of code | C4: 19 | F4: Lack of test cases | L4: =IF(Functions!E6<>"N/A",SUM(C4*Functions!E6/1000,-O7),"N/A") -> -7.1
A5: Test requirement | C5: Show relative time for list items in English and Vietnamese; empty text for a missing or invalid date.
A6: Passed | C6: Failed | F6: Untested | L6: N/A/B | O6: Total Test Cases
A7: =COUNTIF(F33:T33,"P") -> 9 | C7: =COUNTIF(F33:T33,"F") -> 0 | F7: =SUM(O7,-A7,-C7) -> 0 | L7: =COUNTIF(F32:T32,"N") -> 6 | M7: =COUNTIF(F32:T32,"A") -> 1 | N7: =COUNTIF(F32:T32,"B") -> 2 | O7: =COUNTA(F9:T9) -> 9
F9: UTCID01 | G9: UTCID02 | H9: UTCID03 | I9: UTCID04 | J9: UTCID05 | K9: UTCID06 | L9: UTCID07 | M9: UTCID08 | N9: UTCID09
A10: Condition | B10: Precondition
B11: System time fixed at 15/06/2026 12:00 UTC | F11: O | G11: O | H11: O | I11: O | J11: O | K11: O | L11: O | M11: O | N11: O
B12: Input
B13: undefined / "not-a-date" | F13: O
B14: Age 0 ms, lang en | G14: O
B15: Age 0 ms, lang vi | H15: O
B16: Age 5 minutes, lang en | I16: O
B17: Age 5 minutes, lang vi | J17: O
B18: Age 3 hours, lang en | K18: O
B19: Age 3 hours, lang vi | L19: O
B20: Age 2 days, lang en | M20: O
B21: Age 2 days, lang vi | N21: O
A22: Confirm | B22: Return
B23: "" | F23: O
B24: "Just now" | G24: O
B25: "Vừa xong" | H25: O
B26: "5 min ago" | I26: O
B27: "5 phút trước" | J27: O
B28: "3h ago" | K28: O
B29: "3 giờ trước" | L29: O
B30: "2d ago" | M30: O
B31: "2 ngày trước" | N31: O
A32: Result | B32: Type(N : Normal, A : Abnormal, B : Boundary) | F32: A | G32: B | H32: B | I32: N | J32: N | K32: N | L32: N | M32: N | N32: N
B33: Passed/Failed | F33: P | G33: P | H33: P | I33: P | J33: P | K33: P | L33: P | M33: P | N33: P
B34: Executed Date | F34: 15/09/2026 | G34: 15/09/2026 | H34: 15/09/2026 | I34: 15/09/2026 | J34: 15/09/2026 | K34: 15/09/2026 | L34: 15/09/2026 | M34: 15/09/2026 | N34: 15/09/2026
B35: Defect ID

Sheet FE-NavUserDisplay
A2: Function Code | C2: =Functions!E26 -> FE-SHR-03 | F2: Function Name | L2: =Functions!D26 -> isAdminNavActive / isHrNavActive / getInitials / resolveAvatarUrl
A3: Created By | C3: Hoàng Đăng Khoa | F3: Executed By | L3: Hoàng Đăng Khoa
A4: Lines of code | C4: 57 | F4: Lack of test cases | L4: =IF(Functions!E6<>"N/A",SUM(C4*Functions!E6/1000,-O7),"N/A") -> -2.3
A5: Test requirement | C5: Highlight the active sidebar item for the current path, and build user initials and avatar URL.
A6: Passed | C6: Failed | F6: Untested | L6: N/A/B | O6: Total Test Cases
A7: =COUNTIF(F30:T30,"P") -> 8 | C7: =COUNTIF(F30:T30,"F") -> 0 | F7: =SUM(O7,-A7,-C7) -> 0 | L7: =COUNTIF(F29:T29,"N") -> 4 | M7: =COUNTIF(F29:T29,"A") -> 2 | N7: =COUNTIF(F29:T29,"B") -> 2 | O7: =COUNTA(F9:T9) -> 8
F9: UTCID01 | G9: UTCID02 | H9: UTCID03 | I9: UTCID04 | J9: UTCID05 | K9: UTCID06 | L9: UTCID07 | M9: UTCID08
A10: Condition | B10: Precondition
B11: Pure functions, no mocks | F11: O | G11: O | H11: O | I11: O | J11: O | K11: O | L11: O | M11: O
B12: Input
B13: Dashboard item on /admin, /admin/dashboard, /admin/users; Users item on /admin/users/ | F13: O
B14: Item /hr/dashboard on path /hr | G14: O
B15: Item /hr/settings on /hr/settings/billing | H15: O
B16: Item /hr/history on /hr/history/qs-1 | I16: O
B17: Item /hr/generate-question on /hr/generate-question/manual | J17: O
B18: "", " ", "Madonna", "Nguyen Van A", " Nguyen Van A " | K18: O
B19: user null / undefined | L19: O
B20: Avatar set on user / only candidate profile / only HR profile / blank | M20: O
A21: Confirm | B21: Return
B22: true, true, false, true | F22: O
B23: true | G23: O
B24: false (exact match only) | H24: O
B25: true (prefix match) | I25: O | J25: O
B26: "??", "??", "MA", "NA", "NA" | K26: O
B27: null | L27: O
B28: "top.png" / "c.png" / "h.png" / null | M28: O
