Workbook
Name Z_BE54E0AD_3725_4423_92D7_4F1C045BE1BC_.wvu.PrintArea: Statistics!$A:$I
Name Z_2C0D9096_8D85_462A_A9B5_0B488ADB4269_.wvu.PrintArea: Statistics!$A:$I
Name ACTION: #REF!
Name Z_6F1DCD5D_5DAC_4817_BF40_2B66F6F593E6_.wvu.PrintArea: Statistics!$A:$I

Sheet Guideline
A1: Guideline to make and understand Unit Test Case
A3: 1. Overview
A4: - In the template, Unit test cases are based on functions. Each sheet presents test cases for one function.
A5: - Cover: General information of the project and Unit Test cases
A6: - FunctionList: The list of Classes and Functions in the document. + To control that the number of Unit TC meets customer's requirement or the norm, user should fill value for 'Normal number of Test cases/KLOC'.
A7: + Click on Function link to open the related Test cases of the function. Note: You should create new Function sheet before creating the link
A8: - Test Report: provive the overview results of Functions Unit test: Test coverage, Test successful coverage (Summary, for normal/abnormal/boundary cases)
A9: Note: Should check the formula of "Sub Total" if you add more functions
A11: 2. Content in Test function sheet
A12: 2.1 Combination of test cases.
A13: - To verify that number of Unit TC meets customer's requirement or not. User has to fill number LOC of tested function and fill value of 'Normal number test cases/KLOC' item in FunctionList sheet, which is required by customer or normal value. The number of lacked TC is shown in 'Lack of test cases' item.
A14: - If the number of Unit TC does not meet the requirement, creator should explain the reasons.
... A47: - Test requirement: Brief description about requirements which are tested in this function, it is not mandatory.

Sheet Cover
B2: UNIT TEST DOCUMENT
A4: Project Name | B4: AI-powered Shared Business Space Platform with Time-based Subleasing | E4: Creator | F4: KietNT
A5: Project Code | B5: SU26SE038 | E5: Issue Date | F5: 46235
A6: Document Code | B6: =B5&"_"&"001"&"_"&"v1.0" -> SU26SE038_001_v1.0 | E6: Version | F6: 1
A9: Record of change
A10: Effective Date | B10: Version | C10: Change Item | D10: *A,D,M | E10: Change description | F10: Reference
A11: 46237 | B11: 1 | D11: A | E11: Add information to unit test document | F11: Cover, Function

Sheet Functions
E2: Function List
A4: Project Name | E4: =Cover!B4 -> AI-powered Shared Business Space Platform with Time-based Subleasing
A5: Project Code | E5: =Cover!B5 -> SU26SE038
A6: Normal number of Test cases/KLOC | E6: 40
A7: Test Environment Setup Description | E7: 1. Server - Local development machine or CI/CD runner. - .NET SDK installed. - The test server does not need to be started for service-layer unit tests. 2. Database - A real database is not required for most unit tests. - Repository and UnitOfWork dependencies are mocked. - If integration tests are added later, SQL Server or an in-memory database can be configured. 3. Web Browser - Not required for current unit tests. - Browsers are only needed for manual UI/API testing or end-to-end testing. 4. Operating System - Windows, Linux, or macOS can be used. - The current project environment is Windows with PowerShell. 5. Runtime and Framework - .NET SDK compatible with the project target framework. - ASP.NET Core runtime for web/API execution when needed. 6. Testing Framework - xUnit is used to define and execute test cases. - Test cases are marked with [Fact] or [Theory]. 7. Mocking Framework - Moq is used to mock dependencies such as repositories, services, and UnitOfWork. 8. Assertion Library - FluentAssertions is used to verify expected results in a readable format. 9. Application Configuration - Unit tests should provide required configuration values through mocked options or test-specific setup. - Production appsettings files are not required for most unit tests. 10. External Services - Email service, PayOS payment gateway, Cloudinary, Fal AI, Expo Push Notification, and Turnstile should be mocked. - No real external API calls should be made during unit testing. 11. Source Code and Test Projects - Production projects: FlexiSpace.Application FlexiSpace.Domain FlexiSpace.Infrastructure FlexiSpace.Web - Test projects: FlexiSpace.Application.Tests FlexiSpace.Domain.Tests FlexiSpace.Infrastructure.Tests FlexiSpace.Web.Tests 12. Test Execution Command - Tests can be executed using: dotnet test FlexiSpace_CapstoneProject.sln
A10: No | B10: Requirement Name | C10: Class Name | D10: Function Name | E10: Function Code(Optional) | F10: Sheet Name | G10: Description | H10: Pre-Condition
A11: 1 | B11: REQ-AI-001 AI Image Generation | C11: AIToolService | D11: GenerateImageAsync | E11: FUNC-AI-001 | F11: AIToolServiceTests | G11: Generates AI image, uploads result, charges wallet, and stores image history. | H11: User wallet, AI provider, Cloudinary service, and unit of work are initialized.
A12: 2 | B12: REQ-AMN-001 Amenity Management | C12: AmenityService | D12: GetAllAmenitiesBySpaceIdAsync | E12: FUNC-AMN-001 | F12: AmenityServiceTests | G12: Retrieves amenities assigned to a specific space. | H12: Space repository and amenity repository are available.
A13: 3 | B13: REQ-AUTH-001 Authentication | C13: AuthService | D13: LoginAsync | E13: FUNC-AUTH-001 | F13: AuthServiceTests | G13: Authenticates user credentials and returns login result. | H13: User repository, password hasher, JWT provider, and Turnstile service are configured.
A14: 4 | B14: REQ-AUTH-002 User Registration | C14: AuthService | D14: RegisterAsync | E14: FUNC-AUTH-002 | F14: AuthServiceTests | G14: Registers a new user and sends verification OTP. | H14: Email service, OTP repository, and user repository are initialized.
A15: 5 | B15: REQ-AUTH-003 OTP Verification | C15: AuthService | D15: VerifyOtpAsync | E15: FUNC-AUTH-003 | F15: AuthServiceTests | G15: Verifies OTP and activates the user account. | H15: OTP data must exist for the target user.
A16: 6 | B16: REQ-AUTH-004 Password Recovery | C16: AuthService | D16: SendPasswordOtpAsync / ResetPasswordAsync | E16: FUNC-AUTH-004 | F16: AuthServiceTests | G16: Sends password reset OTP and updates password after successful validation. | H16: User email must exist and OTP service must be available.
A17: 7 | B17: REQ-AUTH-005 Password Change | C17: AuthService | D17: ChangePasswordAsync | E17: FUNC-AUTH-005 | F17: AuthServiceTests | G17: Changes current user password after validating the current password. | H17: Current user context and password hasher are initialized.
A18: 8 | B18: REQ-BOOK-001 Booking Notification | C18: BookingRequestCreatedNotificationHandler | D18: Handle | E18: FUNC-NOTI-001 | F18: BookingNotificationHandlerTests | G18: Creates notification when a booking request is created. | H18: Notification service and booking event payload are available.
A19: 9 | B19: REQ-BOOK-002 Booking Approval Notification | C19: BookingRequestApprovedNotificationHandler | D19: Handle | E19: FUNC-NOTI-002 | F19: BookingNotificationHandlerTests | G19: Creates notification when a booking request is approved. | H19: Notification service and approved booking event payload are available.
A20: 10 | B20: REQ-CONV-001 Conversation Management | C20: ConversationService | D20: GetOrCreateConversationAsync | E20: FUNC-CONV-001 | F20: ConversationServiceTests | G20: Gets an existing conversation or creates a new one for participants. | H20: Conversation repository and unit of work are initialized.
A21: 11 | B21: REQ-CONV-002 Conversation Query | C21: ConversationService | D21: GetConversationsByUserIdAsync / GetConversationByParticipantsAsync | E21: FUNC-CONV-002 | F21: ConversationServiceTests | G21: Retrieves conversations by user or participant pair. | H21: Conversation repository and mapper are available.
A22: 12 | B22: REQ-DASH-001 Dashboard Statistics | C22: DashboardService | D22: GetDashboardStatsAsync | E22: FUNC-DASH-001 | F22: DashboardServiceTests | G22: Aggregates dashboard statistics for the system. | H22: Required repositories must be initialized
... A38: 28 | B38: REQ-TXN-001 Transaction Management | C38: TransactionService | D38: CreateTransactionAsync | E38: FUNC-TXN-001 | F38: TransactionServiceTests | G38: Creates a PayOS payment transaction for wallet top-up. | H38: HttpContextAccessor and PayOS gateway are configured.

Sheet Statistics
A2: UNIT TEST REPORT
A4: Project Name | B4: =Cover!B4 -> AI-powered Shared Business Space Platform with Time-based Subleasing | D4: Creator | F4: KietNT
A5: Project Code | B5: =Cover!B5 -> SU26SE038 | D5: Reviewer/Approver
A6: Document Code | B6: =B5&"_"&"Test Report"&"_"&"v1.0" -> SU26SE038_Test Report_v1.0 | D6: Issue Date
A7: Notes
A11: No | B11: Function code | C11: Passed | D11: Failed | E11: Untested | F11: N | G11: A | H11: B | I11: Total Test Cases
A12: 1 | B12: FUNC-AI-001 | C12: =AIToolService!A7 -> 6 | D12: =AIToolService!C7 -> 0 | E12: =AIToolService!F7 -> 0 | F12: =AIToolService!L7 -> 1 | G12: =AIToolService!M7 -> 4 | H12: =AIToolService!N7 -> 1 | I12: =AIToolService!O7 -> 6
A13: 2 | B13: FUNC-AMN-001 | C13: =AmenityService!A7 -> 6 | D13: =AmenityService!C7 -> 0 | E13: =AmenityService!F7 -> 0 | F13: =AmenityService!L7 -> 2 | G13: =AmenityService!M7 -> 2 | H13: =AmenityService!N7 -> 2 | I13: =AmenityService!O7 -> 6
A14: 3 | B14: FUNC-AUTH-001 | C14: ='Auth-Login'!A7 -> 3 | D14: ='Auth-Login'!C7 -> 0 | E14: ='Auth-Login'!F7 -> 0 | F14: ='Auth-Login'!L7 -> 1 | G14: ='Auth-Login'!M7 -> 2 | H14: ='Auth-Login'!N7 -> 0 | I14: ='Auth-Login'!O7 -> 3
A15: 4 | B15: FUNC-AUTH-002 | C15: ='Auth-Register'!A7 -> 3 | D15: ='Auth-Register'!C7 -> 0 | E15: ='Auth-Register'!F7 -> 0 | F15: ='Auth-Register'!L7 -> 1 | G15: ='Auth-Register'!M7 -> 1 | H15: ='Auth-Register'!N7 -> 1 | I15: ='Auth-Register'!O7 -> 3
A16: 5 | B16: FUNC-AUTH-003 | C16: ='Auth-VerifyOtp'!A7 -> 2 | D16: ='Auth-VerifyOtp'!C7 -> 0 | E16: ='Auth-VerifyOtp'!F7 -> 0 | F16: ='Auth-VerifyOtp'!L7 -> 1 | G16: ='Auth-VerifyOtp'!M7 -> 1 | H16: ='Auth-VerifyOtp'!N7 -> 0 | I16: ='Auth-VerifyOtp'!O7 -> 2
A17: 6 | B17: FUNC-AUTH-004 | C17: ='Auth-ResetPwd'!A7 -> 4 | D17: ='Auth-ResetPwd'!C7 -> 0 | E17: ='Auth-ResetPwd'!F7 -> 0 | F17: ='Auth-ResetPwd'!L7 -> 1 | G17: ='Auth-ResetPwd'!M7 -> 2 | H17: ='Auth-ResetPwd'!N7 -> 1 | I17: ='Auth-ResetPwd'!O7 -> 4
A18: 7 | B18: FUNC-AUTH-005 | C18: ='Auth-ChangePwd'!A7 -> 2 | D18: ='Auth-ChangePwd'!C7 -> 0 | E18: ='Auth-ChangePwd'!F7 -> 0 | F18: ='Auth-ChangePwd'!L7 -> 1 | G18: ='Auth-ChangePwd'!M7 -> 1 | H18: ='Auth-ChangePwd'!N7 -> 0 | I18: ='Auth-ChangePwd'!O7 -> 2
A19: 8 | B19: FUNC-NOTI-001 | C19: ='BookingNotif-Created'!A7 -> 3 | D19: ='BookingNotif-Created'!C7 -> 0 | E19: ='BookingNotif-Created'!F7 -> 0 | F19: ='BookingNotif-Created'!L7 -> 1 | G19: ='BookingNotif-Created'!M7 -> 2 | H19: ='BookingNotif-Created'!N7 -> 0 | I19: ='BookingNotif-Created'!O7 -> 3
A20: 9 | B20: FUNC-NOTI-002 | C20: ='BookingNotif-Approved'!A7 -> 2 | D20: ='BookingNotif-Approved'!C7 -> 0 | E20: ='BookingNotif-Approved'!F7 -> 0 | F20: ='BookingNotif-Approved'!L7 -> 1 | G20: ='BookingNotif-Approved'!M7 -> 1 | H20: ='BookingNotif-Approved'!N7 -> 0 | I20: ='BookingNotif-Approved'!O7 -> 2
A21: 10 | B21: FUNC-CONV-001 | C21: ='Conv-GetOrCreate'!A7 -> 3 | D21: ='Conv-GetOrCreate'!C7 -> 0 | E21: ='Conv-GetOrCreate'!F7 -> 0 | F21: ='Conv-GetOrCreate'!L7 -> 2 | G21: ='Conv-GetOrCreate'!M7 -> 1 | H21: ='Conv-GetOrCreate'!N7 -> 0 | I21: ='Conv-GetOrCreate'!O7 -> 3
A22: 11 | B22: FUNC-CONV-002 | C22: ='Conv-Query'!A7 -> 3 | D22: ='Conv-Query'!C7 -> 0 | E22: ='Conv-Query'!F7 -> 0 | F22: ='Conv-Query'!L7 -> 1 | G22: ='Conv-Query'!M7 -> 2 | H22: ='Conv-Query'!N7 -> 0 | I22: ='Conv-Query'!O7 -> 3
A23: 12 | B23: FUNC-DASH-001 | C23: ='Dashboard-Stats'!A7 -> 2 | D23: ='Dashboard-Stats'!C7 -> 0 | E23: ='Dashboard-Stats'!F7 -> 0 | F23: ='Dashboard-Stats'!L7 -> 1 | G23: ='Dashboard-Stats'!M7 -> 1 | H23: ='Dashboard-Stats'!N7 -> 0 | I23: ='Dashboard-Stats'!O7 -> 2
A24: 13 | B24: FUNC-DASH-002 | C24: ='Dashboard-Listing'!A7 -> 2 | D24: ='Dashboard-Listing'!C7 -> 1 | E24: ='Dashboard-Listing'!F7 -> 0 | F24: ='Dashboard-Listing'!L7 -> 1 | G24: ='Dashboard-Listing'!M7 -> 2 | H24: ='Dashboard-Listing'!N7 -> 0 | I24: ='Dashboard-Listing'!O7 -> 3
A25: 14 | B25: FUNC-SEED-001 | C25: ='DataSeeder-Admin'!A7 -> 3 | D25: ='DataSeeder-Admin'!C7 -> 0 | E25: ='DataSeeder-Admin'!F7 -> 0 | F25: ='DataSeeder-Admin'!L7 -> 2 | G25: ='DataSeeder-Admin'!M7 -> 0 | H25: ='DataSeeder-Admin'!N7 -> 1 | I25: ='DataSeeder-Admin'!O7 -> 3
A26: 15 | B26: FUNC-CONTRACT-001 | C26: =SUM('Contract-CRUD-1'!A7,'Contract-CRUD-2'!A7) -> 18 | D26: =SUM('Contract-CRUD-1'!C7,'Contract-CRUD-2'!C7) -> 2 | E26: =SUM('Contract-CRUD-1'!F7,'Contract-CRUD-2'!F7) -> 0 | F26: =SUM('Contract-CRUD-1'!L7,'Contract-CRUD-2'!L7) -> 6 | G26: =SUM('Contract-CRUD-1'!M7,'Contract-CRUD-2'!M7) -> 11 | H26: =SUM('Contract-CRUD-1'!N7,'Contract-CRUD-2'!N7) -> 3 | I26: =SUM('Contract-CRUD-1'!O7,'Contract-CRUD-2'!O7) -> 20
A27: 16 | B27: FUNC-CONTRACT-002 | C27: =SUM('Contract-Signing-1'!A7,'Contract-Signing-2'!A7) -> 19 | D27: =SUM('Contract-Signing-1'!C7,'Contract-Signing-2'!C7) -> 1 | E27: =SUM('Contract-Signing-1'!F7,'Contract-Signing-2'!F7) -> 0 | F27: =SUM('Contract-Signing-1'!L7,'Contract-Signing-2'!L7) -> 6 | G27: =SUM('Contract-Signing-1'!M7,'Contract-Signing-2'!M7) -> 12 | H27: =SUM('Contract-Signing-1'!N7,'Contract-Signing-2'!N7) -> 2 | I27: =SUM('Contract-Signing-1'!O7,'Contract-Signing-2'!O7) -> 20
A28: 17 | B28: FUNC-CONTRACT-003 | C28: ='Contract-Share'!A7 -> 5 | D28: ='Contract-Share'!C7 -> 0 | E28: ='Contract-Share'!F7 -> 0 | F28: ='Contract-Share'!L7 -> 1 | G28: ='Contract-Share'!M7 -> 4 | H28: ='Contract-Share'!N7 -> 0 | I28: ='Contract-Share'!O7 -> 5
A29: 18 | B29: FUNC-CONTRACT-004 | C29: ='Contract-Calendar'!A7 -> 2 | D29: ='Contract-Calendar'!C7 -> 0 | E29: ='Contract-Calendar'!F7 -> 0 | F29: ='Contract-Calendar'!L7 -> 1 | G29: ='Contract-Calendar'!M7 -> 0 | H29: ='Contract-Calendar'!N7 -> 1 | I29: ='Contract-Calendar'!O7 -> 2
A30: 19 | B30: FUNC-LISTING-001 | C30: =SUM('Listing-CRUD-1'!A7,'Listing-CRUD-2'!A7) -> 25 | D30: =SUM('Listing-CRUD-1'!C7,'Listing-CRUD-2'!C7) -> 4 | E30: =SUM('Listing-CRUD-1'!F7,'Listing-CRUD-2'!F7) -> 0 | F30: =SUM('Listing-CRUD-1'!L7,'Listing-CRUD-2'!L7) -> 10 | G30: =SUM('Listing-CRUD-1'!M7,'Listing-CRUD-2'!M7) -> 14 | H30: =SUM('Listing-CRUD-1'!N7,'Listing-CRUD-2'!N7) -> 5 | I30: =SUM('Listing-CRUD-1'!O7,'Listing-CRUD-2'!O7) -> 29
A31: 20 | B31: FUNC-LISTING-002 | C31: ='Listing-Query'!A7 -> 9 | D31: ='Listing-Query'!C7 -> 0 | E31: ='Listing-Query'!F7 -> 0 | F31: ='Listing-Query'!L7 -> 3 | G31: ='Listing-Query'!M7 -> 4 | H31: ='Listing-Query'!N7 -> 2 | I31: ='Listing-Query'!O7 -> 9
A32: 21 | B32: FUNC-LISTING-003 | C32: ='Listing-Report'!A7 -> 9 | D32: ='Listing-Report'!C7 -> 0 | E32: ='Listing-Report'!F7 -> 0 | F32: ='Listing-Report'!L7 -> 5 | G32: ='Listing-Report'!M7 -> 2 | H32: ='Listing-Report'!N7 -> 2 | I32: ='Listing-Report'!O7 -> 9
A33: 22 | B33: FUNC-LISTING-004 | C33: =SUM('Listing-Share-1'!A7,'Listing-Share-2'!A7) -> 17 | D33: =SUM('Listing-Share-1'!C7,'Listing-Share-2'!C7) -> 1 | E33: =SUM('Listing-Share-1'!F7,'Listing-Share-2'!F7) -> 0 | F33: =SUM('Listing-Share-1'!L7,'Listing-Share-2'!L7) -> 5 | G33: =SUM('Listing-Share-1'!M7,'Listing-Share-2'!M7) -> 9 | H33: =SUM('Listing-Share-1'!N7,'Listing-Share-2'!N7) -> 4 | I33: =SUM('Listing-Share-1'!O7,'Listing-Share-2'!O7) -> 18
A34: 23 | B34: FUNC-WALLET-001 | C34: =WalletService!A7 -> 14 | D34: =WalletService!C7 -> 0 | E34: =WalletService!F7 -> 0 | F34: =WalletService!L7 -> 4 | G34: =WalletService!M7 -> 9 | H34: =WalletService!N7 -> 1 | I34: =WalletService!O7 -> 14
A35: 24 | B35: FUNC-BOOKING-001 | C35: =PrimaryBooking!A7 -> 14 | D35: =PrimaryBooking!C7 -> 0 | E35: =PrimaryBooking!F7 -> 0 | F35: =PrimaryBooking!L7 -> 3 | G35: =PrimaryBooking!M7 -> 9 | H35: =PrimaryBooking!N7 -> 2 | I35: =PrimaryBooking!O7 -> 14
A36: 25 | B36: FUNC-REVIEW-001 | C36: =ReviewService!A7 -> 13 | D36: =ReviewService!C7 -> 0 | E36: =ReviewService!F7 -> 0 | F36: =ReviewService!L7 -> 5 | G36: =ReviewService!M7 -> 7 | H36: =ReviewService!N7 -> 1 | I36: =ReviewService!O7 -> 13
A37: 26 | B37: FUNC-MSG-001 | C37: =MessageService!A7 -> 5 | D37: =MessageService!C7 -> 0 | E37: =MessageService!F7 -> 0 | F37: =MessageService!L7 -> 3 | G37: =MessageService!M7 -> 1 | H37: =MessageService!N7 -> 1 | I37: =MessageService!O7 -> 5
A38: 27 | B38: FUNC-FAV-001 | C38: =FavoriteListService!A7 -> 7 | D38: =FavoriteListService!C7 -> 0 | E38: =FavoriteListService!F7 -> 0 | F38: =FavoriteListService!L7 -> 3 | G38: =FavoriteListService!M7 -> 4 | H38: =FavoriteListService!N7 -> 0 | I38: =FavoriteListService!O7 -> 7
A39: 28 | B39: FUNC-TXN-001 | C39: =TransactionService!A7 -> 5 | D39: =TransactionService!C7 -> 0 | E39: =TransactionService!F7 -> 0 | F39: =TransactionService!L7 -> 1 | G39: =TransactionService!M7 -> 3 | H39: =TransactionService!N7 -> 1 | I39: =TransactionService!O7 -> 5
B40: Sub total | C40: =SUM(C12:C39) -> 206 | D40: =SUM(D12:D39) -> 9 | E40: =SUM(E12:E39) -> 0 | F40: =SUM(F12:F39) -> 73 | G40: =SUM(G12:G39) -> 111 | H40: =SUM(H12:H39) -> 31 | I40: =SUM(I12:I39) -> 215
B42: Test coverage | D42: =(C40+D40)*100/(I40) -> 100 | E42: %
B43: Test successful coverage | D43: =C40*100/(I40) -> 95.813953 | E43: %
B44: Normal case | D44: =F40*100/I40 -> 33.953488 | E44: %
B45: Abnormal case | D45: =G40*100/I40 -> 51.627907 | E45: %
B46: Boundary case | D46: =H40*100/I40 -> 14.418605 | E46: %

Sheet Example
A2: Function Code | C2: =Functions!E11 -> FUNC-AI-001 | F2: Function Name | L2: =Functions!D11 -> GenerateImageAsync
A3: Created By | C3: <Developer Name> | F3: Executed By
A4: Lines of code | C4: 100 | F4: Lack of test cases | L4: =IF(Functions!E6<>"N/A",SUM(C4*Functions!E6/1000,-O7),"N/A") -> -11
A5: Test requirement | C5: <Brief description about requirements which are tested in this function>
A6: Passed | C6: Failed | F6: Untested | L6: N/A/B | O6: Total Test Cases
A7: =COUNTIF(F47:HQ47,"P") -> 0 | C7: =COUNTIF(F47:HQ47,"F") -> 0 | F7: =SUM(O7,-A7,-C7) -> 15 | L7: =COUNTIF(E46:HQ46,"N") -> 0 | M7: =COUNTIF(E46:HQ46,"A") -> 0 | N7: =COUNTIF(E46:HQ46,"B") -> 0 | O7: =COUNTA(E9:HT9) -> 15
F9: UTCID01 | G9: UTCID02 | H9: UTCID02 | I9: UTCID02 | J9: UTCID02 | K9: UTCID02 | L9: UTCID07 | M9: UTCID08 | N9: UTCID09 | O9: UTCID10 | P9: UTCID11 | Q9: UTCID12 | R9: UTCID13 | S9: UTCID14 | T9: UTCID15
A10: Condition | B10: Precondition
B14: a
D15: -2 | F15: O
D16: -1 | L16: O
D17: 0 | G17: O | H17: O | I17: O
D18: 1 | J18: O | K18: O
B19: b
D20: 0 | G20: O | H20: O
D21: -2 | J21: O | K21: O | L21: O
D22: 2 | I22: O
B23: c
D24: 0 | G24: O
D25: 1 | H25: O | I25: O | J25: O
D26: 3 | L26: O
D27: 5 | K27: O
A33: Confirm | B33: Return
B34: list
D35: null | F35: O | H35: O | K35: O
D36: size = 0 | G36: O
D37: {-1/2} | I37: O
D38: {1,1} | J38: O
D39: {1,-3} | L39: O
B40: Exception
B42: Log message
D43: "please input a>= -1" | F43: O
A45: Result | B45: Type(N : Normal, A : Abnormal, B : Boundary) | F45: A | G45: N | H45: N | I45: N | J45: N | K45: N | L45: B
B46: Passed/Failed
B47: Executed Date | F47: 39139 | G47: 39139 | H47: 39139 | I47: 39139 | J47: 39139 | K47: 39139 | L47: 39144
B48: Defect ID

Sheet AIToolService
A2: Function Code | C2: =Functions!E11 -> FUNC-AI-001 | F2: Function Name | L2: =Functions!D11 -> GenerateImageAsync
A3: Created By | C3: <Developer Name> | F3: Executed By
A4: Lines of code | C4: 74 | F4: Lack of test cases | L4: =IF(Functions!E6<>"N/A",SUM(C4*Functions!E6/1000,-O7),"N/A") -> -3.04
A5: Test requirement | C5: Verify AI image generation: wallet balance gating, AI provider call, Cloudinary upload, payment, and history logging.
A6: Passed | C6: Failed | F6: Untested | L6: N/A/B | O6: Total Test Cases
A7: =COUNTIF(F40:T40,"P") -> 6 | C7: =COUNTIF(F40:T40,"F") -> 0 | F7: =SUM(O7,-A7,-C7) -> 0 | L7: =COUNTIF(F39:T39,"N") -> 1 | M7: =COUNTIF(F39:T39,"A") -> 4 | N7: =COUNTIF(F39:T39,"B") -> 1 | O7: =COUNTA(F40:T40) -> 6
F9: UTCID01 | G9: UTCID02 | H9: UTCID03 | I9: UTCID04 | J9: UTCID05 | K9: UTCID06 | L9: UTCID07 | M9: UTCID08 | N9: UTCID09 | O9: UTCID10 | P9: UTCID11 | Q9: UTCID12 | R9: UTCID13 | S9: UTCID14 | T9: UTCID15
A10: Condition | B10: Precondition
D11: FalAiService, PictureURL, wallet service, history repository mocks initialized | F11: O | G11: O | H11: O | I11: O | J11: O | K11: O
B12: Wallet / AI provider state | D12: Wallet found, Balance=5000, AI+Cloudinary succeed, wallet spend succeeds | F12: O
D13: GetOwnWallet returns IsSuccess=false (wallet not found) | G13: O
D14: Wallet found, Balance=1999 (below 2000 minimum) | H14: O
D15: Wallet ok, FalAiService.GenerateInpaintingAsync returns empty string | I15: O
D16: Wallet ok, AI+upload succeed, SpendWalletBalance returns IsSuccess=false ("wallet locked") | J16: O
D17: GetOwnWallet throws InvalidOperationException("service unavailable") | K17: O
A31: Confirm | B31: Return | D31: IsSuccess=true, Data=Cloudinary URL; history AddAsync called once (UserId/Prompt/ResultImageUrl); SaveChangesAsync once | F31: O
D32: IsSuccess=false, Message="Không tìm thấy ví của bạn hoặc bạn chưa đăng nhập."; AI service never called | G32: O
D33: IsSuccess=false, Message="Số dư ví không đủ. Cần tối thiểu 2000 để sử dụng tính năng AI."; AI service never called | H33: O
D34: IsSuccess=false, Message="Không thể sinh ảnh từ AI."; SpendWalletBalance never called | I34: O
D35: IsSuccess=false, Message="Đã xảy ra lỗi khi thanh toán: wallet locked"; history AddAsync never called | J35: O
D36: IsSuccess=false, Message="Lỗi hệ thống: service unavailable" | K36: O
A39: Result | B39: Type(N : Normal, A : Abnormal, B : Boundary) | F39: N | G39: A | H39: B | I39: A | J39: A | K39: A
B40: Passed/Failed | F40: P | G40: P | H40: P | I40: P | J40: P | K40: P
B41: Executed Date | F41: 46260 | G41: 46260 | H41: 46260 | I41: 46260 | J41: 46260 | K41: 46260
B42: Defect ID

Sheet AmenityService
A2: Function Code | C2: =Functions!E12 -> FUNC-AMN-001 | F2: Function Name | L2: =Functions!D12 -> GetAllAmenitiesBySpaceIdAsync
A3: Created By | C3: <Developer Name> | F3: Executed By
A4: Lines of code | C4: 48 | F4: Lack of test cases | L4: =IF(Functions!E6<>"N/A",SUM(C4*Functions!E6/1000,-O7),"N/A") -> -4.08
A5: Test requirement | C5: Verify amenities retrieval for a space under various space/amenity repository states.
A6: Passed | C6: Failed | F6: Untested | L6: N/A/B | O6: Total Test Cases
A7: =COUNTIF(F40:T40,"P") -> 6 | C7: =COUNTIF(F40:T40,"F") -> 0 | F7: =SUM(O7,-A7,-C7) -> 0 | L7: =COUNTIF(F39:T39,"N") -> 2 | M7: =COUNTIF(F39:T39,"A") -> 2 | N7: =COUNTIF(F39:T39,"B") -> 2 | O7: =COUNTA(F40:T40) -> 6
F9: UTCID01 | G9: UTCID02 | H9: UTCID03 | I9: UTCID04 | J9: UTCID05 | K9: UTCID06 | L9: UTCID07 | M9: UTCID08 | N9: UTCID09 | O9: UTCID10 | P9: UTCID11 | Q9: UTCID12 | R9: UTCID13 | S9: UTCID14 | T9: UTCID15
A10: Condition | B10: Precondition
D11: Space repository and amenity repository mocks are initialized | F11: O | G11: O | H11: O | I11: O | J11: O | K11: O
B12: spaceId lookup | D12: Space not found | F12: O
D13: Space found (Id=123) | G13: O | H13: O | I13: O | J13: O
D14: Space repository throws InvalidOperationException("Db failure") | K14: O
B15: Amenity repository result | D15: Empty list | G15: O
D16: 2 amenities (Id=1,2 / Quantity=2,5) | H16: O
D17: null (repository returns null) | I17: O
D18: 1 amenity matching spaceId filter | J18: O
A31: Confirm | B31: Return | D31: IsSuccess=false, IsNotFound=true, Message contains "Không tìm thấy mặt bằng với ID đã cho.", Data=null | F31: O
D32: IsSuccess=true, Data empty, Message contains "Không có tiện ích nào cho mặt bằng này." | G32: O | I32: O
D33: IsSuccess=true, Data has 2 items mapped correctly (Id, SpaceId, Quantity) | H33: O
D34: IsSuccess=true, Data has 1 item, SpaceId matches filter | J34: O
D35: IsSuccess=false, Message contains "Lỗi khi lấy danh sách tiện ích: Db failure", Data=null | K35: O
A39: Result | B39: Type(N : Normal, A : Abnormal, B : Boundary) | F39: A | G39: B | H39: N | I39: B | J39: N | K39: A
B40: Passed/Failed | F40: P | G40: P | H40: P | I40: P | J40: P | K40: P
B41: Executed Date | F41: 46260 | G41: 46260 | H41: 46260 | I41: 46260 | J41: 46260 | K41: 46260
B42: Defect ID

Sheet Auth-Login
A2: Function Code | C2: =Functions!E13 -> FUNC-AUTH-001 | F2: Function Name | L2: =Functions!D13 -> LoginAsync
A3: Created By | C3: <Developer Name> | F3: Executed By
A4: Lines of code | C4: 39 | F4: Lack of test cases | L4: =IF(Functions!E6<>"N/A",SUM(C4*Functions!E6/1000,-O7),"N/A") -> -1.44
A5: Test requirement | C5: Verify login flow: CAPTCHA verification, account lookup, credential match.
A6: Passed | C6: Failed | F6: Untested | L6: N/A/B | O6: Total Test Cases
A7: =COUNTIF(F40:T40,"P") -> 3 | C7: =COUNTIF(F40:T40,"F") -> 0 | F7: =SUM(O7,-A7,-C7) -> 0 | L7: =COUNTIF(F39:T39,"N") -> 1 | M7: =COUNTIF(F39:T39,"A") -> 2 | N7: =COUNTIF(F39:T39,"B") -> 0 | O7: =COUNTA(F40:T40) -> 3
F9: UTCID01 | G9: UTCID02 | H9: UTCID03 | I9: UTCID04 | J9: UTCID05 | K9: UTCID06 | L9: UTCID07 | M9: UTCID08 | N9: UTCID09 | O9: UTCID10 | P9: UTCID11 | Q9: UTCID12 | R9: UTCID13 | S9: UTCID14 | T9: UTCID15
A10: Condition | B10: Precondition
D11: Turnstile, user repository, JWT provider mocks are initialized | F11: O | G11: O | H11: O
B12: Turnstile token / account lookup | D12: invalid-token (verification fails) | F12: O
D13: valid-token; account not found for email | G13: O
D14: valid-token; account found, password matches, Active/IsActive=true | H14: O
A31: Confirm | B31: Return | D31: IsSuccess=false, Message contains "Xác thực CAPTCHA thất bại", Data=null | F31: O
D32: IsSuccess=false, Message contains "Tài khoản hoặc mật khẩu không chính xác", Data=null | G32: O
D33: IsSuccess=true, Message="Đăng nhập thành công.", Data.AccessToken="generated-jwt-token", Data.Message contains UserId | H33: O
A39: Result | B39: Type(N : Normal, A : Abnormal, B : Boundary) | F39: A | G39: A | H39: N
B40: Passed/Failed | F40: P | G40: P | H40: P
B41: Executed Date | F41: 46260 | G41: 46260 | H41: 46260
B42: Defect ID

Sheet Auth-Register
A2: Function Code | C2: =Functions!E14 -> FUNC-AUTH-002 | F2: Function Name | L2: =Functions!D14 -> RegisterAsync
A3: Created By | C3: <Developer Name> | F3: Executed By
A4: Lines of code | C4: 76 | F4: Lack of test cases | L4: =IF(Functions!E6<>"N/A",SUM(C4*Functions!E6/1000,-O7),"N/A") -> 0.04
A5: Test requirement | C5: Verify registration flow: duplicate email handling, OTP dispatch, unverified account re-registration.
A6: Passed | C6: Failed | F6: Untested | L6: N/A/B | O6: Total Test Cases
A7: =COUNTIF(F40:T40,"P") -> 3 | C7: =COUNTIF(F40:T40,"F") -> 0 | F7: =SUM(O7,-A7,-C7) -> 0 | L7: =COUNTIF(F39:T39,"N") -> 1 | M7: =COUNTIF(F39:T39,"A") -> 1 | N7: =COUNTIF(F39:T39,"B") -> 1 | O7: =COUNTA(F40:T40) -> 3
F9: UTCID01 | G9: UTCID02 | H9: UTCID03 | I9: UTCID04 | J9: UTCID05 | K9: UTCID06 | L9: UTCID07 | M9: UTCID08 | N9: UTCID09 | O9: UTCID10 | P9: UTCID11 | Q9: UTCID12 | R9: UTCID13 | S9: UTCID14 | T9: UTCID15
A10: Condition | B10: Precondition
D11: Turnstile verified=true, email/OTP/user repository mocks initialized | F11: O | G11: O | H11: O
B12: Existing account state for request.Email | D12: Active account already exists (IsActive=true) | F12: O
D13: No account exists | G13: O
D14: Unverified account exists (IsActive=false) | H14: O
A31: Confirm | B31: Return | D31: IsSuccess=false, Message contains "Email này đã được sử dụng hệ thống" | F31: O
D32: IsSuccess=true, Message contains "Đăng ký thành công", new User added (IsActive=false), OTP cached, ResendOtpEmailAsync called once | G32: O
D33: IsSuccess=true, existing account fields updated (UserName/Name/Phone/Password hash), AddAsync never called, UpdateAsync called once, OTP email resent once | H33: O
A39: Result | B39: Type(N : Normal, A : Abnormal, B : Boundary) | F39: A | G39: N | H39: B
B40: Passed/Failed | F40: P | G40: P | H40: P
B41: Executed Date | F41: 46260 | G41: 46260 | H41: 46260
B42: Defect ID

Sheet Auth-VerifyOtp
A2: Function Code | C2: =Functions!E15 -> FUNC-AUTH-003 | F2: Function Name | L2: =Functions!D15 -> VerifyOtpAsync
A3: Created By | C3: <Developer Name> | F3: Executed By
A4: Lines of code | C4: 50 | F4: Lack of test cases | L4: =IF(Functions!E6<>"N/A",SUM(C4*Functions!E6/1000,-O7),"N/A") -> 0
A5: Test requirement | C5: Verify OTP code validation and account activation.
A6: Passed | C6: Failed | F6: Untested | L6: N/A/B | O6: Total Test Cases
A7: =COUNTIF(F40:T40,"P") -> 2 | C7: =COUNTIF(F40:T40,"F") -> 0 | F7: =SUM(O7,-A7,-C7) -> 0 | L7: =COUNTIF(F39:T39,"N") -> 1 | M7: =COUNTIF(F39:T39,"A") -> 1 | N7: =COUNTIF(F39:T39,"B") -> 0 | O7: =COUNTA(F40:T40) -> 2
F9: UTCID01 | G9: UTCID02 | H9: UTCID03 | I9: UTCID04 | J9: UTCID05 | K9: UTCID06 | L9: UTCID07 | M9: UTCID08 | N9: UTCID09 | O9: UTCID10 | P9: UTCID11 | Q9: UTCID12 | R9: UTCID13 | S9: UTCID14 | T9: UTCID15
A10: Condition | B10: Precondition
D11: OTP cached under key OTP:Register:{email} | F11: O | G11: O
B12: OTP code entered vs cached | D12: Entered "000000" != cached "123456" | F12: O
D13: Entered code matches cached code, account exists (IsActive=false) | G13: O
A31: Confirm | B31: Return | D31: IsSuccess=false, Message contains "Mã OTP không chính xác hoặc đã hết hạn" | F31: O
D32: IsSuccess=true, Message contains "Xác thực OTP thành công", Data.AccessToken="otp-token", account.IsActive=true, OTP cache entry removed | G32: O
A39: Result | B39: Type(N : Normal, A : Abnormal, B : Boundary) | F39: A | G39: N
B40: Passed/Failed | F40: P | G40: P
B41: Executed Date | F41: 46260 | G41: 46260
B42: Defect ID

Sheet Auth-ResetPwd
A2: Function Code | C2: =Functions!E16 -> FUNC-AUTH-004 | F2: Function Name | L2: =Functions!D16 -> SendPasswordOtpAsync / ResetPasswordAsync
A3: Created By | C3: <Developer Name> | F3: Executed By
A4: Lines of code | C4: 87 | F4: Lack of test cases | L4: =IF(Functions!E6<>"N/A",SUM(C4*Functions!E6/1000,-O7),"N/A") -> -0.52
A5: Test requirement | C5: Verify password reset OTP dispatch, email normalization, and OTP-based password update.
A6: Passed | C6: Failed | F6: Untested | L6: N/A/B | O6: Total Test Cases
A7: =COUNTIF(F40:T40,"P") -> 4 | C7: =COUNTIF(F40:T40,"F") -> 0 | F7: =SUM(O7,-A7,-C7) -> 0 | L7: =COUNTIF(F39:T39,"N") -> 1 | M7: =COUNTIF(F39:T39,"A") -> 2 | N7: =COUNTIF(F39:T39,"B") -> 1 | O7: =COUNTA(F40:T40) -> 4
F9: UTCID01 | G9: UTCID02 | H9: UTCID03 | I9: UTCID04 | J9: UTCID05 | K9: UTCID06 | L9: UTCID07 | M9: UTCID08 | N9: UTCID09 | O9: UTCID10 | P9: UTCID11 | Q9: UTCID12 | R9: UTCID13 | S9: UTCID14 | T9: UTCID15
A10: Condition | B10: Precondition
D11: OTP cache key OTP:Password:{email} set/removed per scenario | F11: O | G11: O | H11: O | I11: O
B12: Input state | D12: SendPasswordOtpAsync: email not found in user repository | F12: O
D13: SendPasswordOtpAsync: email " User@Email.com " (whitespace/casing), user exists | G13: O
D14: ResetPasswordAsync: cache entry empty/removed, entered "000000" | H14: O
D15: ResetPasswordAsync: entered code "123456" matches cached code, account exists | I15: O
A31: Confirm | B31: Return | D31: IsSuccess=false, Message contains "Email"; ResendOtpEmailAsync never called | F31: O
D32: IsSuccess=true; cache key normalized to "OTP:Password:user@email.com" holds 6-char OTP; email sent once | G32: O
D33: IsSuccess=false, Message contains "Mã OTP không chính xác hoặc đã hết hạn" | H33: O
D34: IsSuccess=true, Message contains "Đặt lại mật khẩu thành công", account.Password re-hashed to NewPassword, OTP cache entry removed | I34: O
A39: Result | B39: Type(N : Normal, A : Abnormal, B : Boundary) | F39: A | G39: B | H39: A | I39: N
B40: Passed/Failed | F40: P | G40: P | H40: P | I40: P
B41: Executed Date | F41: 46260 | G41: 46260 | H41: 46260 | I41: 46260
B42: Defect ID

Sheet Auth-ChangePwd
A2: Function Code | C2: =Functions!E17 -> FUNC-AUTH-005 | F2: Function Name | L2: =Functions!D17 -> ChangePasswordAsync
A3: Created By | C3: <Developer Name> | F3: Executed By
A4: Lines of code | C4: 43 | F4: Lack of test cases | L4: =IF(Functions!E6<>"N/A",SUM(C4*Functions!E6/1000,-O7),"N/A") -> -0.28
A5: Test requirement | C5: Verify current password validation and password change.
A6: Passed | C6: Failed | F6: Untested | L6: N/A/B | O6: Total Test Cases
A7: =COUNTIF(F40:T40,"P") -> 2 | C7: =COUNTIF(F40:T40,"F") -> 0 | F7: =SUM(O7,-A7,-C7) -> 0 | L7: =COUNTIF(F39:T39,"N") -> 1 | M7: =COUNTIF(F39:T39,"A") -> 1 | N7: =COUNTIF(F39:T39,"B") -> 0 | O7: =COUNTA(F40:T40) -> 2
F9: UTCID01 | G9: UTCID02 | H9: UTCID03 | I9: UTCID04 | J9: UTCID05 | K9: UTCID06 | L9: UTCID07 | M9: UTCID08 | N9: UTCID09 | O9: UTCID10 | P9: UTCID11 | Q9: UTCID12 | R9: UTCID13 | S9: UTCID14 | T9: UTCID15
A10: Condition | B10: Precondition
D11: Account found by email with hashed current password | F11: O | G11: O
B12: Current password provided | D12: "WrongPassword!" (does not match stored hash) | F12: O
D13: "CurrentPassword1!" (matches stored hash) | G13: O
A31: Confirm | B31: Return | D31: IsSuccess=false, Message contains "Mật khẩu hiện tại không chính xác" | F31: O
D32: IsSuccess=true, Message contains "Đổi mật khẩu thành công", account.Password re-hashed to NewPassword | G32: O
A39: Result | B39: Type(N : Normal, A : Abnormal, B : Boundary) | F39: A | G39: N
B40: Passed/Failed | F40: P | G40: P
B41: Executed Date | F41: 46260 | G41: 46260
B42: Defect ID

Sheet BookingNotif-Created
A2: Function Code | C2: =Functions!E18 -> FUNC-NOTI-001 | F2: Function Name | L2: =Functions!D18 -> Handle
A3: Created By | C3: <Developer Name> | F3: Executed By
A4: Lines of code | C4: 26 | F4: Lack of test cases | L4: =IF(Functions!E6<>"N/A",SUM(C4*Functions!E6/1000,-O7),"N/A") -> -1.96
A5: Test requirement | C5: Verify booking-created notification is sent to the lessor, guarded by empty LessorId, and exceptions are swallowed.
A6: Passed | C6: Failed | F6: Untested | L6: N/A/B | O6: Total Test Cases
A7: =COUNTIF(F40:T40,"P") -> 3 | C7: =COUNTIF(F40:T40,"F") -> 0 | F7: =SUM(O7,-A7,-C7) -> 0 | L7: =COUNTIF(F39:T39,"N") -> 1 | M7: =COUNTIF(F39:T39,"A") -> 2 | N7: =COUNTIF(F39:T39,"B") -> 0 | O7: =COUNTA(F40:T40) -> 3
F9: UTCID01 | G9: UTCID02 | H9: UTCID03 | I9: UTCID04 | J9: UTCID05 | K9: UTCID06 | L9: UTCID07 | M9: UTCID08 | N9: UTCID09 | O9: UTCID10 | P9: UTCID11 | Q9: UTCID12 | R9: UTCID13 | S9: UTCID14 | T9: UTCID15
A10: Condition | B10: Precondition
D11: NotificationService mock initialized | F11: O | G11: O | H11: O
B12: Event payload | D12: LessorId = " " (blank) | F12: O
D13: Valid LessorId="lessor-1", NotificationService.CreateAsync succeeds | G13: O
D14: Valid LessorId, NotificationService.CreateAsync throws InvalidOperationException("notification failed") | H14: O
A31: Confirm | B31: Return | D31: CreateAsync never called | F31: O
D32: CreateAsync called once with ("lessor-1", "Yeu cau dat cho moi", "Co nguoi vua gui yeu cau dat cho cho Space A.", Booking, "10") | G32: O
D33: Handle does not throw (exception swallowed) | H33: O
A39: Result | B39: Type(N : Normal, A : Abnormal, B : Boundary) | F39: A | G39: N | H39: A
B40: Passed/Failed | F40: P | G40: P | H40: P
B41: Executed Date | F41: 46260 | G41: 46260 | H41: 46260
B42: Defect ID

Sheet BookingNotif-Approved
A2: Function Code | C2: =Functions!E19 -> FUNC-NOTI-002 | F2: Function Name | L2: =Functions!D19 -> Handle
A3: Created By | C3: <Developer Name> | F3: Executed By
A4: Lines of code | C4: 26 | F4: Lack of test cases | L4: =IF(Functions!E6<>"N/A",SUM(C4*Functions!E6/1000,-O7),"N/A") -> -0.96
A5: Test requirement | C5: Verify booking-approved notification is sent to the lessee, guarded by empty LesseeId.
A6: Passed | C6: Failed | F6: Untested | L6: N/A/B | O6: Total Test Cases
A7: =COUNTIF(F40:T40,"P") -> 2 | C7: =COUNTIF(F40:T40,"F") -> 0 | F7: =SUM(O7,-A7,-C7) -> 0 | L7: =COUNTIF(F39:T39,"N") -> 1 | M7: =COUNTIF(F39:T39,"A") -> 1 | N7: =COUNTIF(F39:T39,"B") -> 0 | O7: =COUNTA(F40:T40) -> 2
F9: UTCID01 | G9: UTCID02 | H9: UTCID03 | I9: UTCID04 | J9: UTCID05 | K9: UTCID06 | L9: UTCID07 | M9: UTCID08 | N9: UTCID09 | O9: UTCID10 | P9: UTCID11 | Q9: UTCID12 | R9: UTCID13 | S9: UTCID14 | T9: UTCID15
A10: Condition | B10: Precondition
D11: NotificationService mock initialized | F11: O | G11: O
B12: Event payload | D12: LesseeId = "" (empty) | F12: O
D13: Valid LesseeId="lessee-1", NotificationService.CreateAsync succeeds | G13: O
A31: Confirm | B31: Return | D31: CreateAsync never called | F31: O
D32: CreateAsync called once with ("lessee-1", "Yeu cau dat cho da duoc duyet", "Yeu cau dat cho cua ban cho space #30 da duoc nguoi cho thue chap thuan.", Booking, "10") | G32: O
A39: Result | B39: Type(N : Normal, A : Abnormal, B : Boundary) | F39: A | G39: N
B40: Passed/Failed | F40: P | G40: P
B41: Executed Date | F41: 46260 | G41: 46260
B42: Defect ID

Sheet Conv-GetOrCreate
A2: Function Code | C2: =Functions!E20 -> FUNC-CONV-001 | F2: Function Name | L2: =Functions!D20 -> GetOrCreateConversationAsync
A3: Created By | C3: <Developer Name> | F3: Executed By
A4: Lines of code | C4: 34 | F4: Lack of test cases | L4: =IF(Functions!E6<>"N/A",SUM(C4*Functions!E6/1000,-O7),"N/A") -> -1.64
A5: Test requirement | C5: Verify conversation lookup/creation between lessor and lessee.
A6: Passed | C6: Failed | F6: Untested | L6: N/A/B | O6: Total Test Cases
A7: =COUNTIF(F40:T40,"P") -> 3 | C7: =COUNTIF(F40:T40,"F") -> 0 | F7: =SUM(O7,-A7,-C7) -> 0 | L7: =COUNTIF(F39:T39,"N") -> 2 | M7: =COUNTIF(F39:T39,"A") -> 1 | N7: =COUNTIF(F39:T39,"B") -> 0 | O7: =COUNTA(F40:T40) -> 3
F9: UTCID01 | G9: UTCID02 | H9: UTCID03 | I9: UTCID04 | J9: UTCID05 | K9: UTCID06 | L9: UTCID07 | M9: UTCID08 | N9: UTCID09 | O9: UTCID10 | P9: UTCID11 | Q9: UTCID12 | R9: UTCID13 | S9: UTCID14 | T9: UTCID15
A10: Condition | B10: Precondition
D11: Conversation repository mock initialized | F11: O | G11: O | H11: O
B12: Existing conversation for (lessorId, lesseeId) | D12: Conversation already exists | F12: O
D13: No conversation exists (null) | G13: O
D14: Repository throws InvalidOperationException("Db failure") | H14: O
A31: Confirm | B31: Return | D31: IsSuccess=true, Data=existing conversation.Id, Message contains "đã tồn tại", AddAsync/SaveChangesAsync never called | F31: O
D32: IsSuccess=true, Data=new non-empty Id, Message contains "mới đã được tạo", AddAsync+SaveChangesAsync called once | G32: O
D33: Throws Exception with message containing "Lỗi khi lấy hoặc tạo cuộc trò chuyện: Db failure" | H33: O
A39: Result | B39: Type(N : Normal, A : Abnormal, B : Boundary) | F39: N | G39: N | H39: A
B40: Passed/Failed | F40: P | G40: P | H40: P
B41: Executed Date | F41: 46260 | G41: 46260 | H41: 46260
B42: Defect ID

Sheet Conv-Query
A2: Function Code | C2: =Functions!E21 -> FUNC-CONV-002 | F2: Function Name | L2: =Functions!D21 -> GetConversationsByUserIdAsync / GetConversationByParticipantsAsync
A3: Created By | C3: <Developer Name> | F3: Executed By
A4: Lines of code | C4: 59 | F4: Lack of test cases | L4: =IF(Functions!E6<>"N/A",SUM(C4*Functions!E6/1000,-O7),"N/A") -> -0.64
A5: Test requirement | C5: Verify conversation queries by user and by participant pair.
A6: Passed | C6: Failed | F6: Untested | L6: N/A/B | O6: Total Test Cases
A7: =COUNTIF(F40:T40,"P") -> 3 | C7: =COUNTIF(F40:T40,"F") -> 0 | F7: =SUM(O7,-A7,-C7) -> 0 | L7: =COUNTIF(F39:T39,"N") -> 1 | M7: =COUNTIF(F39:T39,"A") -> 2 | N7: =COUNTIF(F39:T39,"B") -> 0 | O7: =COUNTA(F40:T40) -> 3
F9: UTCID01 | G9: UTCID02 | H9: UTCID03 | I9: UTCID04 | J9: UTCID05 | K9: UTCID06 | L9: UTCID07 | M9: UTCID08 | N9: UTCID09 | O9: UTCID10 | P9: UTCID11 | Q9: UTCID12 | R9: UTCID13 | S9: UTCID14 | T9: UTCID15
A10: Condition | B10: Precondition
D11: Conversation repository / mapper mocks initialized | F11: O | G11: O | H11: O
B12: Query type / repository result | D12: GetConversationsByUserIdAsync("user-1") -> repository returns 1 conversation | F12: O
D13: GetConversationByParticipantsAsync(lessor,lessee) -> repository returns null (not found) | G13: O
D14: GetConversationByParticipantsAsync(lessor,lessee) -> repository throws InvalidOperationException("Db failure") | H14: O
A31: Confirm | B31: Return | D31: IsSuccess=true, Data equivalent to mapped ConversationResp list, Message="Lấy danh sách cuộc trò chuyện thành công." | F31: O
D32: IsSuccess=false, IsNotFound=true, Data=null, Message contains "Không tìm thấy" | G32: O
D33: IsSuccess=false, Message="Db failure" | H33: O
A39: Result | B39: Type(N : Normal, A : Abnormal, B : Boundary) | F39: N | G39: A | H39: A
B40: Passed/Failed | F40: P | G40: P | H40: P
B41: Executed Date | F41: 46260 | G41: 46260 | H41: 46260
B42: Defect ID

Sheet Dashboard-Stats
A2: Function Code | C2: =Functions!E22 -> FUNC-DASH-001 | F2: Function Name | L2: =Functions!D22 -> GetDashboardStatsAsync
A3: Created By | C3: <Developer Name> | F3: Executed By
A4: Lines of code | C4: 57 | F4: Lack of test cases | L4: =IF(Functions!E6<>"N/A",SUM(C4*Functions!E6/1000,-O7),"N/A") -> 0.28
A5: Test requirement | C5: Verify dashboard statistics aggregation from wallets and transaction histories.
A6: Passed | C6: Failed | F6: Untested | L6: N/A/B | O6: Total Test Cases
A7: =COUNTIF(F40:T40,"P") -> 2 | C7: =COUNTIF(F40:T40,"F") -> 0 | F7: =SUM(O7,-A7,-C7) -> 0 | L7: =COUNTIF(F39:T39,"N") -> 1 | M7: =COUNTIF(F39:T39,"A") -> 1 | N7: =COUNTIF(F39:T39,"B") -> 0 | O7: =COUNTA(F40:T40) -> 2
F9: UTCID01 | G9: UTCID02 | H9: UTCID03 | I9: UTCID04 | J9: UTCID05 | K9: UTCID06 | L9: UTCID07 | M9: UTCID08 | N9: UTCID09 | O9: UTCID10 | P9: UTCID11 | Q9: UTCID12 | R9: UTCID13 | S9: UTCID14 | T9: UTCID15
A10: Condition | B10: Precondition
D11: Wallet repository and transaction history repository mocks initialized | F11: O | G11: O
B12: Repository result | D12: Wallets=[150000,250000]; Histories: listing(-50000), AI(-2000)x2, other(-10000, ignored) | F12: O
D13: Wallet repository throws Exception("Database connection failed") | G13: O
A31: Confirm | B31: Return | D31: IsSuccess=true, TotalWalletBalance=400000, TotalListingSpent=50000, TotalListingCount=1, TotalAiImageSpent=4000, TotalAiImageCount=2, TotalSpent=54000, Message="Lấy dữ liệu dashboard thành công." | F31: O
D32: IsSuccess=false, Data=null, Message contains "Lỗi khi tải dữ liệu dashboard: Database connection failed" | G32: O
A39: Result | B39: Type(N : Normal, A : Abnormal, B : Boundary) | F39: N | G39: A
B40: Passed/Failed | F40: P | G40: P
B41: Executed Date | F41: 46260 | G41: 46260
B42: Defect ID

Sheet Dashboard-Listing
A2: Function Code | C2: =Functions!E23 -> FUNC-DASH-002 | F2: Function Name | L2: =Functions!D23 -> GetListingOverviewAsync
A3: Created By | C3: <Developer Name> | F3: Executed By
A4: Lines of code | C4: 111 | F4: Lack of test cases | L4: =IF(Functions!E6<>"N/A",SUM(C4*Functions!E6/1000,-O7),"N/A") -> 1.44
A5: Test requirement | C5: Verify owner listing overview chart aggregation: totals, view/booking trends, contract and expiry trends.
A6: Passed | C6: Failed | F6: Untested | L6: N/A/B | O6: Total Test Cases
A7: =COUNTIF(F40:T40,"P") -> 2 | C7: =COUNTIF(F40:T40,"F") -> 1 | F7: =SUM(O7,-A7,-C7) -> 0 | L7: =COUNTIF(F39:T39,"N") -> 1 | M7: =COUNTIF(F39:T39,"A") -> 2 | N7: =COUNTIF(F39:T39,"B") -> 0 | O7: =COUNTA(F40:T40) -> 3
F9: UTCID01 | G9: UTCID02 | H9: UTCID03 | I9: UTCID04 | J9: UTCID05 | K9: UTCID06 | L9: UTCID07 | M9: UTCID08 | N9: UTCID09 | O9: UTCID10 | P9: UTCID11 | Q9: UTCID12 | R9: UTCID13 | S9: UTCID14 | T9: UTCID15
A10: Condition | B10: Precondition
D11: Listing/ListingViewDailyStat/PrimaryBookingRequest/Contract repository mocks initialized | F11: O | G11: O | H11: O
B12: Current user / data state | D12: Current user id = " " (blank, not registered) | F12: O
D13: Owner "owner-1" with 3 listings (Available/Expired/Available), view stats, 1 booking request, 2 active contracts; rangeDays=7, futureDays=3 | G13: O
D14: Owner "owner-1", ListingRepository.GetAllAsync throws InvalidOperationException("Overview failure") | H14: O
A31: Confirm | B31: Return | D31: IsSuccess=false, Message="Register first!"; ListingRepository.GetAllAsync never called | F31: O
D32: IsSuccess=true; TotalListings=3, ActiveListings=2, SignedContracts=2, ExpiredListings=1; NewListingsTrend/ActiveInteractionTrend have 7 points; SignedContractsTrend has 6; ExpiredTrend has 10 (mixed past/future) | G32: O
D33: IsSuccess=false, Message contains "Overview failure" | H33: O
A39: Result | B39: Type(N : Normal, A : Abnormal, B : Boundary) | F39: A | G39: N | H39: A
B40: Passed/Failed | F40: P | G40: P | H40: F
B41: Executed Date | F41: 46260 | G41: 46260 | H41: 46260
B42: Defect ID

Sheet DataSeeder-Admin
A2: Function Code | C2: =Functions!E24 -> FUNC-SEED-001 | F2: Function Name | L2: =Functions!D24 -> SeedAdminAccountAsync
A3: Created By | C3: <Developer Name> | F3: Executed By
A4: Lines of code | C4: 30 | F4: Lack of test cases | L4: =IF(Functions!E6<>"N/A",SUM(C4*Functions!E6/1000,-O7),"N/A") -> -1.8
A5: Test requirement | C5: Verify default admin account seeding based on configuration.
A6: Passed | C6: Failed | F6: Untested | L6: N/A/B | O6: Total Test Cases
A7: =COUNTIF(F40:T40,"P") -> 3 | C7: =COUNTIF(F40:T40,"F") -> 0 | F7: =SUM(O7,-A7,-C7) -> 0 | L7: =COUNTIF(F39:T39,"N") -> 2 | M7: =COUNTIF(F39:T39,"A") -> 0 | N7: =COUNTIF(F39:T39,"B") -> 1 | O7: =COUNTA(F40:T40) -> 3
F9: UTCID01 | G9: UTCID02 | H9: UTCID03 | I9: UTCID04 | J9: UTCID05 | K9: UTCID06 | L9: UTCID07 | M9: UTCID08 | N9: UTCID09 | O9: UTCID10 | P9: UTCID11 | Q9: UTCID12 | R9: UTCID13 | S9: UTCID14 | T9: UTCID15
A10: Condition | B10: Precondition
D11: User repository mock initialized | F11: O | G11: O | H11: O
B12: AdminAccount configuration / existing admin | D12: Configuration empty (missing Email/Password) | F12: O
D13: Valid configuration, admin with same email already exists | G13: O
D14: Valid configuration, no admin account exists (null) | H14: O
A31: Confirm | B31: Return | D31: GetAsync/AddAsync/SaveChangesAsync never called | F31: O
D32: AddAsync never called, SaveChangesAsync never called | G32: O
D33: AddAsync called once with Email/Name/Phone/Role=ADMIN/IsActive=true, SaveChangesAsync called once | H33: O
A39: Result | B39: Type(N : Normal, A : Abnormal, B : Boundary) | F39: B | G39: N | H39: N
B40: Passed/Failed | F40: P | G40: P | H40: P
B41: Executed Date | F41: 46260 | G41: 46260 | H41: 46260
B42: Defect ID

Sheet Contract-CRUD-1
A2: Function Code | C2: =Functions!E25 -> FUNC-CONTRACT-001 | F2: Function Name | L2: =Functions!D25 -> CreateContractAsync / UpdateContractAsync / DeleteContractAsync
A3: Created By | C3: <Developer Name> | F3: Executed By
A4: Lines of code | C4: 105 | F4: Lack of test cases | L4: =IF(Functions!E6<>"N/A",SUM(C4*Functions!E6/1000,-O7),"N/A") -> -4.8
A5: Test requirement | C5: Verify contract creation, update, and deletion — part 1: creation validation, retrieval by id/list, snapshot check.
A6: Passed | C6: Failed | F6: Untested | L6: N/A/B | O6: Total Test Cases
A7: =COUNTIF(F40:T40,"P") -> 8 | C7: =COUNTIF(F40:T40,"F") -> 1 | F7: =SUM(O7,-A7,-C7) -> 0 | L7: =COUNTIF(F39:T39,"N") -> 3 | M7: =COUNTIF(F39:T39,"A") -> 5 | N7: =COUNTIF(F39:T39,"B") -> 1 | O7: =COUNTA(F40:T40) -> 9
F9: UTCID01 | G9: UTCID02 | H9: UTCID03 | I9: UTCID04 | J9: UTCID05 | K9: UTCID06 | L9: UTCID07 | M9: UTCID08 | N9: UTCID09 | O9: UTCID10 | P9: UTCID11 | Q9: UTCID12 | R9: UTCID13 | S9: UTCID14 | T9: UTCID15
A10: Condition | B10: Precondition
D11: Space/Booking/Conversation/Profile/User repository mocks initialized | F11: O | G11: O | H11: O | I11: O | J11: O | K11: O | L11: O | M11: O | N11: O
B12: Action / lookup state | D12: CreateContractAsync: request.Duration = 0 (invalid) | F12: O
D13: CreateContractAsync: valid request, space/booking/conversation found, both profiles verified | G13: O
D14: CreateContractAsync: ContractRepository.AddAsync throws InvalidOperationException("Create contract failure") | H14: O
D15: GetAllContractsAsync: contracts include Lessor/Lessee navigation, current user = lessor-1 | I15: O
D16: GetAllContractsAsync: repository GetAllAsync throws InvalidOperationException("Get contracts failure") | J16: O
D17: GetContractByIdAsync: current user (lessee-1) is a participant | K17: O
D18: GetContractByIdAsync: current user ("other-user") is not a participant | L18: O
D19: GetContractByIdAsync: repository GetAsync throws InvalidOperationException("Get contract failure") | M19: O
D20: GetContractSnapshotByIdAsync: contract found but ContractSnapshot="" (not yet signed) | N20: O
A31: Confirm | B31: Return | D31: IsSuccess=false, Message contains "Thời hạn", AddAsync never called | F31: O
D32: IsSuccess=true, Data populated (Lessor/Lessee number cards, names, addresses), EndDate=StartDate+1 month, ContractVerification+1 schedule created, AddAsync+CommitTransactionAsync once | G32: O
D33: IsSuccess=false, Message="Create contract failure", RollbackTransactionAsync called once | H33: O
D34: IsSuccess=true, Data equivalent to responses, LessorNickName/LesseeNickName populated | I34: O
D35: IsSuccess=false, Message="Get contracts failure" or "Get contract failure" (repository exception) | J35: O | M35: O
D36: IsSuccess=true, Data equivalent to response, nick names populated | K36: O
D37: IsSuccess=false, Message contains "không có quyền" | L37: O
D38: IsSuccess=false, Message contains "chưa được ký" | N38: O
A39: Result | B39: Type(N : Normal, A : Abnormal, B : Boundary) | F39: A | G39: N | H39: A | I39: N | J39: A | K39: N | L39: A | M39: A | N39: B
B40: Passed/Failed | F40: P | G40: P | H40: P | I40: P | J40: P | K40: P | L40: P | M40: P | N40: F
B41: Executed Date | F41: 46260 | G41: 46260 | H41: 46260 | I41: 46260 | J41: 46260 | K41: 46260 | L41: 46260 | M41: 46260 | N41: 46260
B42: Defect ID

Sheet Contract-CRUD-2
A2: Function Code | C2: =Functions!E25 -> FUNC-CONTRACT-001 | F2: Function Name | L2: =Functions!D25 -> CreateContractAsync / UpdateContractAsync / DeleteContractAsync
A3: Created By | C3: <Developer Name> | F3: Executed By
A4: Lines of code | C4: 104 | F4: Lack of test cases | L4: =IF(Functions!E6<>"N/A",SUM(C4*Functions!E6/1000,-O7),"N/A") -> -6.84
A5: Test requirement | C5: Verify contract creation, update, and deletion — part 2: update, delete, deactivation of expired contracts, private helper branches.
A6: Passed | C6: Failed | F6: Untested | L6: N/A/B | O6: Total Test Cases
A7: =COUNTIF(F40:T40,"P") -> 10 | C7: =COUNTIF(F40:T40,"F") -> 1 | F7: =SUM(O7,-A7,-C7) -> 0 | L7: =COUNTIF(F39:T39,"N") -> 3 | M7: =COUNTIF(F39:T39,"A") -> 6 | N7: =COUNTIF(F39:T39,"B") -> 2 | O7: =COUNTA(F40:T40) -> 11
F9: UTCID01 | G9: UTCID02 | H9: UTCID03 | I9: UTCID04 | J9: UTCID05 | K9: UTCID06 | L9: UTCID07 | M9: UTCID08 | N9: UTCID09 | O9: UTCID10 | P9: UTCID11 | Q9: UTCID12 | R9: UTCID13 | S9: UTCID14 | T9: UTCID15
A10: Condition | B10: Precondition
D11: Contract repository mock initialized; current user context varies | F11: O | G11: O | H11: O | I11: O | J11: O | K11: O | L11: O | M11: O | N11: O | O11: O | P11: O
B12: Action / lookup state | D12: UpdateContractAsync: Draft contract owned by current user (lessor-1), valid request | F12: O
D13: UpdateContractAsync: contract not found | G13: O
D14: UpdateContractAsync: repository GetAsync throws InvalidOperationException("Update contract failure") | H14: O
D15: DeleteContractAsync: contract not found | I15: O
D16: DeleteContractAsync: Draft contract owned by current user | J16: O
D17: DeleteContractAsync: contract Status=Active (not Draft) | K17: O
D18: DeleteContractAsync: repository GetAsync throws InvalidOperationException("Delete contract failure") | L18: O
D19: DeactivateExpiredContractsAsync: repository returns empty list | M19: O
D20: DeactivateExpiredContractsAsync: 2 Active contracts with EndDate in the past | N20: O
D21: DeactivateExpiredContractsAsync: repository GetAllAsync throws InvalidOperationException("Deactivate failure") | O21: O
D22: Private helpers (CalculateEndDate, PopulateContractParticipantProfilesAsync, SyncContractSchedules, ResetSigningSession) invoked via reflection with boundary/unverified-profile inputs | P22: O
A31: Confirm | B31: Return | D31: IsSuccess=true, ContractSchedules count=1, EndDate recalculated, Lessor/Lessee Name refreshed, UpdateAsync+SaveChangesAsync once | F31: O
D32: IsSuccess=false, IsNotFound=true (UpdateAsync/RemoveByIdAsync never called), Message contains "Không tìm thấy" where applicable | G32: O | I32: O
D33: IsSuccess=false, Message="Update contract failure" / "Delete contract failure" / "Deactivate failure" (repository exception) | H33: O | L33: O | O33: O
D34: IsSuccess=true, SaveChangesAsync called once | J34: O
D35: IsSuccess=false, RemoveByIdAsync never called | K35: O
D36: IsSuccess=true, Data=0, UpdateAsync never called | M36: O
D37: IsSuccess=true, Data=2, contracts set Status=Expired/IsActive=false/UpdatedBy="SystemBackgroundWorker", UpdateAsync x2 | N37: O
D38: CalculateEndDate correct per DurationUnit; unverified-profile path returns verification error message; schedules synced correctly | P38: O
A39: Result | B39: Type(N : Normal, A : Abnormal, B : Boundary) | F39: N | G39: A | H39: A | I39: A | J39: N | K39: A | L39: A | M39: B | N39: N | O39: A | P39: B
B40: Passed/Failed | F40: P | G40: P | H40: P | I40: P | J40: P | K40: P | L40: P | M40: P | N40: P | O40: P | P40: F
B41: Executed Date | F41: 46260 | G41: 46260 | H41: 46260 | I41: 46260 | J41: 46260 | K41: 46260 | L41: 46260 | M41: 46260 | N41: 46260 | O41: 46260 | P41: 46260
B42: Defect ID

Sheet Contract-Signing-1
A2: Function Code | C2: =Functions!E26 -> FUNC-CONTRACT-002 | F2: Function Name | L2: =Functions!D26 -> StartContractSigningAsync / CancelContractSigningAsync / ContractValidateOtpAsync
A3: Created By | C3: <Developer Name> | F3: Executed By
A4: Lines of code | C4: 152 | F4: Lack of test cases | L4: =IF(Functions!E6<>"N/A",SUM(C4*Functions!E6/1000,-O7),"N/A") -> -4.92
A5: Test requirement | C5: Verify contract signing workflow — part 1: start signing and cancel signing, including guard conditions.
A6: Passed | C6: Failed | F6: Untested | L6: N/A/B | O6: Total Test Cases
A7: =COUNTIF(F40:T40,"P") -> 10 | C7: =COUNTIF(F40:T40,"F") -> 1 | F7: =SUM(O7,-A7,-C7) -> 0 | L7: =COUNTIF(F39:T39,"N") -> 2 | M7: =COUNTIF(F39:T39,"A") -> 9 | N7: =COUNTIF(F39:T39,"B") -> 0 | O7: =COUNTA(F40:T40) -> 11
F9: UTCID01 | G9: UTCID02 | H9: UTCID03 | I9: UTCID04 | J9: UTCID05 | K9: UTCID06 | L9: UTCID07 | M9: UTCID08 | N9: UTCID09 | O9: UTCID10 | P9: UTCID11 | Q9: UTCID12 | R9: UTCID13 | S9: UTCID14 | T9: UTCID15
A10: Condition | B10: Precondition
D11: Contract exists with ContractVerification and schedule as needed per case | F11: O | G11: O | H11: O | I11: O | J11: O | K11: O | L11: O | M11: O | N11: O | O11: O | P11: O
B12: Action / contract state | D12: StartContractSigningAsync: Draft contract, current user=lessor-1, matching participants | F12: O
D13: StartContractSigningAsync: contract not found | G13: O
D14: StartContractSigningAsync: current user=lessee-1 (not the Lessor) | H14: O
D15: StartContractSigningAsync: request LesseeId does not match contract.LesseeId | I15: O
D16: StartContractSigningAsync: contract Status=Active (not Draft) | J16: O
D17: StartContractSigningAsync: repository GetAsync throws InvalidOperationException("Start signing failure") | K17: O
D18: CancelContractSigningAsync: Signing contract with PreSignSnapshot/Hash, lessor already agreed | L18: O
D19: CancelContractSigningAsync: contract not found | M19: O
D20: CancelContractSigningAsync: current user=lessee-1 (not the Lessor) | N20: O
D21: CancelContractSigningAsync: contract Status=Draft (not Signing) | O21: O
D22: CancelContractSigningAsync: repository GetAsync throws InvalidOperationException("Cancel signing failure") | P22: O
A31: Confirm | B31: Return | D31: IsSuccess=true, Status=Signing, PreSignSnapshot set (excludes ContractVerification/CreatedAt/UpdatedAt), PreSignHash length=64, UpdateAsync+SaveChangesAsync once | F31: O
D32: IsSuccess=false, IsNotFound=true | G32: O | M32: O
D33: IsSuccess=false (permission/state mismatch) | H33: O | I33: O | J33: O | N33: O | O33: O
D34: IsSuccess=false, Message="Start signing failure" | K34: O
D35: IsSuccess=true, Status=Draft, PreSignSnapshot/Hash cleared, ContractVerification.IsLessorAgreed=false, LessorSignedAt=null, UpdateAsync+SaveChangesAsync once | L35: O
D36: IsSuccess=false, Message="Cancel signing failure" | P36: O
A39: Result | B39: Type(N : Normal, A : Abnormal, B : Boundary) | F39: N | G39: A | H39: A | I39: A | J39: A | K39: A | L39: N | M39: A | N39: A | O39: A | P39: A
B40: Passed/Failed | F40: P | G40: P | H40: P | I40: P | J40: F | K40: P | L40: P | M40: P | N40: P | O40: P | P40: P
B41: Executed Date | F41: 46260 | G41: 46260 | H41: 46260 | I41: 46260 | J41: 46260 | K41: 46260 | L41: 46260 | M41: 46260 | N41: 46260 | O41: 46260 | P41: 46260
B42: Defect ID

Sheet Contract-Signing-2
A2: Function Code | C2: =Functions!E26 -> FUNC-CONTRACT-002 | F2: Function Name | L2: =Functions!D26 -> StartContractSigningAsync / CancelContractSigningAsync / ContractValidateOtpAsync
A3: Created By | C3: <Developer Name> | F3: Executed By
A4: Lines of code | C4: 151 | F4: Lack of test cases | L4: =IF(Functions!E6<>"N/A",SUM(C4*Functions!E6/1000,-O7),"N/A") -> -2.96
A5: Test requirement | C5: Verify contract signing workflow — part 2: full cancel, integrity verification, OTP validation, OTP dispatch.
A6: Passed | C6: Failed | F6: Untested | L6: N/A/B | O6: Total Test Cases
A7: =COUNTIF(F40:T40,"P") -> 9 | C7: =COUNTIF(F40:T40,"F") -> 0 | F7: =SUM(O7,-A7,-C7) -> 0 | L7: =COUNTIF(F39:T39,"N") -> 4 | M7: =COUNTIF(F39:T39,"A") -> 3 | N7: =COUNTIF(F39:T39,"B") -> 2 | O7: =COUNTA(F40:T40) -> 9
F9: UTCID01 | G9: UTCID02 | H9: UTCID03 | I9: UTCID04 | J9: UTCID05 | K9: UTCID06 | L9: UTCID07 | M9: UTCID08 | N9: UTCID09 | O9: UTCID10 | P9: UTCID11 | Q9: UTCID12 | R9: UTCID13 | S9: UTCID14 | T9: UTCID15
A10: Condition | B10: Precondition
D11: Contract exists with signing/verification state as needed per case | F11: O | G11: O | H11: O | I11: O | J11: O | K11: O | L11: O | M11: O | N11: O
B12: Action / contract state | D12: CancelContractAsync: Draft contract, current user=lessor-1 (owner) | F12: O
D13: VerifyContractIntegrityAsync: current computed PostSignHash equals stored hash | G13: O
D14: VerifyContractIntegrityAsync: current computed PostSignHash differs from stored hash | H14: O
D15: ContractValidateOtpAsync: cached OTP "123456", entered "123456" but PreSignHash recomputed mismatches stored | I15: O
D16: ContractValidateOtpAsync: cached OTP "123456", entered "000000" (wrong OTP) | J16: O
D17: ContractValidateOtpAsync: current user=lessee-1 (last signer), correct OTP, PreSignHash matches, listing Available/EntireSpace | K17: O
D18: SendContractOtpAsync: contract Status=Draft (no active signing session) | L18: O
D19: SendContractOtpAsync: Signing contract, ContractVerification found (not yet agreed), user email found | M19: O
D20: SendContractOtpAsync: ContractVerification.IsLessorAgreed already true | N20: O
A31: Confirm | B31: Return | D31: IsSuccess=true, Status=Cancelled, UpdateAsync+SaveChangesAsync once | F31: O
D32: IsSuccess=true, Data.IsTampered=false, OldPostSignHash=NewPostSignHash, IsMatched=true | G32: O
D33: IsSuccess=true, Data.IsTampered=true, NewPostSignHash != OldPostSignHash, IsMatched=false | H33: O
D34: IsSuccess=false, Status reverted to Draft, PreSignSnapshot/Hash cleared, UpdateAsync+SaveChangesAsync once | I34: O
D35: IsSuccess=false, Message contains "không hợp lệ", or email never sent (guard condition) | J35: O | N35: O
D36: IsSuccess=true, Status=Active/IsActive=true, ContractSnapshot/PostSignHash set, IsLesseeAgreed=true, Listing→Occupied, SpaceUsageRight AddAsync once | K36: O
D37: IsSuccess=false, Message contains "phien ky", ProfileRepository/EmailService never called | L37: O
D38: IsSuccess=true, Data=true, OTP cached (6 chars), email sent once | M38: O
A39: Result | B39: Type(N : Normal, A : Abnormal, B : Boundary) | F39: N | G39: N | H39: B | I39: B | J39: A | K39: N | L39: A | M39: N | N39: A
B40: Passed/Failed | F40: P | G40: P | H40: P | I40: P | J40: P | K40: P | L40: P | M40: P | N40: P
B41: Executed Date | F41: 46260 | G41: 46260 | H41: 46260 | I41: 46260 | J41: 46260 | K41: 46260 | L41: 46260 | M41: 46260 | N41: 46260
