Workbook
Name ACTION: #REF!
Name ACTION: #REF!

Sheet Cover
B2: TEST REPORT DOCUMENT
A4: Project Name | B4: AI-powered Shared Business Space Platform with Time-based Subleasing (FlexiSpace) | E4: Creator | F4: Nguyen Viet Thanh
A5: Project Code | B5: SU26SE038 / GSU26SE45 | E5: Issue Date | F5: 13/8/2026
A6: Document Code | B6: =B5&"_"&"v0.2" -> SU26SE038 / GSU26SE45_v0.2 | E6: Version | F6: V.0.2
A9: Record of change
A10: Effective Date | B10: Version | C10: Change Item | D10: *A,D,M | E10: Change description | F10: Reference
A11: 13/8/2026 | B11: V.0.1 | C11: Add test case | D11: A | E11: Add Test case for 10 feature | F11: TEST CASE LIST
A12: 46121 | B12: V.0.2 | C12: Update infomation testing | D12: M | E12: Update infomation for test form

Sheet Test Cases
D1: TEST CASE LIST
B3: Project Name | D3: AI-powered Shared Business Space Platform with Time-based Subleasing (FlexiSpace)
B4: Project Code | D4: SU26SE038 / GSU26SE45
B5: Test Environment Setup Description | D5: 1. Web application built with React 19 + Vite, running against the Backend API (.NET 8) on a dedicated test/staging environment. 2. Backend database: PostgreSQL 16 (dedicated test instance) with Redis for OTP caching. 3. Web Browsers: Google Chrome (primary), Microsoft Edge (secondary), Firefox and Safari (public pages only). 4. Viewports tested: 1024px, 1440px, 2560px (per the defined responsive NFR — mobile viewports are out of scope for the Web app).
B8: No | C8: Function Name | D8: Sheet Name | E8: Description | F8: Pre-Condition
B9: 1 | C9: Function A - Register Form | D9: Authentication & Onboarding | E9: Verify user registration, OTP verification, login, password recovery, onboarding profile completion, and identity (CCCD) verification flows on the Web Frontend. | F9: See sheet 'Authentication & Onboardi' for detailed pre-conditions per test case.
B10: 2 | C10: Function B - OTP Verification | D10: Authentication & Onboarding | E10: Verify user registration, OTP verification, login, password recovery, onboarding profile completion, and identity (CCCD) verification flows on the Web Frontend. | F10: See sheet 'Authentication & Onboardi' for detailed pre-conditions per test case.
B11: 3 | C11: Function C - Login Form | D11: Authentication & Onboarding | E11: Verify user registration, OTP verification, login, password recovery, onboarding profile completion, and identity (CCCD) verification flows on the Web Frontend. | F11: See sheet 'Authentication & Onboardi' for detailed pre-conditions per test case.
B12: 4 | C12: Function D - Protected Route & Role Guard | D12: Authentication & Onboarding | E12: Verify user registration, OTP verification, login, password recovery, onboarding profile completion, and identity (CCCD) verification flows on the Web Frontend. | F12: See sheet 'Authentication & Onboardi' for detailed pre-conditions per test case.
B13: 5 | C13: Function E - Onboarding Profile Completion | D13: Authentication & Onboarding | E13: Verify user registration, OTP verification, login, password recovery, onboarding profile completion, and identity (CCCD) verification flows on the Web Frontend. | F13: See sheet 'Authentication & Onboardi' for detailed pre-conditions per test case.
B14: 6 | C14: Function F - Identity Verification (CCCD) | D14: Authentication & Onboarding | E14: Verify user registration, OTP verification, login, password recovery, onboarding profile completion, and identity (CCCD) verification flows on the Web Frontend. | F14: See sheet 'Authentication & Onboardi' for detailed pre-conditions per test case.
B15: 7 | C15: Function A - Space Form (Create/Edit) | D15: Space & Listing Management | E15: Verify Space creation/management, Listing creation for both EntireSpace and SharedSpace (subleasing) types, and listing moderation status handling on the Web Frontend. | F15: See sheet 'Space & Listing Managemen' for detailed pre-conditions per test case.
B16: 8 | C16: Function B - Owner Spaces List | D16: Space & Listing Management | E16: Verify Space creation/management, Listing creation for both EntireSpace and SharedSpace (subleasing) types, and listing moderation status handling on the Web Frontend. | F16: See sheet 'Space & Listing Managemen' for detailed pre-conditions per test case.
B17: 9 | C17: Function C - Listing Form (EntireSpace) | D17: Space & Listing Management | E17: Verify Space creation/management, Listing creation for both EntireSpace and SharedSpace (subleasing) types, and listing moderation status handling on the Web Frontend. | F17: See sheet 'Space & Listing Managemen' for detailed pre-conditions per test case.
B18: 10 | C18: Function D - Share Listing Form (SharedSpace / Subleasing) | D18: Space & Listing Management | E18: Verify Space creation/management, Listing creation for both EntireSpace and SharedSpace (subleasing) types, and listing moderation status handling on the Web Frontend. | F18: See sheet 'Space & Listing Managemen' for detailed pre-conditions per test case.
B19: 11 | C19: Function E - Owner Listings / Sublease Listings List | D19: Space & Listing Management | E19: Verify Space creation/management, Listing creation for both EntireSpace and SharedSpace (subleasing) types, and listing moderation status handling on the Web Frontend. | F19: See sheet 'Space & Listing Managemen' for detailed pre-conditions per test case.
B20: 12 | C20: Function F - Shared Space Management | D20: Search & Public Feed | E20: Verify Space creation/management, Listing creation for both EntireSpace and SharedSpace (subleasing) types, and listing moderation status handling on the Web Frontend. | F20: See sheet 'Space & Listing Managemen' for detailed pre-conditions per test case.
... B43: 35 | C43: Function D - Revenue Analytics Dashboard | D43: Admin Dashboard | E43: Verify administrative functions: listing moderation, user/wallet/category management, and revenue analytics. | F43: See sheet 'Admin Dashboard' for detailed pre-conditions per test case.

Sheet Test Statistics
B1: TEST STATISTICS
B3: Project Name | C3: AI-powered Shared Business Space Platform with Time-based Subleasing (FlexiSpace) | E3: Creator | G3: Nguyen Viet Thanh
B4: Project Code | C4: SU26SE038 / GSU26SE45 | E4: Reviewer/Approver
B5: Document Code | C5: =C4&"_"&"Test Report"&"_"&"v0.2" -> SU26SE038 / GSU26SE45_Test Report_v0.2 | E5: Issue Date | G5: 13/8/2026
B6: Notes
B10: No | C10: Module code | D10: Passed | E10: Failed | F10: Pending | G10: N/A | H10: Number of test cases
B11: 1 | C11: Authentication & Onboarding | D11: ='Authentication & Onboarding'!B6 -> 20 | E11: ='Authentication & Onboarding'!C6 -> 0 | F11: ='Authentication & Onboarding'!D6 -> 0 | G11: ='Authentication & Onboarding'!E6 -> 0 | H11: ='Authentication & Onboarding'!B4 -> 25
B12: 2 | C12: Space & Listing Management | D12: ='Space & Listing Management'!B6 -> 23 | E12: ='Space & Listing Management'!C6 -> 0 | F12: ='Space & Listing Management'!D6 -> 0 | G12: ='Space & Listing Management'!E6 -> 2 | H12: ='Space & Listing Management'!B4 -> 25
B13: 3 | C13: Search & Public Feed | D13: ='Search & Public Feed'!B6 -> 5 | E13: ='Search & Public Feed'!C6 -> 0 | F13: ='Search & Public Feed'!D6 -> 0 | G13: ='Search & Public Feed'!E6 -> 1 | H13: ='Search & Public Feed'!B4 -> 6
B14: 4 | C14: Booking & Real-time Chat | D14: ='Booking & Real-time Chat'!B6 -> 12 | E14: ='Booking & Real-time Chat'!C6 -> 0 | F14: ='Booking & Real-time Chat'!D6 -> 1 | G14: ='Booking & Real-time Chat'!E6 -> 0 | H14: ='Booking & Real-time Chat'!B4 -> 13
B15: 5 | C15: E-Contract & OTP Signing | D15: ='E-Contract & OTP Signing'!B6 -> 11 | E15: ='E-Contract & OTP Signing'!C6 -> 0 | F15: ='E-Contract & OTP Signing'!D6 -> 0 | G15: ='E-Contract & OTP Signing'!E6 -> 0 | H15: ='E-Contract & OTP Signing'!B4 -> 11
B16: 6 | C16: Time-based Scheduling & Sub-Booking | D16: ='Time-based Scheduling & Sub-Boo'!B6 -> 6 | E16: ='Time-based Scheduling & Sub-Boo'!C6 -> 3 | F16: ='Time-based Scheduling & Sub-Boo'!D6 -> 0 | G16: ='Time-based Scheduling & Sub-Boo'!E6 -> 0 | H16: ='Time-based Scheduling & Sub-Boo'!B4 -> 9
B17: 7 | C17: Tenant & Contract Management Da | D17: ='Tenant & Contract Management '!B6 -> 2 | E17: ='Tenant & Contract Management '!C6 -> 1 | F17: ='Tenant & Contract Management '!D6 -> 0 | G17: ='Tenant & Contract Management '!E6 -> 0 | H17: ='Tenant & Contract Management '!B4 -> 3
B18: 8 | C18: Wallet & Payment | D18: ='Wallet & Payment'!B6 -> 7 | E18: ='Wallet & Payment'!C6 -> 1 | F18: ='Wallet & Payment'!D6 -> 0 | G18: ='Wallet & Payment'!E6 -> 0 | H18: ='Wallet & Payment'!B4 -> 8
B19: 9 | C19: AI Image Editor | D19: ='AI Image Editor'!B6 -> 4 | E19: ='AI Image Editor'!C6 -> 1 | F19: ='AI Image Editor'!D6 -> 0 | G19: ='AI Image Editor'!E6 -> 0 | H19: ='AI Image Editor'!B4 -> 5
B20: 10 | C20: Admin Dashboard | D20: ='Admin Dashboard'!B6 -> 9 | E20: ='Admin Dashboard'!C6 -> 1 | F20: ='Admin Dashboard'!D6 -> 0 | G20: ='Admin Dashboard'!E6 -> 0 | H20: ='Admin Dashboard'!B4 -> 10
C21: Sub total | D21: =SUM(D9:D20) -> 99 | E21: =SUM(E9:E20) -> 7 | F21: =SUM(F9:F20) -> 1 | G21: =SUM(G9:G20) -> 3 | H21: =SUM(H9:H20) -> 115
C23: Test coverage | E23: =(D21+E21)*100/(H21-G21) -> 94.642857 | F23: %
C24: Test successful coverage | E24: =D21*100/(H21-G21) -> 88.392857 | F24: %

Sheet Authentication & Onboarding
A2: Feature | B2: Authentication & Onboarding | R2: Passed
A3: Test requirement | B3: 13/8/2026 | R3: Failed
A4: Number of TCs | B4: =COUNTA(A12:A1014) -> 25 | R4: Pending
A5: Testing Round | B5: Passed | C5: Failed | D5: Pending | E5: N/A | R5: N/A
A6: Round 1 | B6: =COUNTIF($F10:$F1012,B5) -> 20 | C6: =COUNTIF($F10:$F1012,C5) -> 0 | D6: =COUNTIF($F10:$F1012,D5) -> 0 | E6: =COUNTIF($F10:$F1012,E5) -> 0
A7: Round 2 | B7: =COUNTIF($F10:$F1012,B5) -> 20 | C7: =COUNTIF($F10:$F1012,C5) -> 0 | D7: =COUNTIF($F10:$F1012,D5) -> 0 | E7: =COUNTIF($F10:$F1012,E5) -> 0
A8: Round 3 | B8: =COUNTIF($F10:$F1012,B5) -> 20 | C8: =COUNTIF($F10:$F1012,C5) -> 0 | D8: =COUNTIF($F10:$F1012,D5) -> 0 | E8: =COUNTIF($F10:$F1012,E5) -> 0
A10: Test Case ID | B10: Test Case Description | C10: Test Case Procedure | D10: Expected Results | E10: Pre-conditions | F10: Round 1 | G10: Test date | H10: Tester | I10: Round 2 | J10: Test date | K10: Tester | L10: Round 3 | M10: Test date | N10: Tester | O10: Note
A11: Function A
A12: F1-01 | B12: Verify registration form rejects submission when required fields are empty. | C12: 1. Navigate to the Register page. 2. Leave Email, Password, Full Name, Phone Number blank. 3. Click the "Register" button. | D12: Form is not submitted. Inline validation error messages are displayed under each required field. No API call is triggered. | E12: User is not logged in. Register page is loaded. | F12: Passed | G12: 13/8/2026 | H12: Nguyễn Việt Thành | I12: N/A | L12: N/A
A13: F1-02 | B13: Verify registration form rejects an invalid email format. | C13: 1. Navigate to the Register page. 2. Enter "abc123" in the Email field. 3. Fill in other required fields with valid values. 4. Click "Register". | D13: Form displays an inline error such as "Invalid email address" under the Email field. No API call is triggered. | E13: User is not logged in. Register page is loaded. | F13: Passed | G13: 13/8/2026 | H13: Nguyễn Việt Thành | I13: N/A | L13: N/A
A14: F1-03 | B14: Verify registration form rejects a password below the minimum length. | C14: 1. Navigate to the Register page. 2. Enter a password shorter than the configured minimum (e.g. "123"). 3. Fill in other required fields with valid values. 4. Click "Register". | D14: Form displays an inline error indicating the minimum password length requirement. No API call is triggered. | E14: User is not logged in. Register page is loaded. | F14: Passed | G14: 13/8/2026 | H14: Nguyễn Việt Thành
A15: F1-04 | B15: Verify successful registration with valid data triggers the Cloudflare Turnstile check and calls POST /api/Auth/register. | C15: 1. Navigate to the Register page. 2. Fill in Email, Password, Date of Birth, Phone Number, Full Name with valid values. 3. Complete the Turnstile widget. 4. Click "Register". | D15: A request is sent to POST /api/Auth/register with the correct payload shape (email, password, dob, phoneNumber, name, turnstileToken). On success, the user is redirected to the OTP verification step and a success message is displayed. | E15: User is not logged in. Register page is loaded. Turnstile widget has loaded successfully. | F15: Passed | G15: 13/8/2026 | H15: Nguyễn Việt Thành | I15: N/A | L15: N/A
A16: F1-05 | B16: Verify registration fails gracefully when the backend returns a duplicate-email error. | C16: 1. Register with an email address that already exists in the system. 2. Click "Register". | D16: A clear, human-readable error message is displayed to the user (e.g. "This email is already registered"). The form remains editable and no partial state is left behind. | E16: An account with the same email already exists in the system. | F16: Passed | G16: 13/8/2026 | H16: Nguyễn Việt Thành
A17: Function B
A18: F1-06 | B18: Verify the OTP input accepts only the expected numeric code length. | C18: 1. Complete registration to reach the OTP verification screen. 2. Attempt to enter fewer digits than required. 3. Attempt to enter non-numeric characters. | D18: The "Verify" button remains disabled until a code of the expected length is entered. Non-numeric characters are rejected or ignored. | E18: User has just completed registration and is on the OTP verification screen. | F18: Passed | G18: 13/8/2026 | H18: Nguyễn Việt Thành | I18: N/A | L18: N/A
A19: F1-07 | B19: Verify entering an incorrect OTP code displays an error and does not activate the account. | C19: 1. On the OTP verification screen, enter an incorrect 6-digit code. 2. Click "Verify". | D19: POST /api/Auth/verify-otp is called and returns an error. An error message is displayed (e.g. MSG-1002-equivalent). The user remains on the OTP screen and is not redirected. | E19: User is on the OTP verification screen with a valid pending registration. | F19: Passed | G19: 13/8/2026 | H19: Nguyễn Việt Thành
A20: F1-08 | B20: Verify entering the correct OTP code activates the account and redirects the user. | C20: 1. On the OTP verification screen, enter the correct OTP code received via email. 2. Click "Verify". | D20: POST /api/Auth/verify-otp succeeds. A success message is displayed and the user is redirected to the Login page or directly logged in, per the defined flow. | E20: User is on the OTP verification screen with a valid pending registration and knows the correct OTP code. | F20: Passed | G20: 13/8/2026 | H20: Nguyễn Việt Thành | I20: N/A | L20: N/A
A21: Function C
A22: F1-09 | B22: Verify login form rejects submission with empty Email or Password. | C22: 1. Navigate to the Login page. 2. Leave Email and/or Password blank. 3. Click "Login". | D22: Form is not submitted. Inline validation errors are shown. No API call is triggered. | E22: User is not logged in. Login page is loaded. | F22: Passed | G22: 13/8/2026 | H22: Nguyễn Việt Thành | I22: N/A | L22: N/A
A23: F1-10 | B23: Verify login fails with a wrong email/password combination. | C23: 1. Navigate to the Login page. 2. Enter a registered email with an incorrect password. 3. Complete the Turnstile widget. 4. Click "Login". | D23: POST /api/Auth/login returns an error. The UI displays "Invalid email address or password provided" (or localized equivalent). The user remains on the Login page. | E23: An account with the given email already exists in the system. | F23: Passed | G23: 13/8/2026 | H23: Nguyễn Việt Thành | I23: N/A | L23: N/A
A24: F1-11 | B24: Verify successful login stores the JWT token and redirects according to user role. | C24: 1. Navigate to the Login page. 2. Enter valid credentials for an Owner account. 3. Complete the Turnstile widget. 4. Click "Login". | D24: POST /api/Auth/login succeeds. The JWT token is stored under the "portal_token" key in localStorage. The user is redirected to the correct role-based dashboard route. | E24: A valid, verified account exists with a known role. | F24: Passed | G24: 13/8/2026 | H24: Nguyễn Việt Thành | I24: N/A | L24: N/A
A25: F1-12 | B25: Verify session persistence: reloading the page after login keeps the user authenticated. | C25: 1. Log in successfully. 2. Refresh the browser page (F5). | D25: The user remains logged in; the dashboard is displayed without redirecting back to the Login page, because the token is read from localStorage on app load. | E25: User has an active, valid session. | F25: Passed | G25: 13/8/2026 | H25: Nguyễn Việt Thành | I25: N/A | L25: N/A
A26: Function D
A27: F1-13 | B27: Verify an unauthenticated user is redirected away from a protected route. | C27: 1. Ensure no token is present in localStorage (logged out state). 2. Directly navigate to a protected dashboard URL (deep link). | D27: The user is redirected to the Home route (ROUTES.HOME) via <Navigate replace />, and the protected content is never rendered. | E27: User is logged out; localStorage does not contain a valid "portal_token". | F27: Passed | G27: 13/8/2026 | H27: Nguyễn Việt Thành | I27: N/A | L27: N/A
A28: F1-14 | B28: Verify a logged-in user with the wrong role cannot access a route reserved for another role. | C28: 1. Log in as a Renter. 2. Directly navigate to an Admin-only or Owner-only dashboard route. | D28: The user is redirected to the Home route. The restricted page content and its data are never rendered or fetched. | E28: User is logged in with a role that does not match the target route's required role. | F28: Passed | G28: 13/8/2026 | H28: Nguyễn Việt Thành | I28: N/A | L28: N/A
A29: F1-15 | B29: Verify a logged-in user with the correct role can access the corresponding protected route. | C29: 1. Log in with the role required by the target route (e.g. Owner). 2. Navigate to the corresponding dashboard route. | D29: The page renders normally with the expected content for that role. | E29: User is logged in with the correct role for the target route. | F29: Passed | G29: 13/8/2026 | H29: Nguyễn Việt Thành | I29: N/A | L29: N/A
A30: Function E
A31: F1-16 | B31: Verify a newly registered user is prompted to complete their profile before accessing the dashboard. | C31: 1. Complete registration and OTP verification for a brand-new account. 2. Observe the next screen shown. | D31: The user is routed to the onboarding profile-completion screen rather than directly to the dashboard. | E31: Account has just been created and verified, with no profile data yet. | F31: Passed | G31: 13/8/2026 | H31: Nguyễn Việt Thành | I31: N/A | L31: N/A
A32: F1-17 | B32: Verify onboarding form validates required profile fields before allowing submission. | C32: 1. On the onboarding screen, leave required fields blank. 2. Attempt to submit. | D32: Submission is blocked and inline validation errors are shown for missing required fields. | E32: User is on the onboarding profile-completion screen. | F32: Passed | G32: 13/8/2026 | H32: Nguyễn Việt Thành | I32: N/A | L32: N/A
A33: Function F
A34: F1-18 | B34: Verify the identity verification screen accepts an uploaded CCCD image file. | C34: 1. Navigate to the Identity Verification screen. 2. Upload a valid CCCD image file (JPEG/PNG) via the upload control. | D34: The image preview is displayed and the "Submit"/"Verify" action becomes enabled. | E34: User is logged in and has not yet completed identity verification. | F34: Passed | G34: 13/8/2026 | H34: Nguyễn Việt Thành
A35: F1-19 | B35: Verify the QR code scan path correctly auto-fills parsed CCCD data fields. | C35: 1. Navigate to the Identity Verification screen. 2. Use the webcam/QR scan option to scan a CCCD QR code. | D35: Fields such as ID number and full name are automatically parsed and populated from the scanned QR payload for user confirmation. | E35: User is logged in, camera permission is granted, and a valid CCCD QR code is available for scanning. | F35: Passed | G35: 13/8/2026 | H35: Nguyễn Việt Thành
A36: F1-20 | B36: Verify submitting identity verification calls the correct backend endpoint and reflects the pending status. | C36: 1. Complete the CCCD upload/scan step. 2. Click "Submit for verification". | D36: A request is sent to the profile verification endpoint (POST /Profile/{userProfileId}/verify). The UI shows a "Pending verification" status afterward. | E36: CCCD image/data has been captured and is ready to submit. | F36: Passed | G36: 13/8/2026 | H36: Nguyễn Việt Thành | I36: N/A | L36: N/A

Sheet Space & Listing Management
A2: Feature | B2: Space & Listing Management | R2: Passed
A3: Test requirement | B3: The Space & Listing Management sheet covers the end-to-end management of physical premises and their rental offerings. | R3: Failed
A4: Number of TCs | B4: 25 | R4: Pending
A5: Testing Round | B5: Passed | C5: Failed | D5: Pending | E5: N/A | R5: N/A
A6: Round 1 | B6: =COUNTIF($F10:$F1011,B5) -> 23 | C6: =COUNTIF($F10:$F1011,C5) -> 0 | D6: =COUNTIF($F10:$F1011,D5) -> 0 | E6: =COUNTIF($F10:$F1011,E5) -> 2
A7: Round 2 | B7: =COUNTIF($F10:$F1011,B5) -> 23 | C7: =COUNTIF($F10:$F1011,C5) -> 0 | D7: =COUNTIF($F10:$F1011,D5) -> 0 | E7: =COUNTIF($F10:$F1011,E5) -> 2
A8: Round 3 | B8: =COUNTIF($F10:$F1011,B5) -> 23 | C8: =COUNTIF($F10:$F1011,C5) -> 0 | D8: =COUNTIF($F10:$F1011,D5) -> 0 | E8: =COUNTIF($F10:$F1011,E5) -> 2
A10: Test Case ID | B10: Test Case Description | C10: Test Case Procedure | D10: Expected Results | E10: Pre-conditions | F10: Round 1 | G10: Test date | H10: Tester | I10: Round 2 | J10: Test date | K10: Tester | L10: Round 3 | M10: Test date | N10: Tester | O10: Note
A11: Function A - Space Form (Create/Edit)
A12: F2-01 | B12: Verify Space Form rejects submission when Name, Address, or Area is empty. | C12: 1. Navigate to "Add Space". 2. Leave the Space Name field blank. 3. Click "Save"/"Submit". | D12: Form is not submitted (the field is marked required in the DOM). An inline error is shown, and no API call is made. | E12: User is logged in as Space Owner and is on the Space creation form. | F12: Passed | G12: 13/8/2026 | H12: Nguyễn Việt Thành | I12: N/A | L12: N/A
A13: F2-02 | B13: Verify the Province/District/Ward cascading dropdown loads correctly. | C13: 1. Open the Space Form. 2. Select a Province from the dropdown. 3. Observe the District dropdown. 4. Select a District. 5. Observe the Ward dropdown. | D13: Selecting a Province populates the District dropdown with districts belonging to that province (via GET /api/Space/GetAddress); selecting a District populates the Ward dropdown accordingly. Previously selected lower-level values are reset when a higher-level value changes. | E13: User is on the Space creation form; province/address reference data is available from the API. | F13: Passed | G13: 13/8/2026 | H13: Nguyễn Việt Thành | I13: N/A | L13: N/A
A14: F2-03 | B14: Verify the Area field only accepts numeric input. | C14: 1. In the Area field, type non-numeric characters (e.g. "abc"). | D14: Non-numeric characters are stripped or rejected; the field only retains digit characters, matching the field's numeric-sanitizing behavior. | E14: User is on the Space creation form. | F14: Passed | G14: 13/8/2026 | H14: Nguyễn Việt Thành | I14: N/A | L14: N/A
A15: F2-04 | B15: Verify selecting Amenity checkboxes updates the selected-amenities list correctly. | C15: 1. On the Space Form, check two predefined amenities (e.g. Wifi, Air Conditioning). 2. Uncheck one of them. | D15: The selected amenities state reflects exactly the currently checked items after each toggle. | E15: User is on the Space creation form; amenity options are loaded. | F15: Passed | G15: 13/8/2026 | H15: Nguyễn Việt Thành | I15: N/A | L15: N/A
A16: F2-05 | B16: Verify entering a custom amenity via the "Other" text field is included in the submitted payload. | C16: 1. Check the custom-amenity checkbox. 2. Enter a free-text value, e.g. "Rooftop Garden", in the custom amenity field. 3. Submit the form. | D16: The custom amenity text is included in the amenities array sent in the CreateSpaceRQ payload. | E16: User is on the Space creation form. | F16: Passed | G16: 13/8/2026 | H16: Nguyễn Việt Thành | I16: N/A | L16: N/A
A17: F2-06 | B17: Verify Operating Hours can be configured per day of week and are included in the submission payload. | C17: 1. On the Space Form, set Open Time and Close Time for at least one day of the week. 2. Submit the form. | D17: The submitted payload's operatingHours array contains an entry with the correct dayOfWeek (numeric, 0=Sunday…6=Saturday), openTime, and closeTime in HH:mm:ss format. | E17: User is on the Space creation form. | F17: Passed | G17: 13/8/2026 | H17: Nguyễn Việt Thành | I17: N/A | L17: N/A
A18: F2-07 | B18: Verify successful Space creation calls POST /api/Space/Create and redirects to the Owner Spaces list. | C18: 1. Fill in all required fields with valid data. 2. Submit the form. | D18: POST /api/Space/Create is called with a payload matching CreateSpaceRQ. On success, the user is redirected to the "My Spaces" list and the new space appears in it. | E18: User is logged in as Space Owner. All required fields are valid. | F18: Passed | G18: 13/8/2026 | H18: Nguyễn Việt Thành | I18: N/A | L18: N/A
A19: F2-08 | B19: Verify editing an existing Space pre-fills the form with the current data. | C19: 1. From the Owner Spaces list, click "Edit" on an existing space. | D19: The form loads pre-populated with the space's current name, address, area, amenities, and operating hours. | E19: At least one Space already exists for the logged-in Owner. | F19: Passed | G19: 13/8/2026 | H19: Nguyễn Việt Thành | I19: N/A | L19: N/A
A20: Function B - Owner Spaces List
A21: F2-09 | B21: Verify the Owner Spaces list displays all spaces belonging to the logged-in Owner. | C21: 1. Log in as an Owner with existing spaces. 2. Navigate to "My Spaces". | D21: GET /api/Space/GetAll is called filtered by OwnerId, and all matching spaces are rendered in the list/grid. | E21: Logged-in Owner has at least one existing Space. | F21: Passed | G21: 13/8/2026 | H21: Nguyễn Việt Thành | I21: N/A | L21: N/A
A22: F2-10 | B22: Verify the empty state is displayed when the Owner has no spaces yet. | C22: 1. Log in as an Owner with zero spaces. 2. Navigate to "My Spaces". | D22: An empty-state message/illustration is shown instead of an empty table, with a call-to-action to create the first space. | E22: Logged-in Owner currently has zero spaces. | F22: Passed | G22: 13/8/2026 | H22: Nguyễn Việt Thành | I22: N/A | L22: N/A
A23: F2-11 | B23: Verify deleting a Space asks for confirmation before calling the delete endpoint. | C23: 1. On the Owner Spaces list, click "Delete" on a space. | D23: A confirmation dialog appears before DELETE /api/Space/Delete{id} is called; canceling the dialog does not delete the space. | E23: At least one Space exists in the Owner's list. | F23: Passed | G23: 13/8/2026 | H23: Nguyễn Việt Thành | I23: N/A | L23: N/A
A24: Function C - Listing Form (EntireSpace)
A25: F2-12 | B25: Verify the Listing Form requires an associated Space to be selected before submission. | C25: 1. Open "Create Listing". 2. Leave the Space selector empty. 3. Attempt to submit. | D25: Form blocks submission and shows a validation error indicating a Space must be selected. | E25: User is logged in as Space Owner and is on the Space creation form. | F25: Passed | G25: 13/8/2026 | H25: Nguyễn Việt Thành | I25: N/A | L25: N/A
A26: F2-13 | B26: Verify Allowed Start Time must be earlier than Allowed End Time. | C26: 1. On the Listing Form, set Allowed Start Time to a date/time later than Allowed End Time. 2. Attempt to submit. | D26: Form displays a validation error and blocks submission until the date range is valid. | E26: User is on the Listing creation form. | F26: Passed | G26: 13/8/2026 | H26: Nguyễn Việt Thành | I26: N/A | L26: N/A
A27: F2-14 | B27: Verify the Price field rejects negative or zero values. | C27: 1. Enter "-100" or "0" in the Price field. 2. Attempt to submit. | D27: Form displays a validation error requiring a positive price value. | E27: User is on the Listing creation form. | F27: Passed | G27: 13/8/2026 | H27: Nguyễn Việt Thành | I27: N/A | L27: N/A
A28: F2-15 | B28: Verify successful submission calls POST /api/Listing/Create with the correct ListingRequest shape and the new listing shows status Pending. | C28: 1. Fill in Space, Allowed Start/End Time, Description, Price, and upload at least one listing picture. 2. Submit the form. | D28: POST /api/Listing/Create is called with a payload matching ListingRequest (spaceId, allowedStartTime, allowedEndTime, description, price, listingPictures). The new listing appears in "My Listings" with status "Pending". | E28: User is on the Space creation form; province/address reference data is available from the API. | F28: N/A | G28: 13/8/2026 | H28: Nguyễn Việt Thành | I28: N/A | L28: N/A
A29: Function D - Share Listing Form (SharedSpace / Subleasing)
A30: F2-16 | B30: Verify Max Sub-Renter field only accepts a positive integer. | C30: 1. On the Share Listing Form, enter "0" or a negative number in the Max Sub-Renter field. 2. Attempt to submit. | D30: Form displays a validation error requiring a positive integer for the maximum number of sub-renters. | E30: User is a Primary Renter with an active lease eligible for subleasing. | F30: Passed | G30: 13/8/2026 | H30: Nguyễn Việt Thành | I30: N/A | L30: N/A
A31: F2-17 | B31: Verify Amenity inclusion toggles correctly compute price fields (isIncluded vs. surcharge price). | C31: 1. On the Share Listing Form, mark one amenity as "Included" and leave its price at 0. 2. Mark a second amenity as "Not included" and enter a surcharge price. 3. Submit the form. | D31: The submitted shareSpaceDetailShareSpaceAmenities array reflects isIncluded=true with price=0 for the first amenity, and isIncluded=false with the entered surcharge price for the second. | E31: User is on the Share Listing Form; amenity list is loaded. | F31: Passed | G31: 13/8/2026 | H31: Nguyễn Việt Thành | I31: N/A | L31: N/A
A32: F2-18 | B32: Verify Availability Time entries support either recurring days-of-week or a specific date, not requiring both simultaneously. | C32: 1. Add an availability entry using "Days of Week" (e.g. Monday, Wednesday) with a Start/End Time. 2. Add a second availability entry using a "Specific Date" instead. 3. Submit the form. | D32: The submitted shareSpaceDetailAvailabilitiesTimes array contains one entry with populated daysOfWeek and null specificDate, and another entry with a populated specificDate and null/empty daysOfWeek. | E32: User is on the Share Listing Form. | F32: Passed | G32: 13/8/2035 | H32: Nguyễn Việt Thành | I32: N/A | L32: N/A
A33: F2-19 | B33: Verify Availability Time's Valid From date cannot be later than Valid To date. | C33: 1. Set Valid From to a date after Valid To for an availability entry. 2. Attempt to submit. | D33: Form blocks submission and displays a validation error for the invalid date range. | E33: User is on the Share Listing Form. | F33: Passed | G33: 13/8/2026 | H33: Nguyễn Việt Thành | I33: N/A | L33: N/A
A34: F2-20 | B34: Verify Business Category selection for the shared listing is included in the submitted payload. | C34: 1. Select one or more allowed business categories for the shared listing. 2. Optionally add a note. 3. Submit the form. | D34: The submitted shareSpaceDetailShareSpaceCategories array contains the selected bussinessCategoryId values (note the intentional "bussiness" spelling used across the API) with the corresponding note text. | E34: User is on the Share Listing Form; business category list is loaded. | F34: Passed | G34: 13/8/2026 | H34: Nguyễn Việt Thành | I34: N/A | L34: N/A
A35: F2-21 | B35: Verify successful submission calls POST /api/Listing/CreateShareListing with the full nested payload. | C35: 1. Complete all required sections of the Share Listing Form (basic info, amenities, availability, categories). 2. Submit. | D35: POST /api/Listing/CreateShareListing is called with a payload matching SharedListingRequest. On success, the listing appears in the Sublease Listings list with a Pending status. | E35: User is a Primary Renter with an active lease eligible for subleasing. | F35: Passed | G35: 13/8/2026 | H35: Nguyễn Việt Thành | I35: N/A | L35: N/A
A36: Function E - Owner Listings / Sublease Listings List
A37: F2-22 | B37: Verify listing status badges correctly reflect Pending, Accepted, and Canceled states. | C37: 1. Navigate to "My Listings" where listings of multiple statuses exist. | D37: Each listing row/card displays a status badge matching its actual status field (Pending / Accepted / Canceled), styled distinctly. | E37: At least one listing of each status exists for the logged-in user. | F37: Passed | G37: 13/8/2026 | H37: Nguyễn Việt Thành | I37: N/A | L37: N/A
A38: F2-23 | B38: Verify filtering the listings list by status returns only matching listings. | C38: 1. On "My Listings", apply the status filter for "Accepted". | D38: GET /api/Listing/GetAll is called with status=Accepted, and only Accepted listings are displayed. | E38: Listings of multiple statuses exist for the logged-in user. | F38: Passed | G38: 13/8/2026 | H38: Nguyễn Việt Thành | I38: N/A | L38: N/A
A39: F2-24 | B39: Verify a Canceled listing displays its cancellation reason to the owner. | C39: 1. Locate a Canceled listing in "My Listings". 2. Open its detail view. | D39: The cancelReason text returned by the API is displayed to the user. | E39: At least one listing with status Canceled and a populated cancelReason exists. | F39: Passed | G39: 13/8/2026 | H39: Nguyễn Việt Thành | I39: N/A | L39: N/A
A40: Function F - Shared Space Management
A41: F2-25 | B41: Verify the list of spaces available for subleasing is populated from a real API call. | C41: 1. Log in as a Primary Renter with an active lease. 2. Navigate to Shared Space Management. | D41: The screen displays the Primary Renter's currently active leased space(s) fetched from the backend, not an empty hardcoded list. | E41: Logged-in user has an active PrimaryBookingRequest with status Approved for at least one space. | F41: N/A | G41: 13/8/2026 | H41: Nguyễn Việt Thành | I41: N/A | L41: N/A

Sheet Search & Public Feed
A2: Feature | B2: Search & Public Feed | R2: Passed
A3: Test requirement | B3: The brief description of the requirements tested in the Search & Public Feed module | R3: Failed
A4: Number of TCs | B4: 6 | R4: Pending
A5: Testing Round | B5: Passed | C5: Failed | D5: Pending | E5: N/A | R5: N/A
A6: Round 1 | B6: =COUNTIF($F10:$F997,B5) -> 5 | C6: =COUNTIF($F10:$F997,C5) -> 0 | D6: =COUNTIF($F10:$F997,D5) -> 0 | E6: =COUNTIF($F10:$F997,E5) -> 1
A7: Round 2 | B7: =COUNTIF($F10:$F997,B5) -> 5 | C7: =COUNTIF($F10:$F997,C5) -> 0 | D7: =COUNTIF($F10:$F997,D5) -> 0 | E7: =COUNTIF($F10:$F997,E5) -> 1
A8: Round 3 | B8: =COUNTIF($F10:$F997,B5) -> 5 | C8: =COUNTIF($F10:$F997,C5) -> 0 | D8: =COUNTIF($F10:$F997,D5) -> 0 | E8: =COUNTIF($F10:$F997,E5) -> 1
A10: Test Case ID | B10: Test Case Description | C10: Test Case Procedure | D10: Expected Results | E10: Pre-conditions | F10: Round 1 | G10: Test date | H10: Tester | I10: Round 2 | J10: Test date | K10: Tester | L10: Round 3 | M10: Test date | N10: Tester | O10: Note
A11: Function A - Listing Feed Search & Filter
A12: F3-01 | B12: Verify filtering by location returns only listings matching that location. | C12: 1. Navigate to the public feed/homepage search page. | D12: GET /api/Listing/GetAll?status=Accepted (or equivalent) is called, and only Accepted listings are rendered. | E12: At least one Accepted listing exists in the system. | F12: Passed | G12: 13/8/2026 | H12: Nguyễn Việt Thành | I12: N/A | L12: N/A
A13: F3-02 | B13: Verify filtering by location returns only listings matching that location. | C13: 1. On the feed page, enter or select a location/city filter. 2. Apply the filter. | D13: The result list updates to show only listings whose space matches the selected location. | E13: Listings exist across at least two different locations. | F13: Passed | G13: 13/8/2026 | H13: Nguyễn Việt Thành | I13: N/A | L13: N/A
A14: F3-03 | B14: Verify filtering by price range excludes listings outside the range. | C14: 1. Set a minimum and maximum price filter. 2. Apply the filter. | D14: Only listings with a price within the specified range are displayed. | E14: Listings with varying prices exist in the system. | F14: Passed | G14: 13/8/2026 | H14: Nguyễn Việt Thành | I14: N/A | L14: N/A
A15: F3-04 | B15: Verify the empty-result state is shown when no listing matches the applied filters. | C15: 1. Apply a filter combination guaranteed to match zero listings. | D15: An empty-state message is displayed instead of a blank list or an error. | E15: The applied filter combination does not match any existing listing. | F15: Passed | G15: 13/8/2026 | H15: Nguyễn Việt Thành | I15: N/A | L15: N/A
A16: Function B - Listing Detail Page
A17: F3-05 | B17: Verify the listing detail page displays all key information returned by the API. | C17: 1. From the feed, click into a listing card. | D17: GET /api/Listing/GetById/{id} is called; the detail page renders title, description, price, address, images, and amenities matching the API response. | E17: At least one published (Accepted) listing exists. | F17: Passed | G17: 13/8/2026 | H17: Nguyễn Việt Thành | I17: N/A | L17: N/A
A18: F3-06 | B18: Verify navigating to a non-existent or removed listing ID shows a not-found state instead of crashing. | C18: 1. Manually navigate to a listing detail URL with an invalid/non-existent ID. | D18: A "listing not found" message is displayed. The page does not crash or show a blank white screen. | E18: The listing ID used does not exist in the system. | F18: N/A | G18: 13/8/2026 | H18: Nguyễn Việt Thành | I18: N/A | L18: N/A

Sheet Booking & Real-time Chat
A2: Feature | B2: Booking & Real-time Chat | R2: Passed
A3: Test requirement | B3: Booking & Real-time Chat module tests the reservation lifecycle and direct party-to-party negotiation. | R3: Failed
A4: Number of TCs | B4: 13 | R4: Pending
A5: Testing Round | B5: Passed | C5: Failed | D5: Pending | E5: N/A | R5: N/A
A6: Round 1 | B6: =COUNTIF($F10:$F999,B5) -> 12 | C6: =COUNTIF($F10:$F999,C5) -> 0 | D6: =COUNTIF($F10:$F999,D5) -> 1 | E6: =COUNTIF($F10:$F999,E5) -> 0
A7: Round 2 | B7: =COUNTIF($F10:$F999,B5) -> 12 | C7: =COUNTIF($F10:$F999,C5) -> 0 | D7: =COUNTIF($F10:$F999,D5) -> 1 | E7: =COUNTIF($F10:$F999,E5) -> 0
A8: Round 3 | B8: =COUNTIF($F10:$F999,B5) -> 12 | C8: =COUNTIF($F10:$F999,C5) -> 0 | D8: =COUNTIF($F10:$F999,D5) -> 1 | E8: =COUNTIF($F10:$F999,E5) -> 0
A10: Test Case ID | B10: Test Case Description | C10: Test Case Procedure | D10: Expected Results | E10: Pre-conditions | F10: Round 1 | G10: Test date | H10: Tester | I10: Round 2 | J10: Test date | K10: Tester | L10: Round 3 | M10: Test date | N10: Tester | O10: Note
A11: Function A - Create Booking Request
A12: F4-01 | B12: Verify the booking form rejects an Expected Start Date set in the past. | C12: 1. On the booking request form for a listing, set Expected Start Date to a past date. 2. Submit. | D12: Form displays a validation error and blocks submission (matching the backend rule rejecting past start dates). | E12: User is logged in as a Renter viewing an available listing. | F12: Passed | G12: 13/8/2026 | H12: Nguyễn Việt Thành | I12: Pending | L12: Pending
A13: F4-02 | B13: Verify Duration and Duration Unit fields are required and accept only supported unit values (Days/Weeks/Months/Years). | C13: 1. Leave the Duration field empty. 2. Attempt to submit. | D13: Form blocks submission with a validation message; the Duration Unit dropdown only offers Days, Weeks, Months, Years. | E13: User is on the booking request form. | F13: Passed | G13: 13/8/2026 | H13: Nguyễn Việt Thành
A14: F4-03 | B14: Verify an optional Offered Price can be submitted to propose a negotiated price. | C14: 1. Enter a value in the Offered Price field different from the listing price. 2. Submit the booking request. | D14: POST /api/PrimaryBookingRequest/Create is called including the offeredPrice field with the entered value. | E14: User is on the booking request form for an available listing. | F14: Passed | G14: 13/8/2026 | H14: Nguyễn Việt Thành | I14: Pending | L14: Pending
A15: F4-04 | B15: Verify successful submission creates a booking request with status Pending, visible to the Renter. | C15: 1. Fill in all required fields with valid data. 2. Submit. | D15: The new booking request appears in "My Booking Requests" with status "Pending". | E15: User is logged in as a Renter viewing an available listing. | F15: Passed | G15: 13/8/2026 | H15: Nguyễn Việt Thành | I15: Pending | L15: Pending
A16: Function B - Owner Booking Requests (Approve/Reject/Negotiate)
A17: F4-05 | B17: Verify the Owner can view all incoming booking requests filtered by status. | C17: 1. Log in as Owner. 2. Navigate to "Booking Requests". 3. Apply the "Pending" status filter. | D17: GET /api/PrimaryBookingRequest/GetAll?status=Pending returns and displays only Pending requests for the Owner's listings. | E17: At least one booking request of status Pending exists for the Owner's listing. | F17: Passed | G17: 13/8/2026 | H17: Nguyễn Việt Thành | I17: Pending | L17: Pending
A18: F4-06 | B18: Verify approving a booking request requires confirmation and updates its status. | C18: 1. On a Pending booking request, click "Approve". 2. Confirm the action in the dialog. | D18: PATCH /api/PrimaryBookingRequest/Status/{id} is called with status=Approved. The request's displayed status updates to "Approved". | E18: At least one booking request of status Pending exists. | F18: Passed | G18: 13/8/2026 | H18: Nguyễn Việt Thành
A19: F4-07 | B19: Verify rejecting a booking request requires a Cancel Reason before submission. | C19: 1. On a Pending booking request, click "Reject". 2. Leave the Cancel Reason field empty. 3. Attempt to confirm. | D19: The confirm action is blocked until a Cancel Reason is entered, matching the API's requirement for cancelReason on Rejected/Canceled status. | E19: At least one booking request of status Pending exists. | F19: Passed | G19: 13/8/2026 | H19: Nguyễn Việt Thành
A20: F4-08 | B20: Verify successfully rejecting a booking request updates its status and displays the reason to the Renter. | C20: 1. Reject a Pending booking request with a valid Cancel Reason. 2. Log in as the Renter who submitted it. 3. View the same booking request. | D20: The request status shows "Rejected" and the entered cancel reason is visible to the Renter. | E20: A booking request has just been rejected by the Owner with a cancel reason. | F20: Passed | G20: 13/8/2026 | H20: Nguyễn Việt Thành | I20: Pending | L20: Pending
A21: Function C - Renter Booking Requests List
A22: F4-09 | B22: Verify the Renter can see the real-time status of their submitted booking requests. | C22: 1. Log in as Renter. 2. Navigate to "My Booking Requests". | D22: All booking requests submitted by this Renter are listed with their current status (Pending/Negotiating/Approved/Rejected/Canceled). | E22: The logged-in Renter has submitted at least one booking request. | F22: Passed | G22: 13/8/2026 | H22: Nguyễn Việt Thành | I22: Pending | L22: Pending
A23: Function D - Real-time Chat (SignalR)
A24: F4-10 | B24: Verify opening a conversation with another user creates or retrieves the existing conversation. | C24: 1. From a listing or booking request, click "Message Owner"/"Message Renter". | D24: POST /api/Conversation/Create (or equivalent) is called with lessorId/lesseeId; an existing conversation is reused if one already exists between the two users, otherwise a new one is created. | E24: Two distinct user accounts exist (e.g. an Owner and a Renter) with a relevant listing/booking context. | F24: Passed | G24: 13/8/2026 | H24: Nguyễn Việt Thành | I24: Pending | L24: Pending
A25: F4-11 | B25: Verify sending a chat message delivers it in real time to the recipient without a page refresh. | C25: 1. Open the same conversation in two separate browser sessions (or two tabs, one per user). 2. Send a message from User A. 3. Observe User B's chat window. | D25: The message appears in User B's chat window in real time via the SignalR ChatHub connection, without requiring a manual page refresh. | E25: Both users have an active session and the conversation is already open in both windows. | F25: Passed | G25: 13/8/2026 | H25: Nguyễn Việt Thành | I25: Pending | L25: Pending
A26: F4-12 | B26: Verify chat message history loads correctly with pagination when scrolling up. | C26: 1. Open a conversation that has more messages than a single page. 2. Scroll to the top of the message list. | D26: GET /api/Message/GetMessageHistory is called with the timeBefore cursor of the oldest loaded message, and older messages are appended above the current list. | E26: The conversation contains more messages than the default page size. | F26: Passed | G26: 13/8/2026 | H26: Nguyễn Việt Thành | I26: Pending | L26: Pending
A27: F4-13 | B27: Verify the chat connection reconnects gracefully after a temporary network interruption. | C27: 1. Open a conversation. 2. Temporarily disable the network connection. 3. Re-enable the network connection. | D27: The SignalR connection attempts to reconnect automatically; once reconnected, new messages are received again without requiring a manual page reload. | E27: A conversation is open with an active SignalR connection. | F27: Pending | G27: 13/8/2026 | H27: Nguyễn Việt Thành | I27: Pending | L27: Pending

Sheet E-Contract & OTP Signing
A2: Feature | B2: E-Contract & OTP Signing | R2: Passed
A3: Test requirement | B3: E-Contract & OTP Signing module validates the formal agreement lifecycle between space providers and renters without requiring third-party paper procedures | R3: Failed
A4: Number of TCs | B4: 11 | R4: Pending
A5: Testing Round | B5: Passed | C5: Failed | D5: Pending | E5: N/A | R5: N/A
A6: Round 1 | B6: =COUNTIF($F10:$F996,B5) -> 11 | C6: =COUNTIF($F10:$F996,C5) -> 0 | D6: =COUNTIF($F10:$F996,D5) -> 0 | E6: =COUNTIF($F10:$F996,E5) -> 0
A7: Round 2 | B7: =COUNTIF($F10:$F996,B5) -> 11 | C7: =COUNTIF($F10:$F996,C5) -> 0 | D7: =COUNTIF($F10:$F996,D5) -> 0 | E7: =COUNTIF($F10:$F996,E5) -> 0
A8: Round 3 | B8: =COUNTIF($F10:$F996,B5) -> 11 | C8: =COUNTIF($F10:$F996,C5) -> 0 | D8: =COUNTIF($F10:$F996,D5) -> 0 | E8: =COUNTIF($F10:$F996,E5) -> 0
A10: Test Case ID | B10: Test Case Description | C10: Test Case Procedure | D10: Expected Results | E10: Pre-conditions | F10: Round 1 | G10: Test date | H10: Tester | I10: Round 2 | J10: Test date | K10: Tester | L10: Round 3 | M10: Test date | N10: Tester | O10: Note
A11: Function A - Create Booking Request
A12: F5-01 | B12: Verify the contracts list displays contracts with the correct status label (Pending/Active/Expired/Cancelled). | C12: 1. Log in as a user with existing contracts of varying statuses. 2. Navigate to "My Contracts". | D12: GET /api/Contract/GetAll is called and each contract row/card shows the correct status label matching ContractStatusEnum. | E12: At least one contract of each relevant status exists for the logged-in user. | F12: Passed | G12: 14/8/2026 | H12: Nguyễn Việt Thành | I12: N/A | L12: N/A
A13: F5-02 | B13: Verify clicking a contract opens its detail view with correct lease information. | C13: 1. On "My Contracts", click into a specific contract. | D13: GET /api/Contract/GetById/{id} is called; the detail view shows the correct space, lessor/lessee, price, deposit, start date, and end date. | E13: At least one contract exists for the logged-in user. | F13: Passed | G13: 14/8/2026 | H13: Nguyễn Việt Thành | I13: N/A | L13: N/A
A14: Function B - Contract Creation from Approved Booking
A15: F5-03 | B15: Verify a contract can only be created from a booking request with status Approved. | C15: 1. Attempt to trigger contract creation from a booking request that is not yet Approved. | D15: The "Create Contract" action is not available/disabled for booking requests that are not Approved. | E15: A booking request with status other than Approved exists. | F15: Passed | G15: 14/8/2026 | H15: Nguyễn Việt Thành | I15: N/A | L15: N/A
A16: F5-04 | B16: Verify the Contract creation form requires Lessor/Lessee ID card numbers before submission. | C16: 1. Open "Create Contract" from an Approved booking request. 2. Leave lessorNumberCard or lesseeNumberCard blank. 3. Attempt to submit. | D16: Form blocks submission and shows a validation error for the missing ID card field. | E16: An Approved booking request exists and the Create Contract form is open. | F16: Passed | G16: 14/8/2026 | H16: Nguyễn Việt Thành | I16: N/A | L16: N/A
A17: F5-05 | B17: Verify successful contract creation calls POST /api/Contract/Create with the correct payload and initial status Pending. | C17: 1. Fill in all required contract fields (acreage, duration, start/end date, deposit amount, price, ID cards). 2. Submit. | D17: POST /api/Contract/Create is called with a payload matching ContractRequest. The new contract appears with status "Pending". | E17: An Approved booking request exists. | F17: Passed | G17: 14/8/2026 | H17: Nguyễn Việt Thành | I17: N/A | L17: N/A
A18: Function C - Contract View Modal & OTP Signing
A19: F5-06 | B19: Verify clicking "Sign Contract" triggers an OTP to be sent to the user. | C19: 1. Open a Pending contract's detail modal. 2. Click "Sign Contract" / "Start Signing". | D19: The corresponding send-OTP endpoint is called; a message confirms the OTP has been sent, and an OTP input field is displayed. | E19: A contract with status Pending (awaiting signature) exists and is open in the view modal. | F19: Passed | G19: 14/8/2026 | H19: Nguyễn Việt Thành | I19: N/A | L19: N/A
A20: F5-07 | B20: Verify entering an incorrect OTP during contract signing displays an error and does not activate the contract. | C20: 1. On the OTP input step of the signing flow, enter an incorrect code. 2. Submit. | D20: The validate-OTP endpoint returns an error. An error message is shown and the contract status remains unchanged (not Active). | E20: An OTP has been sent for a pending contract signature. | F20: Passed | G20: 14/8/2026 | H20: Nguyễn Việt Thành | I20: N/A | L20: N/A
A21: F5-08 | B21: Verify entering the correct OTP completes the signing and updates the contract status to Active. | C21: 1. On the OTP input step, enter the correct code. 2. Submit. | D21: The validate-OTP endpoint succeeds. The contract status updates to "Active" and the signed state is reflected immediately in the modal. | E21: An OTP has been sent for a pending contract signature and the correct code is known. | F21: Passed | G21: 14/8/2026 | H21: Nguyễn Việt Thành | I21: N/A | L21: N/A
A22: F5-09 | B22: Verify the contract list/detail view refreshes automatically after a successful signature without requiring a manual page reload. | C22: 1. Complete OTP signing successfully from the contract view modal. 2. Close the modal. 3. Observe the underlying contract list. | D22: The contract's status in the underlying list reflects "Active" immediately after closing the modal, without needing a manual page refresh. | E22: A contract signature has just been completed successfully. | F22: Passed | G22: 14/8/2026 | H22: Nguyễn Việt Thành | I22: N/A | L22: N/A
A23: F5-10 | B23: Verify the signed contract's PDF/document link is accessible from the view modal. | C23: 1. Open the detail view of a contract that has already been signed (Active). | D23: A link/button to view or download the signed contract document is available and opens the correct file. | E23: At least one contract with status Active exists. | F23: Passed | G23: 14/8/2026 | H23: Nguyễn Việt Thành | I23: N/A | L23: N/A
A24: F5-11 | B24: Verify canceling the signing process before OTP completion leaves the contract in its original state. | C24: 1. Start the signing flow (OTP sent). 2. Close the modal or click "Cancel" before entering the OTP. | D24: The cancel-signing action is called if applicable; the contract status remains "Pending" (not signed, not corrupted). | E24: A contract signing flow has been initiated but not completed. | F24: Passed | G24: 14/8/2026 | H24: Nguyễn Việt Thành | I24: N/A | L24: N/A

Sheet Time-based Scheduling & Sub-Boo
A2: Feature | B2: Time-based Scheduling & Sub-Booking | R2: Passed
A3: Test requirement | B3: Time-based Scheduling & Sub-Booking sheet tests the core micro-leasing engine of FlexiSpace-allowing primary tenants to partition and sublease unused time windows to secondary renters. | R3: Failed
A4: Number of TCs | B4: 9 | R4: Pending
A5: Testing Round | B5: Passed | C5: Failed | D5: Pending | E5: N/A | R5: N/A
A6: Round 1 | B6: =COUNTIF($F10:$F994,B5) -> 6 | C6: =COUNTIF($F10:$F994,C5) -> 3 | D6: =COUNTIF($F10:$F994,D5) -> 0 | E6: =COUNTIF($F10:$F994,E5) -> 0
A7: Round 2 | B7: =COUNTIF($F10:$F994,B5) -> 6 | C7: =COUNTIF($F10:$F994,C5) -> 3 | D7: =COUNTIF($F10:$F994,D5) -> 0 | E7: =COUNTIF($F10:$F994,E5) -> 0
A8: Round 3 | B8: =COUNTIF($F10:$F994,B5) -> 6 | C8: =COUNTIF($F10:$F994,C5) -> 3 | D8: =COUNTIF($F10:$F994,D5) -> 0 | E8: =COUNTIF($F10:$F994,E5) -> 0
A10: Test Case ID | B10: Test Case Description | C10: Test Case Procedure | D10: Expected Results | E10: Pre-conditions | F10: Round 1 | G10: Test date | H10: Tester | I10: Round 2 | J10: Test date | K10: Tester | L10: Round 3 | M10: Test date | N10: Tester | O10: Note
A11: Function A - Slot Calendar Display
A12: F6-01 | B12: Verify the calendar correctly renders all existing time slots for a shared space. | C12: 1. Navigate to the Slot Calendar for a space with existing sublease slots. | D12: Every existing slot is rendered at its correct day/time position on the calendar grid, matching the backend data. | E12: At least one shared space with configured availability/sublease slots exists. | F12: Passed | G12: 14/8/2026 | H12: Nguyễn Việt Thành | I12: N/A | L12: N/A
A13: F6-02 | B13: Verify the calendar visually distinguishes an available slot from an already-booked slot. | C13: 1. View a calendar containing both an available slot and a booked slot. | D13: Available and booked slots are shown with clearly distinct visual states (e.g. different colors/labels). | E13: The calendar contains at least one available slot and one booked slot. | F13: Passed | G13: N/A | H13: Nguyễn Việt Thành | I13: N/A | L13: N/A
A14: Function B - Sublease Slot Form (Time-Slot Subdivision)
A15: F6-03 | B15: Verify the sublease slot form requires selecting an active Primary Lease before proceeding. | C15: 1. Attempt to open the Sublease Slot Form without an active lease selected. | D15: The form is inaccessible or shows a clear message requiring an active lease/space to be selected first. | E15: User is a Primary Renter. | F15: Passed | G15: N/A | H15: Nguyễn Việt Thành | I15: N/A | L15: N/A
A16: F6-04 | B16: Verify Start Time must be earlier than End Time when defining a sublease time slot. | C16: 1. On the Sublease Slot Form, set a Start Time later than the End Time. 2. Attempt to submit. | D16: Form blocks submission and shows a validation error for the invalid time range. | E16: User is a Primary Renter on the Sublease Slot Form with an active lease selected. | F16: Passed | G16: N/A | H16: Nguyễn Việt Thành | I16: N/A | L16: N/A
A17: F6-05 | B17: Verify the client attempts to warn the user when a newly defined slot overlaps with an existing slot for the same space. | C17: 1. Attempt to create a new sublease slot with a time range that overlaps an already-existing slot for the same space. 2. Submit. | D17: If the backend rejects the overlapping slot, the UI must clearly surface the returned error to the user rather than silently failing or showing a generic error. | E17: At least one existing sublease slot occupies a known time range for the target space. | F17: Failed | G17: N/A | H17: Nguyễn Việt Thành | I17: N/A | L17: N/A
A18: F6-06 | B18: Verify successful sublease slot creation publishes the new slot with status Available. | C18: 1. Fill in a invalid, non-overlapping time slot and price. 2. Submit. | D18: The new slot appears on the Slot Calendar / Sublease Listings with status "Available". | E18: User is a Primary Renter with an active lease eligible for subleasing. | F18: Failed | G18: N/A | H18: Nguyễn Việt Thành | I18: N/A | L18: N/A
A19: Function C - Sub-Booking Form
A20: F6-07 | B20: Verify a Secondary Renter can only select an Available slot for booking. | C20: 1. On the Sub-Booking Form, attempt to select a slot already marked as booked/unavailable. | D20: The unavailable slot cannot be selected (disabled state) or selecting it shows a clear message that the slot is unavailable. | E20: At least one slot with a non-Available status exists. | F20: Passed | G20: N/A | H20: Nguyễn Việt Thành | I20: N/A | L20: N/A
A21: F6-08 | B21: Verify the total price displayed is calculated correctly from the slot's hourly rate and the selected duration. | C21: 1. Select an available slot with a known hourly rate. 2. Select a duration. 3. Observe the displayed total price. | D21: The displayed total matches (hourly rate × selected hours), consistent with the pricing shown by the backend/listing data. | E21: An available slot with a known price exists. | F21: Passed | G21: N/A | H21: Nguyễn Việt Thành | I21: N/A | L21: N/A
A22: F6-09 | B22: Verify submitting a sub-booking request for an available slot succeeds and updates the slot's displayed status. | C22: 1. Select a invalid available slot and duration. 2. Submit the booking. | D22: The booking request is created successfully and the slot's status updates (e.g. to "Pending"/"Booked") in the UI. | E22: An available slot exists for the target shared space. | F22: Failed | G22: N/A | H22: Nguyễn Việt Thành | I22: N/A | L22: N/A

Sheet Tenant & Contract Management 
A2: Feature | B2: Tenant & Contract Management | R2: Passed
A3: Test requirement | B3: Tenant & Contract Management sheet tests the post-agreement operational lifecycle-enabling hosts to oversee their active occupants across multiple tiers and manage executed leases | R3: Failed
A4: Number of TCs | B4: 3 | R4: Pending
A5: Testing Round | B5: Passed | C5: Failed | D5: Pending | E5: N/A | R5: N/A
A6: Round 1 | B6: =COUNTIF($F10:$F987,B5) -> 2 | C6: =COUNTIF($F10:$F987,C5) -> 1 | D6: =COUNTIF($F10:$F987,D5) -> 0 | E6: =COUNTIF($F10:$F987,E5) -> 0
A7: Round 2 | B7: =COUNTIF($F10:$F987,B5) -> 2 | C7: =COUNTIF($F10:$F987,C5) -> 1 | D7: =COUNTIF($F10:$F987,D5) -> 0 | E7: =COUNTIF($F10:$F987,E5) -> 0
A8: Round 3 | B8: =COUNTIF($F10:$F987,B5) -> 2 | C8: =COUNTIF($F10:$F987,C5) -> 1 | D8: =COUNTIF($F10:$F987,D5) -> 0 | E8: =COUNTIF($F10:$F987,E5) -> 0
A10: Test Case ID | B10: Test Case Description | C10: Test Case Procedure | D10: Expected Results | E10: Pre-conditions | F10: Round 1 | G10: Test date | H10: Tester | I10: Round 2 | J10: Test date | K10: Tester | L10: Round 3 | M10: Test date | N10: Tester | O10: Note
A11: Function A - Owner Tenants List
A12: F7-01 | B12: Verify the Owner Tenants list aggregates tenants across all of the Owner's properties. | C12: 1. Log in as an Owner with tenants across two or more spaces. 2. Navigate to "Tenants". | D12: All active tenants across every one of the Owner's spaces are listed, each correctly associated with its corresponding space. | E12: The Owner has active contracts/tenants across at least two different spaces. | F12: Passed | G12: 14/8/2026 | H12: Nguyễn Việt Thành | I12: N/A | L12: N/A
